
#######################################################################
# +-----------------------------------------------------------------+ #
# |                            BO3 object                           | #
# +-----------------------------------------------------------------+ #
#######################################################################

# This is the config file of a custom object.
# If you add this object correctly to your BiomeConfigs, it will spawn in the world.

# This is the creator of this BO3 object
Author: TrueMalice

# A short description of this BO3 object
Description: No description given

# The BO3 version, don't change this! It can be used by external applications to do a version check.
Version: 3

# The settings mode, WriteAll, WriteWithoutComments or WriteDisable. See WorldConfig.
SettingsMode: WriteAll


#######################################################################
# +-----------------------------------------------------------------+ #
# |                          Main settings                          | #
# +-----------------------------------------------------------------+ #
#######################################################################

# This needs to be set to true to spawn the object in the Tree and Sapling resources.
Tree: false

# The frequency of the BO3 from 1 to 200. Tries this many times to spawn this BO3 when using the CustomObject(...) resource.
# Ignored by Tree(..), Sapling(..) and CustomStructure(..)
Frequency: 1

# The rarity of the BO3 from 0 to 100. Each spawn attempt has rarity% chance to succeed when using the CustomObject(...) resource.
# Ignored by Tree(..), Sapling(..) and CustomStructure(..)
Rarity: 100.0

# If you set this to true, the BO3 will be placed with a random rotation.
RotateRandomly: false

# The spawn height of the BO3 - randomY, randomY or highestSolidBlock.
SpawnHeight: randomY

# The height limits for the BO3.
MinHeight: 40

MaxHeight: 40

# Objects can have other objects attacthed to it: branches. Branches can also
# have branches attached to it, which can also have branches, etc. This is the
# maximum branch depth for this objects.
MaxBranchDepth: 10

# When spawned with the UseWorld keyword, this BO3 should NOT spawn in the following biomes.
# If you writer.write the BO3 name directly in the BiomeConfigs, this will be ignored.
ExcludedBiomes: All


#######################################################################
# +-----------------------------------------------------------------+ #
# |                      Source block settings                      | #
# +-----------------------------------------------------------------+ #
#######################################################################

# The block(s) the BO3 should spawn in.
SourceBlocks: AIR, LAVA, NETHERRACK

# The maximum percentage of the BO3 that can be outside the SourceBlock.
# The BO3 won't be placed on a location with more blocks outside the SourceBlock than this percentage.
MaxPercentageOutsideSourceBlock: 50

# What to do when a block is about to be placed outside the SourceBlock? (dontPlace, placeAnyway)
OutsideSourceBlock: dontPlace


#######################################################################
# +-----------------------------------------------------------------+ #
# |                              Blocks                             | #
# +-----------------------------------------------------------------+ #
#######################################################################

# All the blocks used in the BO3 are listed here. Possible blocks:
# Block(x,y,z,id[.data][,nbtfile.nbt)
# RandomBlock(x,y,z,id[:data][,nbtfile.nbt],chance[,id[:data][,nbtfile.nbt],chance[,...]])
# So RandomBlock(0,0,0,CHEST,chest.nbt,50,CHEST,anotherchest.nbt,100) will spawn a chest at
# the BO3 origin, and give it a 50% chance to have the contents of chest.nbt, or, if that
# fails, a 100% percent chance to have the contents of anotherchest.nbt.
Block(-6,-39,-3,NETHER_BRICK)
Block(-6,-39,-2,NETHER_BRICK)
Block(-6,-39,-1,NETHER_BRICK)
Block(-6,-39,0,NETHER_BRICK)
Block(-6,-39,1,NETHER_BRICK)
Block(-6,-39,2,NETHER_BRICK)
Block(-6,-39,3,NETHER_BRICK)
Block(-6,-38,-3,NETHER_BRICK)
Block(-6,-38,-2,NETHER_BRICK)
Block(-6,-38,-1,NETHER_BRICK)
Block(-6,-38,0,NETHER_BRICK)
Block(-6,-38,1,NETHER_BRICK)
Block(-6,-38,2,NETHER_BRICK)
Block(-6,-38,3,NETHER_BRICK)
Block(-6,-37,-3,NETHER_BRICK)
Block(-6,-37,-2,NETHER_BRICK)
Block(-6,-37,-1,NETHER_BRICK)
Block(-6,-37,0,NETHER_BRICK)
Block(-6,-37,1,NETHER_BRICK)
Block(-6,-37,2,NETHER_BRICK)
Block(-6,-37,3,NETHER_BRICK)
Block(-6,-36,-3,NETHER_BRICK)
Block(-6,-36,-2,NETHER_BRICK)
Block(-6,-36,-1,NETHER_BRICK)
Block(-6,-36,0,NETHER_BRICK)
Block(-6,-36,1,NETHER_BRICK)
Block(-6,-36,2,NETHER_BRICK)
Block(-6,-36,3,NETHER_BRICK)
Block(-6,-35,-3,NETHER_BRICK)
Block(-6,-35,-2,NETHER_BRICK)
Block(-6,-35,-1,NETHER_BRICK)
Block(-6,-35,0,NETHER_BRICK)
Block(-6,-35,1,NETHER_BRICK)
Block(-6,-35,2,NETHER_BRICK)
Block(-6,-35,3,NETHER_BRICK)
Block(-6,-34,-3,NETHER_BRICK)
Block(-6,-34,-2,NETHER_BRICK)
Block(-6,-34,-1,NETHER_BRICK)
Block(-6,-34,0,NETHER_BRICK)
Block(-6,-34,1,NETHER_BRICK)
Block(-6,-34,2,NETHER_BRICK)
Block(-6,-34,3,NETHER_BRICK)
Block(-6,-33,-3,NETHER_BRICK)
Block(-6,-33,-2,NETHER_BRICK)
Block(-6,-33,-1,NETHER_BRICK)
Block(-6,-33,0,NETHER_BRICK)
Block(-6,-33,1,NETHER_BRICK)
Block(-6,-33,2,NETHER_BRICK)
Block(-6,-33,3,NETHER_BRICK)
Block(-6,-32,-3,NETHER_BRICK)
Block(-6,-32,-2,NETHER_BRICK)
Block(-6,-32,-1,NETHER_BRICK)
Block(-6,-32,0,NETHER_BRICK)
Block(-6,-32,1,NETHER_BRICK)
Block(-6,-32,2,NETHER_BRICK)
Block(-6,-32,3,NETHER_BRICK)
Block(-6,-31,-3,NETHER_BRICK)
Block(-6,-31,-2,NETHER_BRICK)
Block(-6,-31,-1,NETHER_BRICK)
Block(-6,-31,0,NETHER_BRICK)
Block(-6,-31,1,NETHER_BRICK)
Block(-6,-31,2,NETHER_BRICK)
Block(-6,-31,3,NETHER_BRICK)
Block(-6,-30,-3,NETHER_BRICK)
Block(-6,-30,-2,NETHER_BRICK)
Block(-6,-30,-1,NETHER_BRICK)
Block(-6,-30,0,NETHER_BRICK)
Block(-6,-30,1,NETHER_BRICK)
Block(-6,-30,2,NETHER_BRICK)
Block(-6,-30,3,NETHER_BRICK)
Block(-6,-29,-3,NETHER_BRICK)
Block(-6,-29,-2,NETHER_BRICK)
Block(-6,-29,-1,NETHER_BRICK)
Block(-6,-29,0,NETHER_BRICK)
Block(-6,-29,1,NETHER_BRICK)
Block(-6,-29,2,NETHER_BRICK)
Block(-6,-29,3,NETHER_BRICK)
Block(-6,-28,-3,NETHER_BRICK)
Block(-6,-28,-2,NETHER_BRICK)
Block(-6,-28,-1,NETHER_BRICK)
Block(-6,-28,0,NETHER_BRICK)
Block(-6,-28,1,NETHER_BRICK)
Block(-6,-28,2,NETHER_BRICK)
Block(-6,-28,3,NETHER_BRICK)
Block(-6,-27,-3,NETHER_BRICK)
Block(-6,-27,-2,NETHER_BRICK)
Block(-6,-27,-1,NETHER_BRICK)
Block(-6,-27,0,NETHER_BRICK)
Block(-6,-27,1,NETHER_BRICK)
Block(-6,-27,2,NETHER_BRICK)
Block(-6,-27,3,NETHER_BRICK)
Block(-6,-26,-3,NETHER_BRICK)
Block(-6,-26,-2,NETHER_BRICK)
Block(-6,-26,-1,NETHER_BRICK)
Block(-6,-26,0,NETHER_BRICK)
Block(-6,-26,1,NETHER_BRICK)
Block(-6,-26,2,NETHER_BRICK)
Block(-6,-26,3,NETHER_BRICK)
Block(-6,-25,-3,NETHER_BRICK)
Block(-6,-25,-2,NETHER_BRICK)
Block(-6,-25,-1,NETHER_BRICK)
Block(-6,-25,0,NETHER_BRICK)
Block(-6,-25,1,NETHER_BRICK)
Block(-6,-25,2,NETHER_BRICK)
Block(-6,-25,3,NETHER_BRICK)
Block(-6,-24,-3,NETHER_BRICK)
Block(-6,-24,-2,NETHER_BRICK)
Block(-6,-24,-1,NETHER_BRICK)
Block(-6,-24,0,NETHER_BRICK)
Block(-6,-24,1,NETHER_BRICK)
Block(-6,-24,2,NETHER_BRICK)
Block(-6,-24,3,NETHER_BRICK)
Block(-6,-23,-3,NETHER_BRICK)
Block(-6,-23,-2,NETHER_BRICK)
Block(-6,-23,-1,NETHER_BRICK)
Block(-6,-23,0,NETHER_BRICK)
Block(-6,-23,1,NETHER_BRICK)
Block(-6,-23,2,NETHER_BRICK)
Block(-6,-23,3,NETHER_BRICK)
Block(-6,-22,-3,NETHER_BRICK)
Block(-6,-22,-2,NETHER_BRICK)
Block(-6,-22,-1,NETHER_BRICK)
Block(-6,-22,0,NETHER_BRICK)
Block(-6,-22,1,NETHER_BRICK)
Block(-6,-22,2,NETHER_BRICK)
Block(-6,-22,3,NETHER_BRICK)
Block(-6,-21,-3,NETHER_BRICK)
Block(-6,-21,-2,NETHER_BRICK)
Block(-6,-21,-1,NETHER_BRICK)
Block(-6,-21,0,NETHER_BRICK)
Block(-6,-21,1,NETHER_BRICK)
Block(-6,-21,2,NETHER_BRICK)
Block(-6,-21,3,NETHER_BRICK)
Block(-6,-20,-3,NETHER_BRICK)
Block(-6,-20,-2,NETHER_BRICK)
Block(-6,-20,-1,NETHER_BRICK)
Block(-6,-20,0,NETHER_BRICK)
Block(-6,-20,1,NETHER_BRICK)
Block(-6,-20,2,NETHER_BRICK)
Block(-6,-20,3,NETHER_BRICK)
Block(-6,-19,-3,NETHER_BRICK)
Block(-6,-19,-2,NETHER_BRICK)
Block(-6,-19,-1,NETHER_BRICK)
Block(-6,-19,0,NETHER_BRICK)
Block(-6,-19,1,NETHER_BRICK)
Block(-6,-19,2,NETHER_BRICK)
Block(-6,-19,3,NETHER_BRICK)
Block(-6,-18,-3,NETHER_BRICK)
Block(-6,-18,-2,NETHER_BRICK)
Block(-6,-18,-1,NETHER_BRICK)
Block(-6,-18,0,NETHER_BRICK)
Block(-6,-18,1,NETHER_BRICK)
Block(-6,-18,2,NETHER_BRICK)
Block(-6,-18,3,NETHER_BRICK)
Block(-6,-17,-3,NETHER_BRICK)
Block(-6,-17,-2,NETHER_BRICK)
Block(-6,-17,-1,NETHER_BRICK)
Block(-6,-17,0,NETHER_BRICK)
Block(-6,-17,1,NETHER_BRICK)
Block(-6,-17,2,NETHER_BRICK)
Block(-6,-17,3,NETHER_BRICK)
Block(-6,-16,-3,NETHER_BRICK)
Block(-6,-16,-2,NETHER_BRICK)
Block(-6,-16,-1,NETHER_BRICK)
Block(-6,-16,0,NETHER_BRICK)
Block(-6,-16,1,NETHER_BRICK)
Block(-6,-16,2,NETHER_BRICK)
Block(-6,-16,3,NETHER_BRICK)
Block(-6,-15,-3,NETHER_BRICK)
Block(-6,-15,-2,NETHER_BRICK)
Block(-6,-15,-1,NETHER_BRICK)
Block(-6,-15,0,NETHER_BRICK)
Block(-6,-15,1,NETHER_BRICK)
Block(-6,-15,2,NETHER_BRICK)
Block(-6,-15,3,NETHER_BRICK)
Block(-6,-14,-3,NETHER_BRICK)
Block(-6,-14,-2,NETHER_BRICK)
Block(-6,-14,-1,NETHER_BRICK)
Block(-6,-14,0,NETHER_BRICK)
Block(-6,-14,1,NETHER_BRICK)
Block(-6,-14,2,NETHER_BRICK)
Block(-6,-14,3,NETHER_BRICK)
Block(-6,-13,-3,NETHER_BRICK)
Block(-6,-13,-2,NETHER_BRICK)
Block(-6,-13,-1,NETHER_BRICK)
Block(-6,-13,0,NETHER_BRICK)
Block(-6,-13,1,NETHER_BRICK)
Block(-6,-13,2,NETHER_BRICK)
Block(-6,-13,3,NETHER_BRICK)
Block(-6,-12,-3,NETHER_BRICK)
Block(-6,-12,-2,NETHER_BRICK)
Block(-6,-12,-1,NETHER_BRICK)
Block(-6,-12,0,NETHER_BRICK)
Block(-6,-12,1,NETHER_BRICK)
Block(-6,-12,2,NETHER_BRICK)
Block(-6,-12,3,NETHER_BRICK)
Block(-6,-11,-3,NETHER_BRICK)
Block(-6,-11,-2,NETHER_BRICK)
Block(-6,-11,-1,NETHER_BRICK)
Block(-6,-11,0,NETHER_BRICK)
Block(-6,-11,1,NETHER_BRICK)
Block(-6,-11,2,NETHER_BRICK)
Block(-6,-11,3,NETHER_BRICK)
Block(-6,-10,-3,NETHER_BRICK)
Block(-6,-10,-2,NETHER_BRICK)
Block(-6,-10,-1,NETHER_BRICK)
Block(-6,-10,0,NETHER_BRICK)
Block(-6,-10,1,NETHER_BRICK)
Block(-6,-10,2,NETHER_BRICK)
Block(-6,-10,3,NETHER_BRICK)
Block(-6,-9,-3,NETHER_BRICK)
Block(-6,-9,-2,NETHER_BRICK)
Block(-6,-9,-1,NETHER_BRICK)
Block(-6,-9,0,NETHER_BRICK)
Block(-6,-9,1,NETHER_BRICK)
Block(-6,-9,2,NETHER_BRICK)
Block(-6,-9,3,NETHER_BRICK)
Block(-6,-8,-3,NETHER_BRICK)
Block(-6,-8,-2,NETHER_BRICK)
Block(-6,-8,-1,NETHER_BRICK)
Block(-6,-8,0,NETHER_BRICK)
Block(-6,-8,1,NETHER_BRICK)
Block(-6,-8,2,NETHER_BRICK)
Block(-6,-8,3,NETHER_BRICK)
Block(-6,-7,-3,NETHER_BRICK)
Block(-6,-7,-2,NETHER_BRICK)
Block(-6,-7,-1,NETHER_BRICK)
Block(-6,-7,0,NETHER_BRICK)
Block(-6,-7,1,NETHER_BRICK)
Block(-6,-7,2,NETHER_BRICK)
Block(-6,-7,3,NETHER_BRICK)
Block(-6,-6,-3,NETHER_BRICK)
Block(-6,-6,-2,NETHER_BRICK)
Block(-6,-6,-1,NETHER_BRICK)
Block(-6,-6,0,NETHER_BRICK)
Block(-6,-6,1,NETHER_BRICK)
Block(-6,-6,2,NETHER_BRICK)
Block(-6,-6,3,NETHER_BRICK)
Block(-6,-5,-3,NETHER_BRICK)
Block(-6,-5,-2,NETHER_BRICK)
Block(-6,-5,-1,NETHER_BRICK)
Block(-6,-5,0,NETHER_BRICK)
Block(-6,-5,1,NETHER_BRICK)
Block(-6,-5,2,NETHER_BRICK)
Block(-6,-5,3,NETHER_BRICK)
Block(-6,-4,-3,NETHER_BRICK)
Block(-6,-4,-2,NETHER_BRICK)
Block(-6,-4,-1,NETHER_BRICK)
Block(-6,-4,0,NETHER_BRICK)
Block(-6,-4,1,NETHER_BRICK)
Block(-6,-4,2,NETHER_BRICK)
Block(-6,-4,3,NETHER_BRICK)
Block(-6,-3,-3,NETHER_BRICK)
Block(-6,-3,-2,NETHER_BRICK)
Block(-6,-3,-1,NETHER_BRICK)
Block(-6,-3,0,NETHER_BRICK)
Block(-6,-3,1,NETHER_BRICK)
Block(-6,-3,2,NETHER_BRICK)
Block(-6,-3,3,NETHER_BRICK)
Block(-6,-2,-3,NETHER_BRICK)
Block(-6,-2,-2,NETHER_BRICK)
Block(-6,-2,-1,NETHER_BRICK)
Block(-6,-2,0,NETHER_BRICK)
Block(-6,-2,1,NETHER_BRICK)
Block(-6,-2,2,NETHER_BRICK)
Block(-6,-2,3,NETHER_BRICK)
Block(-6,-1,-3,NETHER_BRICK)
Block(-6,-1,-2,NETHER_BRICK)
Block(-6,-1,-1,NETHER_BRICK)
Block(-6,-1,0,NETHER_BRICK)
Block(-6,-1,1,NETHER_BRICK)
Block(-6,-1,2,NETHER_BRICK)
Block(-6,-1,3,NETHER_BRICK)
Block(-6,0,-3,NETHER_BRICK)
Block(-6,0,-2,NETHER_BRICK)
Block(-6,0,-1,NETHER_BRICK)
Block(-6,0,0,NETHER_BRICK)
Block(-6,0,1,NETHER_BRICK)
Block(-6,0,2,NETHER_BRICK)
Block(-6,0,3,NETHER_BRICK)
Block(-6,1,-3,NETHER_BRICK)
Block(-6,1,-2,NETHER_BRICK)
Block(-6,1,-1,NETHER_BRICK)
Block(-6,1,0,NETHER_BRICK)
Block(-6,1,1,NETHER_BRICK)
Block(-6,1,2,NETHER_BRICK)
Block(-6,1,3,NETHER_BRICK)
Block(-6,2,-3,NETHER_BRICK)
Block(-6,2,-2,AIR)
Block(-6,2,-1,AIR)
Block(-6,2,0,AIR)
Block(-6,2,1,AIR)
Block(-6,2,2,AIR)
Block(-6,2,3,NETHER_BRICK)
Block(-6,3,-3,AIR)
Block(-6,3,-2,AIR)
Block(-6,3,-1,AIR)
Block(-6,3,0,AIR)
Block(-6,3,1,AIR)
Block(-6,3,2,AIR)
Block(-6,3,3,AIR)
Block(-6,4,-3,AIR)
Block(-6,4,-2,AIR)
Block(-6,4,-1,AIR)
Block(-6,4,0,AIR)
Block(-6,4,1,AIR)
Block(-6,4,2,AIR)
Block(-6,4,3,AIR)
Block(-6,5,-3,AIR)
Block(-6,5,-2,AIR)
Block(-6,5,-1,AIR)
Block(-6,5,0,AIR)
Block(-6,5,1,AIR)
Block(-6,5,2,AIR)
Block(-6,5,3,AIR)
Block(-6,6,-3,AIR)
Block(-6,6,-2,AIR)
Block(-6,6,-1,AIR)
Block(-6,6,0,AIR)
Block(-6,6,1,AIR)
Block(-6,6,2,AIR)
Block(-6,6,3,AIR)
Block(-5,-39,-3,NETHER_BRICK)
Block(-5,-39,-2,NETHER_BRICK)
Block(-5,-39,-1,NETHER_BRICK)
Block(-5,-39,0,NETHER_BRICK)
Block(-5,-39,1,NETHER_BRICK)
Block(-5,-39,2,NETHER_BRICK)
Block(-5,-39,3,NETHER_BRICK)
Block(-5,-38,-3,NETHER_BRICK)
Block(-5,-38,-2,NETHER_BRICK)
Block(-5,-38,-1,NETHER_BRICK)
Block(-5,-38,0,NETHER_BRICK)
Block(-5,-38,1,NETHER_BRICK)
Block(-5,-38,2,NETHER_BRICK)
Block(-5,-38,3,NETHER_BRICK)
Block(-5,-37,-3,NETHER_BRICK)
Block(-5,-37,-2,NETHER_BRICK)
Block(-5,-37,-1,NETHER_BRICK)
Block(-5,-37,0,NETHER_BRICK)
Block(-5,-37,1,NETHER_BRICK)
Block(-5,-37,2,NETHER_BRICK)
Block(-5,-37,3,NETHER_BRICK)
Block(-5,-36,-3,NETHER_BRICK)
Block(-5,-36,-2,NETHER_BRICK)
Block(-5,-36,-1,NETHER_BRICK)
Block(-5,-36,0,NETHER_BRICK)
Block(-5,-36,1,NETHER_BRICK)
Block(-5,-36,2,NETHER_BRICK)
Block(-5,-36,3,NETHER_BRICK)
Block(-5,-35,-3,NETHER_BRICK)
Block(-5,-35,-2,NETHER_BRICK)
Block(-5,-35,-1,NETHER_BRICK)
Block(-5,-35,0,NETHER_BRICK)
Block(-5,-35,1,NETHER_BRICK)
Block(-5,-35,2,NETHER_BRICK)
Block(-5,-35,3,NETHER_BRICK)
Block(-5,-34,-3,NETHER_BRICK)
Block(-5,-34,-2,NETHER_BRICK)
Block(-5,-34,-1,NETHER_BRICK)
Block(-5,-34,0,NETHER_BRICK)
Block(-5,-34,1,NETHER_BRICK)
Block(-5,-34,2,NETHER_BRICK)
Block(-5,-34,3,NETHER_BRICK)
Block(-5,-33,-3,NETHER_BRICK)
Block(-5,-33,-2,NETHER_BRICK)
Block(-5,-33,-1,NETHER_BRICK)
Block(-5,-33,0,NETHER_BRICK)
Block(-5,-33,1,NETHER_BRICK)
Block(-5,-33,2,NETHER_BRICK)
Block(-5,-33,3,NETHER_BRICK)
Block(-5,-32,-3,NETHER_BRICK)
Block(-5,-32,-2,NETHER_BRICK)
Block(-5,-32,-1,NETHER_BRICK)
Block(-5,-32,0,NETHER_BRICK)
Block(-5,-32,1,NETHER_BRICK)
Block(-5,-32,2,NETHER_BRICK)
Block(-5,-32,3,NETHER_BRICK)
Block(-5,-31,-3,NETHER_BRICK)
Block(-5,-31,-2,NETHER_BRICK)
Block(-5,-31,-1,NETHER_BRICK)
Block(-5,-31,0,NETHER_BRICK)
Block(-5,-31,1,NETHER_BRICK)
Block(-5,-31,2,NETHER_BRICK)
Block(-5,-31,3,NETHER_BRICK)
Block(-5,-30,-3,NETHER_BRICK)
Block(-5,-30,-2,NETHER_BRICK)
Block(-5,-30,-1,NETHER_BRICK)
Block(-5,-30,0,NETHER_BRICK)
Block(-5,-30,1,NETHER_BRICK)
Block(-5,-30,2,NETHER_BRICK)
Block(-5,-30,3,NETHER_BRICK)
Block(-5,-29,-3,NETHER_BRICK)
Block(-5,-29,-2,NETHER_BRICK)
Block(-5,-29,-1,NETHER_BRICK)
Block(-5,-29,0,NETHER_BRICK)
Block(-5,-29,1,NETHER_BRICK)
Block(-5,-29,2,NETHER_BRICK)
Block(-5,-29,3,NETHER_BRICK)
Block(-5,-28,-3,NETHER_BRICK)
Block(-5,-28,-2,NETHER_BRICK)
Block(-5,-28,-1,NETHER_BRICK)
Block(-5,-28,0,NETHER_BRICK)
Block(-5,-28,1,NETHER_BRICK)
Block(-5,-28,2,NETHER_BRICK)
Block(-5,-28,3,NETHER_BRICK)
Block(-5,-27,-3,NETHER_BRICK)
Block(-5,-27,-2,NETHER_BRICK)
Block(-5,-27,-1,NETHER_BRICK)
Block(-5,-27,0,NETHER_BRICK)
Block(-5,-27,1,NETHER_BRICK)
Block(-5,-27,2,NETHER_BRICK)
Block(-5,-27,3,NETHER_BRICK)
Block(-5,-26,-3,NETHER_BRICK)
Block(-5,-26,-2,NETHER_BRICK)
Block(-5,-26,-1,NETHER_BRICK)
Block(-5,-26,0,NETHER_BRICK)
Block(-5,-26,1,NETHER_BRICK)
Block(-5,-26,2,NETHER_BRICK)
Block(-5,-26,3,NETHER_BRICK)
Block(-5,-25,-3,NETHER_BRICK)
Block(-5,-25,-2,NETHER_BRICK)
Block(-5,-25,-1,NETHER_BRICK)
Block(-5,-25,0,NETHER_BRICK)
Block(-5,-25,1,NETHER_BRICK)
Block(-5,-25,2,NETHER_BRICK)
Block(-5,-25,3,NETHER_BRICK)
Block(-5,-24,-3,NETHER_BRICK)
Block(-5,-24,-2,NETHER_BRICK)
Block(-5,-24,-1,NETHER_BRICK)
Block(-5,-24,0,NETHER_BRICK)
Block(-5,-24,1,NETHER_BRICK)
Block(-5,-24,2,NETHER_BRICK)
Block(-5,-24,3,NETHER_BRICK)
Block(-5,-23,-3,NETHER_BRICK)
Block(-5,-23,-2,NETHER_BRICK)
Block(-5,-23,-1,NETHER_BRICK)
Block(-5,-23,0,NETHER_BRICK)
Block(-5,-23,1,NETHER_BRICK)
Block(-5,-23,2,NETHER_BRICK)
Block(-5,-23,3,NETHER_BRICK)
Block(-5,-22,-3,NETHER_BRICK)
Block(-5,-22,-2,NETHER_BRICK)
Block(-5,-22,-1,NETHER_BRICK)
Block(-5,-22,0,NETHER_BRICK)
Block(-5,-22,1,NETHER_BRICK)
Block(-5,-22,2,NETHER_BRICK)
Block(-5,-22,3,NETHER_BRICK)
Block(-5,-21,-3,NETHER_BRICK)
Block(-5,-21,-2,NETHER_BRICK)
Block(-5,-21,-1,NETHER_BRICK)
Block(-5,-21,0,NETHER_BRICK)
Block(-5,-21,1,NETHER_BRICK)
Block(-5,-21,2,NETHER_BRICK)
Block(-5,-21,3,NETHER_BRICK)
Block(-5,-20,-3,NETHER_BRICK)
Block(-5,-20,-2,NETHER_BRICK)
Block(-5,-20,-1,NETHER_BRICK)
Block(-5,-20,0,NETHER_BRICK)
Block(-5,-20,1,NETHER_BRICK)
Block(-5,-20,2,NETHER_BRICK)
Block(-5,-20,3,NETHER_BRICK)
Block(-5,-19,-3,NETHER_BRICK)
Block(-5,-19,-2,NETHER_BRICK)
Block(-5,-19,-1,NETHER_BRICK)
Block(-5,-19,0,NETHER_BRICK)
Block(-5,-19,1,NETHER_BRICK)
Block(-5,-19,2,NETHER_BRICK)
Block(-5,-19,3,NETHER_BRICK)
Block(-5,-18,-3,NETHER_BRICK)
Block(-5,-18,-2,NETHER_BRICK)
Block(-5,-18,-1,NETHER_BRICK)
Block(-5,-18,0,NETHER_BRICK)
Block(-5,-18,1,NETHER_BRICK)
Block(-5,-18,2,NETHER_BRICK)
Block(-5,-18,3,NETHER_BRICK)
Block(-5,-17,-3,NETHER_BRICK)
Block(-5,-17,-2,NETHER_BRICK)
Block(-5,-17,-1,NETHER_BRICK)
Block(-5,-17,0,NETHER_BRICK)
Block(-5,-17,1,NETHER_BRICK)
Block(-5,-17,2,NETHER_BRICK)
Block(-5,-17,3,NETHER_BRICK)
Block(-5,-16,-3,NETHER_BRICK)
Block(-5,-16,-2,NETHER_BRICK)
Block(-5,-16,-1,NETHER_BRICK)
Block(-5,-16,0,NETHER_BRICK)
Block(-5,-16,1,NETHER_BRICK)
Block(-5,-16,2,NETHER_BRICK)
Block(-5,-16,3,NETHER_BRICK)
Block(-5,-15,-3,NETHER_BRICK)
Block(-5,-15,-2,NETHER_BRICK)
Block(-5,-15,-1,NETHER_BRICK)
Block(-5,-15,0,NETHER_BRICK)
Block(-5,-15,1,NETHER_BRICK)
Block(-5,-15,2,NETHER_BRICK)
Block(-5,-15,3,NETHER_BRICK)
Block(-5,-14,-3,NETHER_BRICK)
Block(-5,-14,-2,NETHER_BRICK)
Block(-5,-14,-1,NETHER_BRICK)
Block(-5,-14,0,NETHER_BRICK)
Block(-5,-14,1,NETHER_BRICK)
Block(-5,-14,2,NETHER_BRICK)
Block(-5,-14,3,NETHER_BRICK)
Block(-5,-13,-3,NETHER_BRICK)
Block(-5,-13,-2,NETHER_BRICK)
Block(-5,-13,-1,NETHER_BRICK)
Block(-5,-13,0,NETHER_BRICK)
Block(-5,-13,1,NETHER_BRICK)
Block(-5,-13,2,NETHER_BRICK)
Block(-5,-13,3,NETHER_BRICK)
Block(-5,-12,-3,NETHER_BRICK)
Block(-5,-12,-2,NETHER_BRICK)
Block(-5,-12,-1,NETHER_BRICK)
Block(-5,-12,0,NETHER_BRICK)
Block(-5,-12,1,NETHER_BRICK)
Block(-5,-12,2,NETHER_BRICK)
Block(-5,-12,3,NETHER_BRICK)
Block(-5,-11,-3,NETHER_BRICK)
Block(-5,-11,-2,NETHER_BRICK)
Block(-5,-11,-1,NETHER_BRICK)
Block(-5,-11,0,NETHER_BRICK)
Block(-5,-11,1,NETHER_BRICK)
Block(-5,-11,2,NETHER_BRICK)
Block(-5,-11,3,NETHER_BRICK)
Block(-5,-10,-3,NETHER_BRICK)
Block(-5,-10,-2,NETHER_BRICK)
Block(-5,-10,-1,NETHER_BRICK)
Block(-5,-10,0,NETHER_BRICK)
Block(-5,-10,1,NETHER_BRICK)
Block(-5,-10,2,NETHER_BRICK)
Block(-5,-10,3,NETHER_BRICK)
Block(-5,-9,-3,NETHER_BRICK)
Block(-5,-9,-2,NETHER_BRICK)
Block(-5,-9,-1,NETHER_BRICK)
Block(-5,-9,0,NETHER_BRICK)
Block(-5,-9,1,NETHER_BRICK)
Block(-5,-9,2,NETHER_BRICK)
Block(-5,-9,3,NETHER_BRICK)
Block(-5,-8,-3,NETHER_BRICK)
Block(-5,-8,-2,NETHER_BRICK)
Block(-5,-8,-1,NETHER_BRICK)
Block(-5,-8,0,NETHER_BRICK)
Block(-5,-8,1,NETHER_BRICK)
Block(-5,-8,2,NETHER_BRICK)
Block(-5,-8,3,NETHER_BRICK)
Block(-5,-7,-3,NETHER_BRICK)
Block(-5,-7,-2,NETHER_BRICK)
Block(-5,-7,-1,NETHER_BRICK)
Block(-5,-7,0,NETHER_BRICK)
Block(-5,-7,1,NETHER_BRICK)
Block(-5,-7,2,NETHER_BRICK)
Block(-5,-7,3,NETHER_BRICK)
Block(-5,-6,-3,NETHER_BRICK)
Block(-5,-6,-2,NETHER_BRICK)
Block(-5,-6,-1,NETHER_BRICK)
Block(-5,-6,0,NETHER_BRICK)
Block(-5,-6,1,NETHER_BRICK)
Block(-5,-6,2,NETHER_BRICK)
Block(-5,-6,3,NETHER_BRICK)
Block(-5,-5,-3,NETHER_BRICK)
Block(-5,-5,-2,NETHER_BRICK)
Block(-5,-5,-1,NETHER_BRICK)
Block(-5,-5,0,NETHER_BRICK)
Block(-5,-5,1,NETHER_BRICK)
Block(-5,-5,2,NETHER_BRICK)
Block(-5,-5,3,NETHER_BRICK)
Block(-5,-4,-3,NETHER_BRICK)
Block(-5,-4,-2,NETHER_BRICK)
Block(-5,-4,-1,NETHER_BRICK)
Block(-5,-4,0,NETHER_BRICK)
Block(-5,-4,1,NETHER_BRICK)
Block(-5,-4,2,NETHER_BRICK)
Block(-5,-4,3,NETHER_BRICK)
Block(-5,-3,-3,NETHER_BRICK)
Block(-5,-3,-2,NETHER_BRICK)
Block(-5,-3,-1,NETHER_BRICK)
Block(-5,-3,0,NETHER_BRICK)
Block(-5,-3,1,NETHER_BRICK)
Block(-5,-3,2,NETHER_BRICK)
Block(-5,-3,3,NETHER_BRICK)
Block(-5,-2,-3,NETHER_BRICK)
Block(-5,-2,-2,NETHER_BRICK)
Block(-5,-2,-1,NETHER_BRICK)
Block(-5,-2,0,NETHER_BRICK)
Block(-5,-2,1,NETHER_BRICK)
Block(-5,-2,2,NETHER_BRICK)
Block(-5,-2,3,NETHER_BRICK)
Block(-5,-1,-3,NETHER_FENCE)
Block(-5,-1,-2,NETHER_BRICK)
Block(-5,-1,-1,NETHER_BRICK)
Block(-5,-1,0,NETHER_BRICK)
Block(-5,-1,1,NETHER_BRICK)
Block(-5,-1,2,NETHER_BRICK)
Block(-5,-1,3,NETHER_FENCE)
Block(-5,0,-3,NETHER_FENCE)
Block(-5,0,-2,NETHER_BRICK)
Block(-5,0,-1,NETHER_BRICK)
Block(-5,0,0,NETHER_BRICK)
Block(-5,0,1,NETHER_BRICK)
Block(-5,0,2,NETHER_BRICK)
Block(-5,0,3,NETHER_FENCE)
Block(-5,1,-3,NETHER_BRICK)
Block(-5,1,-2,NETHER_BRICK)
Block(-5,1,-1,NETHER_BRICK)
Block(-5,1,0,NETHER_BRICK)
Block(-5,1,1,NETHER_BRICK)
Block(-5,1,2,NETHER_BRICK)
Block(-5,1,3,NETHER_BRICK)
Block(-5,2,-3,NETHER_BRICK)
Block(-5,2,-2,AIR)
Block(-5,2,-1,AIR)
Block(-5,2,0,AIR)
Block(-5,2,1,AIR)
Block(-5,2,2,AIR)
Block(-5,2,3,NETHER_BRICK)
Block(-5,3,-3,NETHER_BRICK)
Block(-5,3,-2,AIR)
Block(-5,3,-1,AIR)
Block(-5,3,0,AIR)
Block(-5,3,1,AIR)
Block(-5,3,2,AIR)
Block(-5,3,3,NETHER_BRICK)
Block(-5,4,-3,NETHER_BRICK)
Block(-5,4,-2,AIR)
Block(-5,4,-1,AIR)
Block(-5,4,0,AIR)
Block(-5,4,1,AIR)
Block(-5,4,2,AIR)
Block(-5,4,3,NETHER_BRICK)
Block(-5,5,-3,NETHER_BRICK)
Block(-5,5,-2,NETHER_BRICK_STAIRS:7)
Block(-5,5,-1,AIR)
Block(-5,5,0,AIR)
Block(-5,5,1,AIR)
Block(-5,5,2,NETHER_BRICK_STAIRS:6)
Block(-5,5,3,NETHER_BRICK)
Block(-5,6,-3,NETHER_BRICK)
Block(-5,6,-2,NETHER_BRICK)
Block(-5,6,-1,NETHER_BRICK)
Block(-5,6,0,NETHER_BRICK)
Block(-5,6,1,NETHER_BRICK)
Block(-5,6,2,NETHER_BRICK)
Block(-5,6,3,NETHER_BRICK)
Block(-4,-39,-3,NETHER_BRICK)
Block(-4,-39,-2,NETHER_BRICK)
Block(-4,-39,-1,NETHER_BRICK)
Block(-4,-39,0,NETHER_BRICK)
Block(-4,-39,1,NETHER_BRICK)
Block(-4,-39,2,NETHER_BRICK)
Block(-4,-39,3,NETHER_BRICK)
Block(-4,-38,-3,NETHER_BRICK)
Block(-4,-38,-2,NETHER_BRICK)
Block(-4,-38,-1,NETHER_BRICK)
Block(-4,-38,0,NETHER_BRICK)
Block(-4,-38,1,NETHER_BRICK)
Block(-4,-38,2,NETHER_BRICK)
Block(-4,-38,3,NETHER_BRICK)
Block(-4,-37,-3,NETHER_BRICK)
Block(-4,-37,-2,NETHER_BRICK)
Block(-4,-37,-1,NETHER_BRICK)
Block(-4,-37,0,NETHER_BRICK)
Block(-4,-37,1,NETHER_BRICK)
Block(-4,-37,2,NETHER_BRICK)
Block(-4,-37,3,NETHER_BRICK)
Block(-4,-36,-3,NETHER_BRICK)
Block(-4,-36,-2,NETHER_BRICK)
Block(-4,-36,-1,NETHER_BRICK)
Block(-4,-36,0,NETHER_BRICK)
Block(-4,-36,1,NETHER_BRICK)
Block(-4,-36,2,NETHER_BRICK)
Block(-4,-36,3,NETHER_BRICK)
Block(-4,-35,-3,NETHER_BRICK)
Block(-4,-35,-2,NETHER_BRICK)
Block(-4,-35,-1,NETHER_BRICK)
Block(-4,-35,0,NETHER_BRICK)
Block(-4,-35,1,NETHER_BRICK)
Block(-4,-35,2,NETHER_BRICK)
Block(-4,-35,3,NETHER_BRICK)
Block(-4,-34,-3,NETHER_BRICK)
Block(-4,-34,-2,NETHER_BRICK)
Block(-4,-34,-1,NETHER_BRICK)
Block(-4,-34,0,NETHER_BRICK)
Block(-4,-34,1,NETHER_BRICK)
Block(-4,-34,2,NETHER_BRICK)
Block(-4,-34,3,NETHER_BRICK)
Block(-4,-33,-3,NETHER_BRICK)
Block(-4,-33,-2,NETHER_BRICK)
Block(-4,-33,-1,NETHER_BRICK)
Block(-4,-33,0,NETHER_BRICK)
Block(-4,-33,1,NETHER_BRICK)
Block(-4,-33,2,NETHER_BRICK)
Block(-4,-33,3,NETHER_BRICK)
Block(-4,-32,-3,NETHER_BRICK)
Block(-4,-32,-2,NETHER_BRICK)
Block(-4,-32,-1,NETHER_BRICK)
Block(-4,-32,0,NETHER_BRICK)
Block(-4,-32,1,NETHER_BRICK)
Block(-4,-32,2,NETHER_BRICK)
Block(-4,-32,3,NETHER_BRICK)
Block(-4,-31,-3,NETHER_BRICK)
Block(-4,-31,-2,NETHER_BRICK)
Block(-4,-31,-1,NETHER_BRICK)
Block(-4,-31,0,NETHER_BRICK)
Block(-4,-31,1,NETHER_BRICK)
Block(-4,-31,2,NETHER_BRICK)
Block(-4,-31,3,NETHER_BRICK)
Block(-4,-30,-3,NETHER_BRICK)
Block(-4,-30,-2,NETHER_BRICK)
Block(-4,-30,-1,NETHER_BRICK)
Block(-4,-30,0,NETHER_BRICK)
Block(-4,-30,1,NETHER_BRICK)
Block(-4,-30,2,NETHER_BRICK)
Block(-4,-30,3,NETHER_BRICK)
Block(-4,-29,-3,NETHER_BRICK)
Block(-4,-29,-2,NETHER_BRICK)
Block(-4,-29,-1,NETHER_BRICK)
Block(-4,-29,0,NETHER_BRICK)
Block(-4,-29,1,NETHER_BRICK)
Block(-4,-29,2,NETHER_BRICK)
Block(-4,-29,3,NETHER_BRICK)
Block(-4,-28,-3,NETHER_BRICK)
Block(-4,-28,-2,NETHER_BRICK)
Block(-4,-28,-1,NETHER_BRICK)
Block(-4,-28,0,NETHER_BRICK)
Block(-4,-28,1,NETHER_BRICK)
Block(-4,-28,2,NETHER_BRICK)
Block(-4,-28,3,NETHER_BRICK)
Block(-4,-27,-3,NETHER_BRICK)
Block(-4,-27,-2,NETHER_BRICK)
Block(-4,-27,-1,NETHER_BRICK)
Block(-4,-27,0,NETHER_BRICK)
Block(-4,-27,1,NETHER_BRICK)
Block(-4,-27,2,NETHER_BRICK)
Block(-4,-27,3,NETHER_BRICK)
Block(-4,-26,-3,NETHER_BRICK)
Block(-4,-26,-2,NETHER_BRICK)
Block(-4,-26,-1,NETHER_BRICK)
Block(-4,-26,0,NETHER_BRICK)
Block(-4,-26,1,NETHER_BRICK)
Block(-4,-26,2,NETHER_BRICK)
Block(-4,-26,3,NETHER_BRICK)
Block(-4,-25,-3,NETHER_BRICK)
Block(-4,-25,-2,NETHER_BRICK)
Block(-4,-25,-1,NETHER_BRICK)
Block(-4,-25,0,NETHER_BRICK)
Block(-4,-25,1,NETHER_BRICK)
Block(-4,-25,2,NETHER_BRICK)
Block(-4,-25,3,NETHER_BRICK)
Block(-4,-24,-3,NETHER_BRICK)
Block(-4,-24,-2,NETHER_BRICK)
Block(-4,-24,-1,NETHER_BRICK)
Block(-4,-24,0,NETHER_BRICK)
Block(-4,-24,1,NETHER_BRICK)
Block(-4,-24,2,NETHER_BRICK)
Block(-4,-24,3,NETHER_BRICK)
Block(-4,-23,-3,NETHER_BRICK)
Block(-4,-23,-2,NETHER_BRICK)
Block(-4,-23,-1,NETHER_BRICK)
Block(-4,-23,0,NETHER_BRICK)
Block(-4,-23,1,NETHER_BRICK)
Block(-4,-23,2,NETHER_BRICK)
Block(-4,-23,3,NETHER_BRICK)
Block(-4,-22,-3,NETHER_BRICK)
Block(-4,-22,-2,NETHER_BRICK)
Block(-4,-22,-1,NETHER_BRICK)
Block(-4,-22,0,NETHER_BRICK)
Block(-4,-22,1,NETHER_BRICK)
Block(-4,-22,2,NETHER_BRICK)
Block(-4,-22,3,NETHER_BRICK)
Block(-4,-21,-3,NETHER_BRICK)
Block(-4,-21,-2,NETHER_BRICK)
Block(-4,-21,-1,NETHER_BRICK)
Block(-4,-21,0,NETHER_BRICK)
Block(-4,-21,1,NETHER_BRICK)
Block(-4,-21,2,NETHER_BRICK)
Block(-4,-21,3,NETHER_BRICK)
Block(-4,-20,-3,NETHER_BRICK)
Block(-4,-20,-2,NETHER_BRICK)
Block(-4,-20,-1,NETHER_BRICK)
Block(-4,-20,0,NETHER_BRICK)
Block(-4,-20,1,NETHER_BRICK)
Block(-4,-20,2,NETHER_BRICK)
Block(-4,-20,3,NETHER_BRICK)
Block(-4,-19,-3,NETHER_BRICK)
Block(-4,-19,-2,NETHER_BRICK)
Block(-4,-19,-1,NETHER_BRICK)
Block(-4,-19,0,NETHER_BRICK)
Block(-4,-19,1,NETHER_BRICK)
Block(-4,-19,2,NETHER_BRICK)
Block(-4,-19,3,NETHER_BRICK)
Block(-4,-18,-3,NETHER_BRICK)
Block(-4,-18,-2,NETHER_BRICK)
Block(-4,-18,-1,NETHER_BRICK)
Block(-4,-18,0,NETHER_BRICK)
Block(-4,-18,1,NETHER_BRICK)
Block(-4,-18,2,NETHER_BRICK)
Block(-4,-18,3,NETHER_BRICK)
Block(-4,-17,-3,NETHER_BRICK)
Block(-4,-17,-2,NETHER_BRICK)
Block(-4,-17,-1,NETHER_BRICK)
Block(-4,-17,0,NETHER_BRICK)
Block(-4,-17,1,NETHER_BRICK)
Block(-4,-17,2,NETHER_BRICK)
Block(-4,-17,3,NETHER_BRICK)
Block(-4,-16,-3,NETHER_BRICK)
Block(-4,-16,-2,NETHER_BRICK)
Block(-4,-16,-1,NETHER_BRICK)
Block(-4,-16,0,NETHER_BRICK)
Block(-4,-16,1,NETHER_BRICK)
Block(-4,-16,2,NETHER_BRICK)
Block(-4,-16,3,NETHER_BRICK)
Block(-4,-15,-3,NETHER_BRICK)
Block(-4,-15,-2,NETHER_BRICK)
Block(-4,-15,-1,NETHER_BRICK)
Block(-4,-15,0,NETHER_BRICK)
Block(-4,-15,1,NETHER_BRICK)
Block(-4,-15,2,NETHER_BRICK)
Block(-4,-15,3,NETHER_BRICK)
Block(-4,-14,-3,NETHER_BRICK)
Block(-4,-14,-2,NETHER_BRICK)
Block(-4,-14,-1,NETHER_BRICK)
Block(-4,-14,0,NETHER_BRICK)
Block(-4,-14,1,NETHER_BRICK)
Block(-4,-14,2,NETHER_BRICK)
Block(-4,-14,3,NETHER_BRICK)
Block(-4,-13,-3,NETHER_BRICK)
Block(-4,-13,-2,NETHER_BRICK)
Block(-4,-13,-1,NETHER_BRICK)
Block(-4,-13,0,NETHER_BRICK)
Block(-4,-13,1,NETHER_BRICK)
Block(-4,-13,2,NETHER_BRICK)
Block(-4,-13,3,NETHER_BRICK)
Block(-4,-12,-3,NETHER_BRICK)
Block(-4,-12,-2,NETHER_BRICK)
Block(-4,-12,-1,NETHER_BRICK)
Block(-4,-12,0,NETHER_BRICK)
Block(-4,-12,1,NETHER_BRICK)
Block(-4,-12,2,NETHER_BRICK)
Block(-4,-12,3,NETHER_BRICK)
Block(-4,-11,-3,NETHER_BRICK)
Block(-4,-11,-2,NETHER_BRICK)
Block(-4,-11,-1,NETHER_BRICK)
Block(-4,-11,0,NETHER_BRICK)
Block(-4,-11,1,NETHER_BRICK)
Block(-4,-11,2,NETHER_BRICK)
Block(-4,-11,3,NETHER_BRICK)
Block(-4,-10,-3,NETHER_BRICK)
Block(-4,-10,-2,NETHER_BRICK)
Block(-4,-10,-1,NETHER_BRICK)
Block(-4,-10,0,NETHER_BRICK)
Block(-4,-10,1,NETHER_BRICK)
Block(-4,-10,2,NETHER_BRICK)
Block(-4,-10,3,NETHER_BRICK)
Block(-4,-9,-3,NETHER_BRICK)
Block(-4,-9,-2,NETHER_BRICK)
Block(-4,-9,-1,NETHER_BRICK)
Block(-4,-9,0,NETHER_BRICK)
Block(-4,-9,1,NETHER_BRICK)
Block(-4,-9,2,NETHER_BRICK)
Block(-4,-9,3,NETHER_BRICK)
Block(-4,-8,-3,NETHER_BRICK)
Block(-4,-8,-2,NETHER_BRICK)
Block(-4,-8,-1,NETHER_BRICK)
Block(-4,-8,0,NETHER_BRICK)
Block(-4,-8,1,NETHER_BRICK)
Block(-4,-8,2,NETHER_BRICK)
Block(-4,-8,3,NETHER_BRICK)
Block(-4,-7,-3,NETHER_BRICK)
Block(-4,-7,-2,NETHER_BRICK)
Block(-4,-7,-1,NETHER_BRICK)
Block(-4,-7,0,NETHER_BRICK)
Block(-4,-7,1,NETHER_BRICK)
Block(-4,-7,2,NETHER_BRICK)
Block(-4,-7,3,NETHER_BRICK)
Block(-4,-6,-3,NETHER_BRICK)
Block(-4,-6,-2,NETHER_BRICK)
Block(-4,-6,-1,NETHER_BRICK)
Block(-4,-6,0,NETHER_BRICK)
Block(-4,-6,1,NETHER_BRICK)
Block(-4,-6,2,NETHER_BRICK)
Block(-4,-6,3,NETHER_BRICK)
Block(-4,-5,-3,NETHER_BRICK)
Block(-4,-5,-2,NETHER_BRICK)
Block(-4,-5,-1,NETHER_BRICK)
Block(-4,-5,0,NETHER_BRICK)
Block(-4,-5,1,NETHER_BRICK)
Block(-4,-5,2,NETHER_BRICK)
Block(-4,-5,3,NETHER_BRICK)
Block(-4,-4,-3,NETHER_BRICK)
Block(-4,-4,-2,NETHER_BRICK)
Block(-4,-4,-1,NETHER_BRICK)
Block(-4,-4,0,NETHER_BRICK)
Block(-4,-4,1,NETHER_BRICK)
Block(-4,-4,2,NETHER_BRICK)
Block(-4,-4,3,NETHER_BRICK)
Block(-4,-3,-3,NETHER_BRICK)
Block(-4,-3,-2,NETHER_BRICK)
Block(-4,-3,-1,NETHER_BRICK)
Block(-4,-3,0,NETHER_BRICK)
Block(-4,-3,1,NETHER_BRICK)
Block(-4,-3,2,NETHER_BRICK)
Block(-4,-3,3,NETHER_BRICK)
Block(-4,-2,-3,NETHER_BRICK)
Block(-4,-2,-2,NETHER_BRICK)
Block(-4,-2,-1,NETHER_BRICK)
Block(-4,-2,0,NETHER_BRICK)
Block(-4,-2,1,NETHER_BRICK)
Block(-4,-2,2,NETHER_BRICK)
Block(-4,-2,3,NETHER_BRICK)
Block(-4,-1,-3,NETHER_BRICK)
Block(-4,-1,-2,NETHER_BRICK)
Block(-4,-1,-1,NETHER_BRICK)
Block(-4,-1,0,NETHER_BRICK)
Block(-4,-1,1,NETHER_BRICK)
Block(-4,-1,2,NETHER_BRICK)
Block(-4,-1,3,NETHER_BRICK)
Block(-4,0,-3,NETHER_BRICK)
Block(-4,0,-2,NETHER_BRICK)
Block(-4,0,-1,NETHER_BRICK)
Block(-4,0,0,NETHER_BRICK)
Block(-4,0,1,NETHER_BRICK)
Block(-4,0,2,NETHER_BRICK)
Block(-4,0,3,NETHER_BRICK)
Block(-4,1,-3,NETHER_BRICK)
Block(-4,1,-2,NETHER_BRICK)
Block(-4,1,-1,NETHER_BRICK)
Block(-4,1,0,NETHER_BRICK)
Block(-4,1,1,NETHER_BRICK)
Block(-4,1,2,NETHER_BRICK)
Block(-4,1,3,NETHER_BRICK)
Block(-4,2,-3,NETHER_BRICK)
Block(-4,2,-2,AIR)
Block(-4,2,-1,AIR)
Block(-4,2,0,AIR)
Block(-4,2,1,AIR)
Block(-4,2,2,AIR)
Block(-4,2,3,NETHER_BRICK)
Block(-4,3,-3,NETHER_FENCE)
Block(-4,3,-2,AIR)
Block(-4,3,-1,AIR)
Block(-4,3,0,AIR)
Block(-4,3,1,AIR)
Block(-4,3,2,AIR)
Block(-4,3,3,NETHER_FENCE)
Block(-4,4,-3,NETHER_FENCE)
Block(-4,4,-2,AIR)
Block(-4,4,-1,AIR)
Block(-4,4,0,AIR)
Block(-4,4,1,AIR)
Block(-4,4,2,AIR)
Block(-4,4,3,NETHER_FENCE)
Block(-4,5,-3,NETHER_BRICK)
Block(-4,5,-2,AIR)
Block(-4,5,-1,AIR)
Block(-4,5,0,AIR)
Block(-4,5,1,AIR)
Block(-4,5,2,AIR)
Block(-4,5,3,NETHER_BRICK)
Block(-4,6,-3,NETHER_BRICK)
Block(-4,6,-2,NETHER_BRICK)
Block(-4,6,-1,NETHER_BRICK)
Block(-4,6,0,NETHER_BRICK)
Block(-4,6,1,NETHER_BRICK)
Block(-4,6,2,NETHER_BRICK)
Block(-4,6,3,NETHER_BRICK)
Block(-4,7,-2,NETHER_BRICK)
Block(-4,7,-1,NETHER_BRICK)
Block(-4,7,0,NETHER_BRICK)
Block(-4,7,1,NETHER_BRICK)
Block(-4,7,2,NETHER_BRICK)
Block(-4,8,-2,NETHER_BRICK)
Block(-4,8,-1,NETHER_FENCE)
Block(-4,8,0,NETHER_BRICK)
Block(-4,8,1,NETHER_FENCE)
Block(-4,8,2,NETHER_BRICK)
Block(-4,9,-2,NETHER_BRICK)
Block(-4,9,-1,NETHER_FENCE)
Block(-4,9,0,NETHER_BRICK)
Block(-4,9,1,NETHER_FENCE)
Block(-4,9,2,NETHER_BRICK)
Block(-4,10,-2,NETHER_BRICK)
Block(-4,10,-1,NETHER_FENCE)
Block(-4,10,0,NETHER_BRICK)
Block(-4,10,1,NETHER_FENCE)
Block(-4,10,2,NETHER_BRICK)
Block(-4,11,-2,NETHER_BRICK)
Block(-4,11,-1,NETHER_BRICK)
Block(-4,11,0,NETHER_BRICK)
Block(-4,11,1,NETHER_BRICK)
Block(-4,11,2,NETHER_BRICK)
Block(-4,12,-2,NETHER_BRICK)
Block(-4,12,-1,NETHER_FENCE)
Block(-4,12,0,NETHER_BRICK)
Block(-4,12,1,NETHER_FENCE)
Block(-4,12,2,NETHER_BRICK)
Block(-4,13,-2,NETHER_BRICK)
Block(-4,13,-1,NETHER_FENCE)
Block(-4,13,0,NETHER_BRICK)
Block(-4,13,1,NETHER_FENCE)
Block(-4,13,2,NETHER_BRICK)
Block(-4,14,-2,NETHER_BRICK)
Block(-4,14,-1,NETHER_FENCE)
Block(-4,14,0,NETHER_BRICK)
Block(-4,14,1,NETHER_FENCE)
Block(-4,14,2,NETHER_BRICK)
Block(-4,15,-2,NETHER_BRICK)
Block(-4,15,-1,NETHER_BRICK)
Block(-4,15,0,NETHER_BRICK)
Block(-4,15,1,NETHER_BRICK)
Block(-4,15,2,NETHER_BRICK)
Block(-4,16,-2,NETHER_BRICK)
Block(-4,16,-1,NETHER_FENCE)
Block(-4,16,0,NETHER_BRICK)
Block(-4,16,1,NETHER_FENCE)
Block(-4,16,2,NETHER_BRICK)
Block(-4,17,-2,NETHER_BRICK)
Block(-4,17,-1,NETHER_FENCE)
Block(-4,17,0,NETHER_BRICK)
Block(-4,17,1,NETHER_FENCE)
Block(-4,17,2,NETHER_BRICK)
Block(-4,18,-2,NETHER_BRICK)
Block(-4,18,-1,NETHER_FENCE)
Block(-4,18,0,NETHER_BRICK)
Block(-4,18,1,NETHER_FENCE)
Block(-4,18,2,NETHER_BRICK)
Block(-4,19,-2,NETHER_BRICK)
Block(-4,19,-1,NETHER_BRICK)
Block(-4,19,0,NETHER_BRICK)
Block(-4,19,1,NETHER_BRICK)
Block(-4,19,2,NETHER_BRICK)
Block(-4,20,-2,NETHER_BRICK)
Block(-4,20,-1,NETHER_FENCE)
Block(-4,20,0,NETHER_BRICK)
Block(-4,20,1,NETHER_FENCE)
Block(-4,20,2,NETHER_BRICK)
Block(-4,21,-2,NETHER_BRICK)
Block(-4,21,-1,NETHER_FENCE)
Block(-4,21,0,NETHER_BRICK)
Block(-4,21,1,NETHER_FENCE)
Block(-4,21,2,NETHER_BRICK)
Block(-4,22,-2,NETHER_BRICK)
Block(-4,22,-1,NETHER_FENCE)
Block(-4,22,0,NETHER_BRICK)
Block(-4,22,1,NETHER_FENCE)
Block(-4,22,2,NETHER_BRICK)
Block(-4,23,-2,NETHER_BRICK)
Block(-4,23,-1,NETHER_BRICK)
Block(-4,23,0,NETHER_BRICK)
Block(-4,23,1,NETHER_BRICK)
Block(-4,23,2,NETHER_BRICK)
Block(-4,24,-2,NETHER_BRICK)
Block(-4,24,-1,NETHER_FENCE)
Block(-4,24,0,NETHER_BRICK)
Block(-4,24,1,NETHER_FENCE)
Block(-4,24,2,NETHER_BRICK)
Block(-4,25,-2,NETHER_BRICK)
Block(-4,25,-1,NETHER_FENCE)
Block(-4,25,0,NETHER_BRICK)
Block(-4,25,1,NETHER_FENCE)
Block(-4,25,2,NETHER_BRICK)
Block(-4,26,-2,NETHER_BRICK)
Block(-4,26,-1,NETHER_FENCE)
Block(-4,26,0,NETHER_BRICK)
Block(-4,26,1,NETHER_FENCE)
Block(-4,26,2,NETHER_BRICK)
Block(-4,27,-2,NETHER_BRICK)
Block(-4,27,-1,NETHER_BRICK)
Block(-4,27,0,NETHER_BRICK)
Block(-4,27,1,NETHER_BRICK)
Block(-4,27,2,NETHER_BRICK)
Block(-3,-39,-6,NETHER_BRICK)
Block(-3,-39,-5,NETHER_BRICK)
Block(-3,-39,-4,NETHER_BRICK)
Block(-3,-39,-3,NETHER_BRICK)
Block(-3,-39,-2,NETHER_BRICK)
Block(-3,-39,-1,NETHER_BRICK)
Block(-3,-39,0,NETHER_BRICK)
Block(-3,-39,1,NETHER_BRICK)
Block(-3,-39,2,NETHER_BRICK)
Block(-3,-39,3,NETHER_BRICK)
Block(-3,-39,4,NETHER_BRICK)
Block(-3,-39,5,NETHER_BRICK)
Block(-3,-39,6,NETHER_BRICK)
Block(-3,-38,-6,NETHER_BRICK)
Block(-3,-38,-5,NETHER_BRICK)
Block(-3,-38,-4,NETHER_BRICK)
Block(-3,-38,-3,NETHER_BRICK)
Block(-3,-38,-2,NETHER_BRICK)
Block(-3,-38,-1,NETHER_BRICK)
Block(-3,-38,0,NETHER_BRICK)
Block(-3,-38,1,NETHER_BRICK)
Block(-3,-38,2,NETHER_BRICK)
Block(-3,-38,3,NETHER_BRICK)
Block(-3,-38,4,NETHER_BRICK)
Block(-3,-38,5,NETHER_BRICK)
Block(-3,-38,6,NETHER_BRICK)
Block(-3,-37,-6,NETHER_BRICK)
Block(-3,-37,-5,NETHER_BRICK)
Block(-3,-37,-4,NETHER_BRICK)
Block(-3,-37,-3,NETHER_BRICK)
Block(-3,-37,-2,NETHER_BRICK)
Block(-3,-37,-1,NETHER_BRICK)
Block(-3,-37,0,NETHER_BRICK)
Block(-3,-37,1,NETHER_BRICK)
Block(-3,-37,2,NETHER_BRICK)
Block(-3,-37,3,NETHER_BRICK)
Block(-3,-37,4,NETHER_BRICK)
Block(-3,-37,5,NETHER_BRICK)
Block(-3,-37,6,NETHER_BRICK)
Block(-3,-36,-6,NETHER_BRICK)
Block(-3,-36,-5,NETHER_BRICK)
Block(-3,-36,-4,NETHER_BRICK)
Block(-3,-36,-3,NETHER_BRICK)
Block(-3,-36,-2,NETHER_BRICK)
Block(-3,-36,-1,NETHER_BRICK)
Block(-3,-36,0,NETHER_BRICK)
Block(-3,-36,1,NETHER_BRICK)
Block(-3,-36,2,NETHER_BRICK)
Block(-3,-36,3,NETHER_BRICK)
Block(-3,-36,4,NETHER_BRICK)
Block(-3,-36,5,NETHER_BRICK)
Block(-3,-36,6,NETHER_BRICK)
Block(-3,-35,-6,NETHER_BRICK)
Block(-3,-35,-5,NETHER_BRICK)
Block(-3,-35,-4,NETHER_BRICK)
Block(-3,-35,-3,NETHER_BRICK)
Block(-3,-35,-2,NETHER_BRICK)
Block(-3,-35,-1,NETHER_BRICK)
Block(-3,-35,0,NETHER_BRICK)
Block(-3,-35,1,NETHER_BRICK)
Block(-3,-35,2,NETHER_BRICK)
Block(-3,-35,3,NETHER_BRICK)
Block(-3,-35,4,NETHER_BRICK)
Block(-3,-35,5,NETHER_BRICK)
Block(-3,-35,6,NETHER_BRICK)
Block(-3,-34,-6,NETHER_BRICK)
Block(-3,-34,-5,NETHER_BRICK)
Block(-3,-34,-4,NETHER_BRICK)
Block(-3,-34,-3,NETHER_BRICK)
Block(-3,-34,-2,NETHER_BRICK)
Block(-3,-34,-1,NETHER_BRICK)
Block(-3,-34,0,NETHER_BRICK)
Block(-3,-34,1,NETHER_BRICK)
Block(-3,-34,2,NETHER_BRICK)
Block(-3,-34,3,NETHER_BRICK)
Block(-3,-34,4,NETHER_BRICK)
Block(-3,-34,5,NETHER_BRICK)
Block(-3,-34,6,NETHER_BRICK)
Block(-3,-33,-6,NETHER_BRICK)
Block(-3,-33,-5,NETHER_BRICK)
Block(-3,-33,-4,NETHER_BRICK)
Block(-3,-33,-3,NETHER_BRICK)
Block(-3,-33,-2,NETHER_BRICK)
Block(-3,-33,-1,NETHER_BRICK)
Block(-3,-33,0,NETHER_BRICK)
Block(-3,-33,1,NETHER_BRICK)
Block(-3,-33,2,NETHER_BRICK)
Block(-3,-33,3,NETHER_BRICK)
Block(-3,-33,4,NETHER_BRICK)
Block(-3,-33,5,NETHER_BRICK)
Block(-3,-33,6,NETHER_BRICK)
Block(-3,-32,-6,NETHER_BRICK)
Block(-3,-32,-5,NETHER_BRICK)
Block(-3,-32,-4,NETHER_BRICK)
Block(-3,-32,-3,NETHER_BRICK)
Block(-3,-32,-2,NETHER_BRICK)
Block(-3,-32,-1,NETHER_BRICK)
Block(-3,-32,0,NETHER_BRICK)
Block(-3,-32,1,NETHER_BRICK)
Block(-3,-32,2,NETHER_BRICK)
Block(-3,-32,3,NETHER_BRICK)
Block(-3,-32,4,NETHER_BRICK)
Block(-3,-32,5,NETHER_BRICK)
Block(-3,-32,6,NETHER_BRICK)
Block(-3,-31,-6,NETHER_BRICK)
Block(-3,-31,-5,NETHER_BRICK)
Block(-3,-31,-4,NETHER_BRICK)
Block(-3,-31,-3,NETHER_BRICK)
Block(-3,-31,-2,NETHER_BRICK)
Block(-3,-31,-1,NETHER_BRICK)
Block(-3,-31,0,NETHER_BRICK)
Block(-3,-31,1,NETHER_BRICK)
Block(-3,-31,2,NETHER_BRICK)
Block(-3,-31,3,NETHER_BRICK)
Block(-3,-31,4,NETHER_BRICK)
Block(-3,-31,5,NETHER_BRICK)
Block(-3,-31,6,NETHER_BRICK)
Block(-3,-30,-6,NETHER_BRICK)
Block(-3,-30,-5,NETHER_BRICK)
Block(-3,-30,-4,NETHER_BRICK)
Block(-3,-30,-3,NETHER_BRICK)
Block(-3,-30,-2,NETHER_BRICK)
Block(-3,-30,-1,NETHER_BRICK)
Block(-3,-30,0,NETHER_BRICK)
Block(-3,-30,1,NETHER_BRICK)
Block(-3,-30,2,NETHER_BRICK)
Block(-3,-30,3,NETHER_BRICK)
Block(-3,-30,4,NETHER_BRICK)
Block(-3,-30,5,NETHER_BRICK)
Block(-3,-30,6,NETHER_BRICK)
Block(-3,-29,-6,NETHER_BRICK)
Block(-3,-29,-5,NETHER_BRICK)
Block(-3,-29,-4,NETHER_BRICK)
Block(-3,-29,-3,NETHER_BRICK)
Block(-3,-29,-2,NETHER_BRICK)
Block(-3,-29,-1,NETHER_BRICK)
Block(-3,-29,0,NETHER_BRICK)
Block(-3,-29,1,NETHER_BRICK)
Block(-3,-29,2,NETHER_BRICK)
Block(-3,-29,3,NETHER_BRICK)
Block(-3,-29,4,NETHER_BRICK)
Block(-3,-29,5,NETHER_BRICK)
Block(-3,-29,6,NETHER_BRICK)
Block(-3,-28,-6,NETHER_BRICK)
Block(-3,-28,-5,NETHER_BRICK)
Block(-3,-28,-4,NETHER_BRICK)
Block(-3,-28,-3,NETHER_BRICK)
Block(-3,-28,-2,NETHER_BRICK)
Block(-3,-28,-1,NETHER_BRICK)
Block(-3,-28,0,NETHER_BRICK)
Block(-3,-28,1,NETHER_BRICK)
Block(-3,-28,2,NETHER_BRICK)
Block(-3,-28,3,NETHER_BRICK)
Block(-3,-28,4,NETHER_BRICK)
Block(-3,-28,5,NETHER_BRICK)
Block(-3,-28,6,NETHER_BRICK)
Block(-3,-27,-6,NETHER_BRICK)
Block(-3,-27,-5,NETHER_BRICK)
Block(-3,-27,-4,NETHER_BRICK)
Block(-3,-27,-3,NETHER_BRICK)
Block(-3,-27,-2,NETHER_BRICK)
Block(-3,-27,-1,NETHER_BRICK)
Block(-3,-27,0,NETHER_BRICK)
Block(-3,-27,1,NETHER_BRICK)
Block(-3,-27,2,NETHER_BRICK)
Block(-3,-27,3,NETHER_BRICK)
Block(-3,-27,4,NETHER_BRICK)
Block(-3,-27,5,NETHER_BRICK)
Block(-3,-27,6,NETHER_BRICK)
Block(-3,-26,-6,NETHER_BRICK)
Block(-3,-26,-5,NETHER_BRICK)
Block(-3,-26,-4,NETHER_BRICK)
Block(-3,-26,-3,NETHER_BRICK)
Block(-3,-26,-2,NETHER_BRICK)
Block(-3,-26,-1,NETHER_BRICK)
Block(-3,-26,0,NETHER_BRICK)
Block(-3,-26,1,NETHER_BRICK)
Block(-3,-26,2,NETHER_BRICK)
Block(-3,-26,3,NETHER_BRICK)
Block(-3,-26,4,NETHER_BRICK)
Block(-3,-26,5,NETHER_BRICK)
Block(-3,-26,6,NETHER_BRICK)
Block(-3,-25,-6,NETHER_BRICK)
Block(-3,-25,-5,NETHER_BRICK)
Block(-3,-25,-4,NETHER_BRICK)
Block(-3,-25,-3,NETHER_BRICK)
Block(-3,-25,-2,NETHER_BRICK)
Block(-3,-25,-1,NETHER_BRICK)
Block(-3,-25,0,NETHER_BRICK)
Block(-3,-25,1,NETHER_BRICK)
Block(-3,-25,2,NETHER_BRICK)
Block(-3,-25,3,NETHER_BRICK)
Block(-3,-25,4,NETHER_BRICK)
Block(-3,-25,5,NETHER_BRICK)
Block(-3,-25,6,NETHER_BRICK)
Block(-3,-24,-6,NETHER_BRICK)
Block(-3,-24,-5,NETHER_BRICK)
Block(-3,-24,-4,NETHER_BRICK)
Block(-3,-24,-3,NETHER_BRICK)
Block(-3,-24,-2,NETHER_BRICK)
Block(-3,-24,-1,NETHER_BRICK)
Block(-3,-24,0,NETHER_BRICK)
Block(-3,-24,1,NETHER_BRICK)
Block(-3,-24,2,NETHER_BRICK)
Block(-3,-24,3,NETHER_BRICK)
Block(-3,-24,4,NETHER_BRICK)
Block(-3,-24,5,NETHER_BRICK)
Block(-3,-24,6,NETHER_BRICK)
Block(-3,-23,-6,NETHER_BRICK)
Block(-3,-23,-5,NETHER_BRICK)
Block(-3,-23,-4,NETHER_BRICK)
Block(-3,-23,-3,NETHER_BRICK)
Block(-3,-23,-2,NETHER_BRICK)
Block(-3,-23,-1,NETHER_BRICK)
Block(-3,-23,0,NETHER_BRICK)
Block(-3,-23,1,NETHER_BRICK)
Block(-3,-23,2,NETHER_BRICK)
Block(-3,-23,3,NETHER_BRICK)
Block(-3,-23,4,NETHER_BRICK)
Block(-3,-23,5,NETHER_BRICK)
Block(-3,-23,6,NETHER_BRICK)
Block(-3,-22,-6,NETHER_BRICK)
Block(-3,-22,-5,NETHER_BRICK)
Block(-3,-22,-4,NETHER_BRICK)
Block(-3,-22,-3,NETHER_BRICK)
Block(-3,-22,-2,NETHER_BRICK)
Block(-3,-22,-1,NETHER_BRICK)
Block(-3,-22,0,NETHER_BRICK)
Block(-3,-22,1,NETHER_BRICK)
Block(-3,-22,2,NETHER_BRICK)
Block(-3,-22,3,NETHER_BRICK)
Block(-3,-22,4,NETHER_BRICK)
Block(-3,-22,5,NETHER_BRICK)
Block(-3,-22,6,NETHER_BRICK)
Block(-3,-21,-6,NETHER_BRICK)
Block(-3,-21,-5,NETHER_BRICK)
Block(-3,-21,-4,NETHER_BRICK)
Block(-3,-21,-3,NETHER_BRICK)
Block(-3,-21,-2,NETHER_BRICK)
Block(-3,-21,-1,NETHER_BRICK)
Block(-3,-21,0,NETHER_BRICK)
Block(-3,-21,1,NETHER_BRICK)
Block(-3,-21,2,NETHER_BRICK)
Block(-3,-21,3,NETHER_BRICK)
Block(-3,-21,4,NETHER_BRICK)
Block(-3,-21,5,NETHER_BRICK)
Block(-3,-21,6,NETHER_BRICK)
Block(-3,-20,-6,NETHER_BRICK)
Block(-3,-20,-5,NETHER_BRICK)
Block(-3,-20,-4,NETHER_BRICK)
Block(-3,-20,-3,NETHER_BRICK)
Block(-3,-20,-2,NETHER_BRICK)
Block(-3,-20,-1,NETHER_BRICK)
Block(-3,-20,0,NETHER_BRICK)
Block(-3,-20,1,NETHER_BRICK)
Block(-3,-20,2,NETHER_BRICK)
Block(-3,-20,3,NETHER_BRICK)
Block(-3,-20,4,NETHER_BRICK)
Block(-3,-20,5,NETHER_BRICK)
Block(-3,-20,6,NETHER_BRICK)
Block(-3,-19,-6,NETHER_BRICK)
Block(-3,-19,-5,NETHER_BRICK)
Block(-3,-19,-4,NETHER_BRICK)
Block(-3,-19,-3,NETHER_BRICK)
Block(-3,-19,-2,NETHER_BRICK)
Block(-3,-19,-1,NETHER_BRICK)
Block(-3,-19,0,NETHER_BRICK)
Block(-3,-19,1,NETHER_BRICK)
Block(-3,-19,2,NETHER_BRICK)
Block(-3,-19,3,NETHER_BRICK)
Block(-3,-19,4,NETHER_BRICK)
Block(-3,-19,5,NETHER_BRICK)
Block(-3,-19,6,NETHER_BRICK)
Block(-3,-18,-6,NETHER_BRICK)
Block(-3,-18,-5,NETHER_BRICK)
Block(-3,-18,-4,NETHER_BRICK)
Block(-3,-18,-3,NETHER_BRICK)
Block(-3,-18,-2,NETHER_BRICK)
Block(-3,-18,-1,NETHER_BRICK)
Block(-3,-18,0,NETHER_BRICK)
Block(-3,-18,1,NETHER_BRICK)
Block(-3,-18,2,NETHER_BRICK)
Block(-3,-18,3,NETHER_BRICK)
Block(-3,-18,4,NETHER_BRICK)
Block(-3,-18,5,NETHER_BRICK)
Block(-3,-18,6,NETHER_BRICK)
Block(-3,-17,-6,NETHER_BRICK)
Block(-3,-17,-5,NETHER_BRICK)
Block(-3,-17,-4,NETHER_BRICK)
Block(-3,-17,-3,NETHER_BRICK)
Block(-3,-17,-2,NETHER_BRICK)
Block(-3,-17,-1,NETHER_BRICK)
Block(-3,-17,0,NETHER_BRICK)
Block(-3,-17,1,NETHER_BRICK)
Block(-3,-17,2,NETHER_BRICK)
Block(-3,-17,3,NETHER_BRICK)
Block(-3,-17,4,NETHER_BRICK)
Block(-3,-17,5,NETHER_BRICK)
Block(-3,-17,6,NETHER_BRICK)
Block(-3,-16,-6,NETHER_BRICK)
Block(-3,-16,-5,NETHER_BRICK)
Block(-3,-16,-4,NETHER_BRICK)
Block(-3,-16,-3,NETHER_BRICK)
Block(-3,-16,-2,NETHER_BRICK)
Block(-3,-16,-1,NETHER_BRICK)
Block(-3,-16,0,NETHER_BRICK)
Block(-3,-16,1,NETHER_BRICK)
Block(-3,-16,2,NETHER_BRICK)
Block(-3,-16,3,NETHER_BRICK)
Block(-3,-16,4,NETHER_BRICK)
Block(-3,-16,5,NETHER_BRICK)
Block(-3,-16,6,NETHER_BRICK)
Block(-3,-15,-6,NETHER_BRICK)
Block(-3,-15,-5,NETHER_BRICK)
Block(-3,-15,-4,NETHER_BRICK)
Block(-3,-15,-3,NETHER_BRICK)
Block(-3,-15,-2,NETHER_BRICK)
Block(-3,-15,-1,NETHER_BRICK)
Block(-3,-15,0,NETHER_BRICK)
Block(-3,-15,1,NETHER_BRICK)
Block(-3,-15,2,NETHER_BRICK)
Block(-3,-15,3,NETHER_BRICK)
Block(-3,-15,4,NETHER_BRICK)
Block(-3,-15,5,NETHER_BRICK)
Block(-3,-15,6,NETHER_BRICK)
Block(-3,-14,-6,NETHER_BRICK)
Block(-3,-14,-5,NETHER_BRICK)
Block(-3,-14,-4,NETHER_BRICK)
Block(-3,-14,-3,NETHER_BRICK)
Block(-3,-14,-2,NETHER_BRICK)
Block(-3,-14,-1,NETHER_BRICK)
Block(-3,-14,0,NETHER_BRICK)
Block(-3,-14,1,NETHER_BRICK)
Block(-3,-14,2,NETHER_BRICK)
Block(-3,-14,3,NETHER_BRICK)
Block(-3,-14,4,NETHER_BRICK)
Block(-3,-14,5,NETHER_BRICK)
Block(-3,-14,6,NETHER_BRICK)
Block(-3,-13,-6,NETHER_BRICK)
Block(-3,-13,-5,NETHER_BRICK)
Block(-3,-13,-4,NETHER_BRICK)
Block(-3,-13,-3,NETHER_BRICK)
Block(-3,-13,-2,NETHER_BRICK)
Block(-3,-13,-1,NETHER_BRICK)
Block(-3,-13,0,NETHER_BRICK)
Block(-3,-13,1,NETHER_BRICK)
Block(-3,-13,2,NETHER_BRICK)
Block(-3,-13,3,NETHER_BRICK)
Block(-3,-13,4,NETHER_BRICK)
Block(-3,-13,5,NETHER_BRICK)
Block(-3,-13,6,NETHER_BRICK)
Block(-3,-12,-6,NETHER_BRICK)
Block(-3,-12,-5,NETHER_BRICK)
Block(-3,-12,-4,NETHER_BRICK)
Block(-3,-12,-3,NETHER_BRICK)
Block(-3,-12,-2,NETHER_BRICK)
Block(-3,-12,-1,NETHER_BRICK)
Block(-3,-12,0,NETHER_BRICK)
Block(-3,-12,1,NETHER_BRICK)
Block(-3,-12,2,NETHER_BRICK)
Block(-3,-12,3,NETHER_BRICK)
Block(-3,-12,4,NETHER_BRICK)
Block(-3,-12,5,NETHER_BRICK)
Block(-3,-12,6,NETHER_BRICK)
Block(-3,-11,-6,NETHER_BRICK)
Block(-3,-11,-5,NETHER_BRICK)
Block(-3,-11,-4,NETHER_BRICK)
Block(-3,-11,-3,NETHER_BRICK)
Block(-3,-11,-2,NETHER_BRICK)
Block(-3,-11,-1,NETHER_BRICK)
Block(-3,-11,0,NETHER_BRICK)
Block(-3,-11,1,NETHER_BRICK)
Block(-3,-11,2,NETHER_BRICK)
Block(-3,-11,3,NETHER_BRICK)
Block(-3,-11,4,NETHER_BRICK)
Block(-3,-11,5,NETHER_BRICK)
Block(-3,-11,6,NETHER_BRICK)
Block(-3,-10,-6,NETHER_BRICK)
Block(-3,-10,-5,NETHER_BRICK)
Block(-3,-10,-4,NETHER_BRICK)
Block(-3,-10,-3,NETHER_BRICK)
Block(-3,-10,-2,NETHER_BRICK)
Block(-3,-10,-1,NETHER_BRICK)
Block(-3,-10,0,NETHER_BRICK)
Block(-3,-10,1,NETHER_BRICK)
Block(-3,-10,2,NETHER_BRICK)
Block(-3,-10,3,NETHER_BRICK)
Block(-3,-10,4,NETHER_BRICK)
Block(-3,-10,5,NETHER_BRICK)
Block(-3,-10,6,NETHER_BRICK)
Block(-3,-9,-6,NETHER_BRICK)
Block(-3,-9,-5,NETHER_BRICK)
Block(-3,-9,-4,NETHER_BRICK)
Block(-3,-9,-3,NETHER_BRICK)
Block(-3,-9,-2,NETHER_BRICK)
Block(-3,-9,-1,NETHER_BRICK)
Block(-3,-9,0,NETHER_BRICK)
Block(-3,-9,1,NETHER_BRICK)
Block(-3,-9,2,NETHER_BRICK)
Block(-3,-9,3,NETHER_BRICK)
Block(-3,-9,4,NETHER_BRICK)
Block(-3,-9,5,NETHER_BRICK)
Block(-3,-9,6,NETHER_BRICK)
Block(-3,-8,-6,NETHER_BRICK)
Block(-3,-8,-5,NETHER_BRICK)
Block(-3,-8,-4,NETHER_BRICK)
Block(-3,-8,-3,NETHER_BRICK)
Block(-3,-8,-2,NETHER_BRICK)
Block(-3,-8,-1,NETHER_BRICK)
Block(-3,-8,0,NETHER_BRICK)
Block(-3,-8,1,NETHER_BRICK)
Block(-3,-8,2,NETHER_BRICK)
Block(-3,-8,3,NETHER_BRICK)
Block(-3,-8,4,NETHER_BRICK)
Block(-3,-8,5,NETHER_BRICK)
Block(-3,-8,6,NETHER_BRICK)
Block(-3,-7,-6,NETHER_BRICK)
Block(-3,-7,-5,NETHER_BRICK)
Block(-3,-7,-4,NETHER_BRICK)
Block(-3,-7,-3,NETHER_BRICK)
Block(-3,-7,-2,NETHER_BRICK)
Block(-3,-7,-1,NETHER_BRICK)
Block(-3,-7,0,NETHER_BRICK)
Block(-3,-7,1,NETHER_BRICK)
Block(-3,-7,2,NETHER_BRICK)
Block(-3,-7,3,NETHER_BRICK)
Block(-3,-7,4,NETHER_BRICK)
Block(-3,-7,5,NETHER_BRICK)
Block(-3,-7,6,NETHER_BRICK)
Block(-3,-6,-6,NETHER_BRICK)
Block(-3,-6,-5,NETHER_BRICK)
Block(-3,-6,-4,NETHER_BRICK)
Block(-3,-6,-3,NETHER_BRICK)
Block(-3,-6,-2,NETHER_BRICK)
Block(-3,-6,-1,NETHER_BRICK)
Block(-3,-6,0,NETHER_BRICK)
Block(-3,-6,1,NETHER_BRICK)
Block(-3,-6,2,NETHER_BRICK)
Block(-3,-6,3,NETHER_BRICK)
Block(-3,-6,4,NETHER_BRICK)
Block(-3,-6,5,NETHER_BRICK)
Block(-3,-6,6,NETHER_BRICK)
Block(-3,-5,-6,NETHER_BRICK)
Block(-3,-5,-5,NETHER_BRICK)
Block(-3,-5,-4,NETHER_BRICK)
Block(-3,-5,-3,NETHER_BRICK)
Block(-3,-5,-2,NETHER_BRICK)
Block(-3,-5,-1,NETHER_BRICK)
Block(-3,-5,0,NETHER_BRICK)
Block(-3,-5,1,NETHER_BRICK)
Block(-3,-5,2,NETHER_BRICK)
Block(-3,-5,3,NETHER_BRICK)
Block(-3,-5,4,NETHER_BRICK)
Block(-3,-5,5,NETHER_BRICK)
Block(-3,-5,6,NETHER_BRICK)
Block(-3,-4,-6,NETHER_BRICK)
Block(-3,-4,-5,NETHER_BRICK)
Block(-3,-4,-4,NETHER_BRICK)
Block(-3,-4,-3,NETHER_BRICK)
Block(-3,-4,-2,NETHER_BRICK)
Block(-3,-4,-1,NETHER_BRICK)
Block(-3,-4,0,NETHER_BRICK)
Block(-3,-4,1,NETHER_BRICK)
Block(-3,-4,2,NETHER_BRICK)
Block(-3,-4,3,NETHER_BRICK)
Block(-3,-4,4,NETHER_BRICK)
Block(-3,-4,5,NETHER_BRICK)
Block(-3,-4,6,NETHER_BRICK)
Block(-3,-3,-6,NETHER_BRICK)
Block(-3,-3,-5,NETHER_BRICK)
Block(-3,-3,-4,NETHER_BRICK)
Block(-3,-3,-3,NETHER_BRICK)
Block(-3,-3,-2,NETHER_BRICK)
Block(-3,-3,-1,NETHER_BRICK)
Block(-3,-3,0,NETHER_BRICK)
Block(-3,-3,1,NETHER_BRICK)
Block(-3,-3,2,NETHER_BRICK)
Block(-3,-3,3,NETHER_BRICK)
Block(-3,-3,4,NETHER_BRICK)
Block(-3,-3,5,NETHER_BRICK)
Block(-3,-3,6,NETHER_BRICK)
Block(-3,-2,-6,NETHER_BRICK)
Block(-3,-2,-5,NETHER_BRICK)
Block(-3,-2,-4,NETHER_BRICK)
Block(-3,-2,-3,NETHER_BRICK)
Block(-3,-2,-2,NETHER_BRICK)
Block(-3,-2,-1,NETHER_BRICK)
Block(-3,-2,0,NETHER_BRICK)
Block(-3,-2,1,NETHER_BRICK)
Block(-3,-2,2,NETHER_BRICK)
Block(-3,-2,3,NETHER_BRICK)
Block(-3,-2,4,NETHER_BRICK)
Block(-3,-2,5,NETHER_BRICK)
Block(-3,-2,6,NETHER_BRICK)
Block(-3,-1,-6,NETHER_BRICK)
Block(-3,-1,-5,NETHER_FENCE)
Block(-3,-1,-4,NETHER_BRICK)
Block(-3,-1,-3,NETHER_BRICK)
Block(-3,-1,-2,NETHER_BRICK)
Block(-3,-1,-1,NETHER_BRICK)
Block(-3,-1,0,NETHER_BRICK)
Block(-3,-1,1,NETHER_BRICK)
Block(-3,-1,2,NETHER_BRICK)
Block(-3,-1,3,NETHER_BRICK)
Block(-3,-1,4,NETHER_BRICK)
Block(-3,-1,5,NETHER_FENCE)
Block(-3,-1,6,NETHER_BRICK)
Block(-3,0,-6,NETHER_BRICK)
Block(-3,0,-5,NETHER_FENCE)
Block(-3,0,-4,NETHER_BRICK)
Block(-3,0,-3,NETHER_BRICK)
Block(-3,0,-2,NETHER_BRICK)
Block(-3,0,-1,NETHER_BRICK)
Block(-3,0,0,NETHER_BRICK)
Block(-3,0,1,NETHER_BRICK)
Block(-3,0,2,NETHER_BRICK)
Block(-3,0,3,NETHER_BRICK)
Block(-3,0,4,NETHER_BRICK)
Block(-3,0,5,NETHER_FENCE)
Block(-3,0,6,NETHER_BRICK)
Block(-3,1,-6,NETHER_BRICK)
Block(-3,1,-5,NETHER_BRICK)
Block(-3,1,-4,NETHER_BRICK)
Block(-3,1,-3,NETHER_BRICK)
Block(-3,1,-2,NETHER_BRICK)
Block(-3,1,-1,NETHER_BRICK)
Block(-3,1,0,NETHER_BRICK)
Block(-3,1,1,NETHER_BRICK)
Block(-3,1,2,NETHER_BRICK)
Block(-3,1,3,NETHER_BRICK)
Block(-3,1,4,NETHER_BRICK)
Block(-3,1,5,NETHER_BRICK)
Block(-3,1,6,NETHER_BRICK)
Block(-3,2,-6,NETHER_BRICK)
Block(-3,2,-5,NETHER_BRICK)
Block(-3,2,-4,NETHER_BRICK)
Block(-3,2,-3,NETHER_BRICK)
Block(-3,2,-2,AIR)
Block(-3,2,-1,AIR)
Block(-3,2,0,AIR)
Block(-3,2,1,AIR)
Block(-3,2,2,AIR)
Block(-3,2,3,NETHER_BRICK)
Block(-3,2,4,NETHER_BRICK)
Block(-3,2,5,NETHER_BRICK)
Block(-3,2,6,NETHER_BRICK)
Block(-3,3,-6,AIR)
Block(-3,3,-5,NETHER_BRICK)
Block(-3,3,-4,NETHER_FENCE)
Block(-3,3,-3,NETHER_BRICK)
Block(-3,3,-2,AIR)
Block(-3,3,-1,AIR)
Block(-3,3,0,AIR)
Block(-3,3,1,AIR)
Block(-3,3,2,AIR)
Block(-3,3,3,NETHER_BRICK)
Block(-3,3,4,NETHER_BRICK)
Block(-3,3,5,NETHER_BRICK)
Block(-3,3,6,NETHER_BRICK)
Block(-3,4,-6,AIR)
Block(-3,4,-5,NETHER_BRICK)
Block(-3,4,-4,NETHER_FENCE)
Block(-3,4,-3,NETHER_BRICK)
Block(-3,4,-2,AIR)
Block(-3,4,-1,AIR)
Block(-3,4,0,AIR)
Block(-3,4,1,AIR)
Block(-3,4,2,AIR)
Block(-3,4,3,NETHER_BRICK)
Block(-3,4,4,NETHER_BRICK)
Block(-3,4,5,NETHER_BRICK)
Block(-3,4,6,NETHER_BRICK)
Block(-3,5,-6,AIR)
Block(-3,5,-5,NETHER_BRICK)
Block(-3,5,-4,NETHER_BRICK)
Block(-3,5,-3,NETHER_BRICK)
Block(-3,5,-2,AIR)
Block(-3,5,-1,AIR)
Block(-3,5,0,AIR)
Block(-3,5,1,AIR)
Block(-3,5,2,AIR)
Block(-3,5,3,NETHER_BRICK)
Block(-3,5,4,NETHER_BRICK)
Block(-3,5,5,NETHER_BRICK)
Block(-3,5,6,NETHER_BRICK)
Block(-3,6,-6,AIR)
Block(-3,6,-5,NETHER_BRICK)
Block(-3,6,-4,NETHER_BRICK)
Block(-3,6,-3,NETHER_BRICK)
Block(-3,6,-2,AIR)
Block(-3,6,-1,AIR)
Block(-3,6,0,AIR)
Block(-3,6,1,AIR)
Block(-3,6,2,AIR)
Block(-3,6,3,NETHER_BRICK)
Block(-3,6,4,NETHER_BRICK)
Block(-3,6,5,NETHER_BRICK)
Block(-3,6,6,NETHER_BRICK)
Block(-3,7,-3,NETHER_BRICK)
Block(-3,7,-2,AIR)
Block(-3,7,-1,AIR)
Block(-3,7,0,AIR)
Block(-3,7,1,AIR)
Block(-3,7,2,AIR)
Block(-3,7,3,NETHER_BRICK)
Block(-3,7,4,NETHER_BRICK)
Block(-3,7,5,NETHER_BRICK)
Block(-3,7,6,NETHER_BRICK)
Block(-3,8,-3,NETHER_BRICK)
Block(-3,8,-2,AIR)
Block(-3,8,-1,AIR)
Block(-3,8,0,AIR)
Block(-3,8,1,AIR)
Block(-3,8,2,AIR)
Block(-3,8,3,NETHER_BRICK)
Block(-3,8,4,NETHER_BRICK)
Block(-3,8,5,NETHER_BRICK)
Block(-3,8,6,NETHER_BRICK)
Block(-3,9,-3,NETHER_BRICK)
Block(-3,9,-2,AIR)
Block(-3,9,-1,AIR)
Block(-3,9,0,AIR)
Block(-3,9,1,AIR)
Block(-3,9,2,AIR)
Block(-3,9,3,NETHER_BRICK)
Block(-3,9,4,NETHER_BRICK)
Block(-3,9,5,NETHER_BRICK)
Block(-3,9,6,NETHER_BRICK)
Block(-3,10,-3,NETHER_BRICK)
Block(-3,10,-2,AIR)
Block(-3,10,-1,AIR)
Block(-3,10,0,AIR)
Block(-3,10,1,AIR)
Block(-3,10,2,AIR)
Block(-3,10,3,NETHER_BRICK)
Block(-3,10,4,NETHER_BRICK)
Block(-3,10,5,NETHER_BRICK)
Block(-3,10,6,NETHER_BRICK)
Block(-3,11,-3,NETHER_BRICK)
Block(-3,11,-2,AIR)
Block(-3,11,-1,AIR)
Block(-3,11,0,AIR)
Block(-3,11,1,AIR)
Block(-3,11,2,AIR)
Block(-3,11,3,NETHER_BRICK)
Block(-3,11,4,NETHER_BRICK)
Block(-3,11,5,NETHER_BRICK)
Block(-3,11,6,NETHER_BRICK)
Block(-3,12,-3,NETHER_BRICK)
Block(-3,12,-2,AIR)
Block(-3,12,-1,AIR)
Block(-3,12,0,AIR)
Block(-3,12,1,AIR)
Block(-3,12,2,AIR)
Block(-3,12,3,NETHER_BRICK)
Block(-3,12,4,NETHER_BRICK)
Block(-3,12,5,NETHER_BRICK)
Block(-3,12,6,NETHER_BRICK)
Block(-3,13,-3,NETHER_BRICK)
Block(-3,13,-2,AIR)
Block(-3,13,-1,AIR)
Block(-3,13,0,AIR)
Block(-3,13,1,AIR)
Block(-3,13,2,AIR)
Block(-3,13,3,NETHER_BRICK)
Block(-3,13,4,NETHER_BRICK)
Block(-3,13,5,NETHER_BRICK)
Block(-3,13,6,NETHER_BRICK)
Block(-3,14,-3,NETHER_BRICK)
Block(-3,14,-2,AIR)
Block(-3,14,-1,AIR)
Block(-3,14,0,AIR)
Block(-3,14,1,AIR)
Block(-3,14,2,AIR)
Block(-3,14,3,NETHER_BRICK)
Block(-3,14,4,NETHER_BRICK)
Block(-3,14,5,NETHER_BRICK)
Block(-3,14,6,NETHER_BRICK)
Block(-3,15,-3,NETHER_BRICK)
Block(-3,15,-2,AIR)
Block(-3,15,-1,AIR)
Block(-3,15,0,AIR)
Block(-3,15,1,AIR)
Block(-3,15,2,AIR)
Block(-3,15,3,NETHER_BRICK)
Block(-3,15,4,NETHER_BRICK)
Block(-3,15,5,NETHER_BRICK)
Block(-3,15,6,NETHER_BRICK)
Block(-3,16,-3,NETHER_BRICK)
Block(-3,16,-2,AIR)
Block(-3,16,-1,AIR)
Block(-3,16,0,AIR)
Block(-3,16,1,AIR)
Block(-3,16,2,AIR)
Block(-3,16,3,NETHER_BRICK)
Block(-3,16,4,NETHER_BRICK)
Block(-3,16,5,NETHER_BRICK)
Block(-3,16,6,NETHER_BRICK)
Block(-3,17,-3,NETHER_BRICK)
Block(-3,17,-2,AIR)
Block(-3,17,-1,AIR)
Block(-3,17,0,AIR)
Block(-3,17,1,AIR)
Block(-3,17,2,AIR)
Block(-3,17,3,NETHER_BRICK)
Block(-3,17,4,NETHER_BRICK)
Block(-3,17,5,NETHER_BRICK)
Block(-3,17,6,NETHER_BRICK)
Block(-3,18,-3,NETHER_BRICK)
Block(-3,18,-2,AIR)
Block(-3,18,-1,AIR)
Block(-3,18,0,AIR)
Block(-3,18,1,AIR)
Block(-3,18,2,AIR)
Block(-3,18,3,NETHER_BRICK)
Block(-3,18,4,NETHER_BRICK)
Block(-3,18,5,NETHER_BRICK)
Block(-3,18,6,NETHER_BRICK)
Block(-3,19,-3,NETHER_BRICK)
Block(-3,19,-2,AIR)
Block(-3,19,-1,AIR)
Block(-3,19,0,AIR)
Block(-3,19,1,AIR)
Block(-3,19,2,AIR)
Block(-3,19,3,NETHER_BRICK)
Block(-3,19,4,NETHER_BRICK)
Block(-3,19,5,NETHER_BRICK)
Block(-3,19,6,NETHER_BRICK)
Block(-3,20,-3,NETHER_BRICK)
Block(-3,20,-2,AIR)
Block(-3,20,-1,AIR)
Block(-3,20,0,AIR)
Block(-3,20,1,AIR)
Block(-3,20,2,AIR)
Block(-3,20,3,NETHER_BRICK)
Block(-3,20,4,NETHER_BRICK)
Block(-3,20,5,NETHER_BRICK)
Block(-3,20,6,NETHER_BRICK)
Block(-3,21,-3,NETHER_BRICK)
Block(-3,21,-2,AIR)
Block(-3,21,-1,AIR)
Block(-3,21,0,AIR)
Block(-3,21,1,AIR)
Block(-3,21,2,AIR)
Block(-3,21,3,NETHER_BRICK)
Block(-3,21,4,NETHER_BRICK)
Block(-3,21,5,NETHER_BRICK)
Block(-3,21,6,NETHER_BRICK)
Block(-3,22,-3,NETHER_BRICK)
Block(-3,22,-2,NETHER_BRICK)
Block(-3,22,-1,NETHER_BRICK)
Block(-3,22,0,NETHER_BRICK)
Block(-3,22,1,NETHER_BRICK)
Block(-3,22,2,NETHER_BRICK)
Block(-3,22,3,NETHER_BRICK)
Block(-3,22,4,NETHER_BRICK)
Block(-3,22,5,NETHER_BRICK)
Block(-3,22,6,NETHER_BRICK)
Block(-3,23,-3,NETHER_BRICK)
Block(-3,23,-2,NETHER_BRICK)
Block(-3,23,-1,AIR)
Block(-3,23,0,AIR)
Block(-3,23,1,AIR)
Block(-3,23,2,NETHER_BRICK)
Block(-3,23,3,NETHER_BRICK)
Block(-3,23,4,NETHER_BRICK)
Block(-3,23,5,NETHER_BRICK)
Block(-3,23,6,NETHER_BRICK)
Block(-3,24,-3,NETHER_BRICK)
Block(-3,24,-2,NETHER_BRICK)
Block(-3,24,-1,AIR)
Block(-3,24,0,AIR)
Block(-3,24,1,AIR)
Block(-3,24,2,NETHER_BRICK)
Block(-3,24,3,NETHER_BRICK)
Block(-3,24,4,NETHER_FENCE)
Block(-3,24,5,NETHER_BRICK)
Block(-3,24,6,NETHER_BRICK)
Block(-3,25,-3,NETHER_BRICK)
Block(-3,25,-2,NETHER_BRICK)
Block(-3,25,-1,AIR)
Block(-3,25,0,AIR)
Block(-3,25,1,AIR)
Block(-3,25,2,NETHER_BRICK)
Block(-3,25,3,NETHER_BRICK)
Block(-3,25,4,NETHER_FENCE)
Block(-3,25,5,NETHER_BRICK)
Block(-3,25,6,NETHER_BRICK)
Block(-3,26,-3,NETHER_BRICK)
Block(-3,26,-2,NETHER_BRICK)
Block(-3,26,-1,AIR)
Block(-3,26,0,AIR)
Block(-3,26,1,AIR)
Block(-3,26,2,NETHER_BRICK)
Block(-3,26,3,NETHER_BRICK)
Block(-3,26,4,NETHER_BRICK)
Block(-3,26,5,NETHER_BRICK)
Block(-3,26,6,NETHER_BRICK)
Block(-3,27,-3,NETHER_BRICK)
Block(-3,27,-2,NETHER_BRICK)
Block(-3,27,-1,NETHER_BRICK)
Block(-3,27,0,NETHER_BRICK)
Block(-3,27,1,NETHER_BRICK)
Block(-3,27,2,NETHER_BRICK)
Block(-3,27,3,NETHER_BRICK)
Block(-3,27,4,NETHER_BRICK)
Block(-3,27,5,NETHER_BRICK)
Block(-3,27,6,NETHER_BRICK)
Block(-2,-39,-6,NETHER_BRICK)
Block(-2,-39,-5,NETHER_BRICK)
Block(-2,-39,-4,NETHER_BRICK)
Block(-2,-39,-3,NETHER_BRICK)
Block(-2,-39,-2,NETHER_BRICK)
Block(-2,-39,-1,NETHER_BRICK)
Block(-2,-39,0,NETHER_BRICK)
Block(-2,-39,1,NETHER_BRICK)
Block(-2,-39,2,NETHER_BRICK)
Block(-2,-39,3,NETHER_BRICK)
Block(-2,-39,4,NETHER_BRICK)
Block(-2,-39,5,NETHER_BRICK)
Block(-2,-39,6,NETHER_BRICK)
Block(-2,-38,-6,NETHER_BRICK)
Block(-2,-38,-5,NETHER_BRICK)
Block(-2,-38,-4,NETHER_BRICK)
Block(-2,-38,-3,NETHER_BRICK)
Block(-2,-38,-2,NETHER_BRICK)
Block(-2,-38,-1,NETHER_BRICK)
Block(-2,-38,0,NETHER_BRICK)
Block(-2,-38,1,NETHER_BRICK)
Block(-2,-38,2,NETHER_BRICK)
Block(-2,-38,3,NETHER_BRICK)
Block(-2,-38,4,NETHER_BRICK)
Block(-2,-38,5,NETHER_BRICK)
Block(-2,-38,6,NETHER_BRICK)
Block(-2,-37,-6,NETHER_BRICK)
Block(-2,-37,-5,NETHER_BRICK)
Block(-2,-37,-4,NETHER_BRICK)
Block(-2,-37,-3,NETHER_BRICK)
Block(-2,-37,-2,NETHER_BRICK)
Block(-2,-37,-1,NETHER_BRICK)
Block(-2,-37,0,NETHER_BRICK)
Block(-2,-37,1,NETHER_BRICK)
Block(-2,-37,2,NETHER_BRICK)
Block(-2,-37,3,NETHER_BRICK)
Block(-2,-37,4,NETHER_BRICK)
Block(-2,-37,5,NETHER_BRICK)
Block(-2,-37,6,NETHER_BRICK)
Block(-2,-36,-6,NETHER_BRICK)
Block(-2,-36,-5,NETHER_BRICK)
Block(-2,-36,-4,NETHER_BRICK)
Block(-2,-36,-3,NETHER_BRICK)
Block(-2,-36,-2,NETHER_BRICK)
Block(-2,-36,-1,NETHER_BRICK)
Block(-2,-36,0,NETHER_BRICK)
Block(-2,-36,1,NETHER_BRICK)
Block(-2,-36,2,NETHER_BRICK)
Block(-2,-36,3,NETHER_BRICK)
Block(-2,-36,4,NETHER_BRICK)
Block(-2,-36,5,NETHER_BRICK)
Block(-2,-36,6,NETHER_BRICK)
Block(-2,-35,-6,NETHER_BRICK)
Block(-2,-35,-5,NETHER_BRICK)
Block(-2,-35,-4,NETHER_BRICK)
Block(-2,-35,-3,NETHER_BRICK)
Block(-2,-35,-2,NETHER_BRICK)
Block(-2,-35,-1,NETHER_BRICK)
Block(-2,-35,0,NETHER_BRICK)
Block(-2,-35,1,NETHER_BRICK)
Block(-2,-35,2,NETHER_BRICK)
Block(-2,-35,3,NETHER_BRICK)
Block(-2,-35,4,NETHER_BRICK)
Block(-2,-35,5,NETHER_BRICK)
Block(-2,-35,6,NETHER_BRICK)
Block(-2,-34,-6,NETHER_BRICK)
Block(-2,-34,-5,NETHER_BRICK)
Block(-2,-34,-4,NETHER_BRICK)
Block(-2,-34,-3,NETHER_BRICK)
Block(-2,-34,-2,NETHER_BRICK)
Block(-2,-34,-1,NETHER_BRICK)
Block(-2,-34,0,NETHER_BRICK)
Block(-2,-34,1,NETHER_BRICK)
Block(-2,-34,2,NETHER_BRICK)
Block(-2,-34,3,NETHER_BRICK)
Block(-2,-34,4,NETHER_BRICK)
Block(-2,-34,5,NETHER_BRICK)
Block(-2,-34,6,NETHER_BRICK)
Block(-2,-33,-6,NETHER_BRICK)
Block(-2,-33,-5,NETHER_BRICK)
Block(-2,-33,-4,NETHER_BRICK)
Block(-2,-33,-3,NETHER_BRICK)
Block(-2,-33,-2,NETHER_BRICK)
Block(-2,-33,-1,NETHER_BRICK)
Block(-2,-33,0,NETHER_BRICK)
Block(-2,-33,1,NETHER_BRICK)
Block(-2,-33,2,NETHER_BRICK)
Block(-2,-33,3,NETHER_BRICK)
Block(-2,-33,4,NETHER_BRICK)
Block(-2,-33,5,NETHER_BRICK)
Block(-2,-33,6,NETHER_BRICK)
Block(-2,-32,-6,NETHER_BRICK)
Block(-2,-32,-5,NETHER_BRICK)
Block(-2,-32,-4,NETHER_BRICK)
Block(-2,-32,-3,NETHER_BRICK)
Block(-2,-32,-2,NETHER_BRICK)
Block(-2,-32,-1,NETHER_BRICK)
Block(-2,-32,0,NETHER_BRICK)
Block(-2,-32,1,NETHER_BRICK)
Block(-2,-32,2,NETHER_BRICK)
Block(-2,-32,3,NETHER_BRICK)
Block(-2,-32,4,NETHER_BRICK)
Block(-2,-32,5,NETHER_BRICK)
Block(-2,-32,6,NETHER_BRICK)
Block(-2,-31,-6,NETHER_BRICK)
Block(-2,-31,-5,NETHER_BRICK)
Block(-2,-31,-4,NETHER_BRICK)
Block(-2,-31,-3,NETHER_BRICK)
Block(-2,-31,-2,NETHER_BRICK)
Block(-2,-31,-1,NETHER_BRICK)
Block(-2,-31,0,NETHER_BRICK)
Block(-2,-31,1,NETHER_BRICK)
Block(-2,-31,2,NETHER_BRICK)
Block(-2,-31,3,NETHER_BRICK)
Block(-2,-31,4,NETHER_BRICK)
Block(-2,-31,5,NETHER_BRICK)
Block(-2,-31,6,NETHER_BRICK)
Block(-2,-30,-6,NETHER_BRICK)
Block(-2,-30,-5,NETHER_BRICK)
Block(-2,-30,-4,NETHER_BRICK)
Block(-2,-30,-3,NETHER_BRICK)
Block(-2,-30,-2,NETHER_BRICK)
Block(-2,-30,-1,NETHER_BRICK)
Block(-2,-30,0,NETHER_BRICK)
Block(-2,-30,1,NETHER_BRICK)
Block(-2,-30,2,NETHER_BRICK)
Block(-2,-30,3,NETHER_BRICK)
Block(-2,-30,4,NETHER_BRICK)
Block(-2,-30,5,NETHER_BRICK)
Block(-2,-30,6,NETHER_BRICK)
Block(-2,-29,-6,NETHER_BRICK)
Block(-2,-29,-5,NETHER_BRICK)
Block(-2,-29,-4,NETHER_BRICK)
Block(-2,-29,-3,NETHER_BRICK)
Block(-2,-29,-2,NETHER_BRICK)
Block(-2,-29,-1,NETHER_BRICK)
Block(-2,-29,0,NETHER_BRICK)
Block(-2,-29,1,NETHER_BRICK)
Block(-2,-29,2,NETHER_BRICK)
Block(-2,-29,3,NETHER_BRICK)
Block(-2,-29,4,NETHER_BRICK)
Block(-2,-29,5,NETHER_BRICK)
Block(-2,-29,6,NETHER_BRICK)
Block(-2,-28,-6,NETHER_BRICK)
Block(-2,-28,-5,NETHER_BRICK)
Block(-2,-28,-4,NETHER_BRICK)
Block(-2,-28,-3,NETHER_BRICK)
Block(-2,-28,-2,NETHER_BRICK)
Block(-2,-28,-1,NETHER_BRICK)
Block(-2,-28,0,NETHER_BRICK)
Block(-2,-28,1,NETHER_BRICK)
Block(-2,-28,2,NETHER_BRICK)
Block(-2,-28,3,NETHER_BRICK)
Block(-2,-28,4,NETHER_BRICK)
Block(-2,-28,5,NETHER_BRICK)
Block(-2,-28,6,NETHER_BRICK)
Block(-2,-27,-6,NETHER_BRICK)
Block(-2,-27,-5,NETHER_BRICK)
Block(-2,-27,-4,NETHER_BRICK)
Block(-2,-27,-3,NETHER_BRICK)
Block(-2,-27,-2,NETHER_BRICK)
Block(-2,-27,-1,NETHER_BRICK)
Block(-2,-27,0,NETHER_BRICK)
Block(-2,-27,1,NETHER_BRICK)
Block(-2,-27,2,NETHER_BRICK)
Block(-2,-27,3,NETHER_BRICK)
Block(-2,-27,4,NETHER_BRICK)
Block(-2,-27,5,NETHER_BRICK)
Block(-2,-27,6,NETHER_BRICK)
Block(-2,-26,-6,NETHER_BRICK)
Block(-2,-26,-5,NETHER_BRICK)
Block(-2,-26,-4,NETHER_BRICK)
Block(-2,-26,-3,NETHER_BRICK)
Block(-2,-26,-2,NETHER_BRICK)
Block(-2,-26,-1,NETHER_BRICK)
Block(-2,-26,0,NETHER_BRICK)
Block(-2,-26,1,NETHER_BRICK)
Block(-2,-26,2,NETHER_BRICK)
Block(-2,-26,3,NETHER_BRICK)
Block(-2,-26,4,NETHER_BRICK)
Block(-2,-26,5,NETHER_BRICK)
Block(-2,-26,6,NETHER_BRICK)
Block(-2,-25,-6,NETHER_BRICK)
Block(-2,-25,-5,NETHER_BRICK)
Block(-2,-25,-4,NETHER_BRICK)
Block(-2,-25,-3,NETHER_BRICK)
Block(-2,-25,-2,NETHER_BRICK)
Block(-2,-25,-1,NETHER_BRICK)
Block(-2,-25,0,NETHER_BRICK)
Block(-2,-25,1,NETHER_BRICK)
Block(-2,-25,2,NETHER_BRICK)
Block(-2,-25,3,NETHER_BRICK)
Block(-2,-25,4,NETHER_BRICK)
Block(-2,-25,5,NETHER_BRICK)
Block(-2,-25,6,NETHER_BRICK)
Block(-2,-24,-6,NETHER_BRICK)
Block(-2,-24,-5,NETHER_BRICK)
Block(-2,-24,-4,NETHER_BRICK)
Block(-2,-24,-3,NETHER_BRICK)
Block(-2,-24,-2,NETHER_BRICK)
Block(-2,-24,-1,NETHER_BRICK)
Block(-2,-24,0,NETHER_BRICK)
Block(-2,-24,1,NETHER_BRICK)
Block(-2,-24,2,NETHER_BRICK)
Block(-2,-24,3,NETHER_BRICK)
Block(-2,-24,4,NETHER_BRICK)
Block(-2,-24,5,NETHER_BRICK)
Block(-2,-24,6,NETHER_BRICK)
Block(-2,-23,-6,NETHER_BRICK)
Block(-2,-23,-5,NETHER_BRICK)
Block(-2,-23,-4,NETHER_BRICK)
Block(-2,-23,-3,NETHER_BRICK)
Block(-2,-23,-2,NETHER_BRICK)
Block(-2,-23,-1,NETHER_BRICK)
Block(-2,-23,0,NETHER_BRICK)
Block(-2,-23,1,NETHER_BRICK)
Block(-2,-23,2,NETHER_BRICK)
Block(-2,-23,3,NETHER_BRICK)
Block(-2,-23,4,NETHER_BRICK)
Block(-2,-23,5,NETHER_BRICK)
Block(-2,-23,6,NETHER_BRICK)
Block(-2,-22,-6,NETHER_BRICK)
Block(-2,-22,-5,NETHER_BRICK)
Block(-2,-22,-4,NETHER_BRICK)
Block(-2,-22,-3,NETHER_BRICK)
Block(-2,-22,-2,NETHER_BRICK)
Block(-2,-22,-1,NETHER_BRICK)
Block(-2,-22,0,NETHER_BRICK)
Block(-2,-22,1,NETHER_BRICK)
Block(-2,-22,2,NETHER_BRICK)
Block(-2,-22,3,NETHER_BRICK)
Block(-2,-22,4,NETHER_BRICK)
Block(-2,-22,5,NETHER_BRICK)
Block(-2,-22,6,NETHER_BRICK)
Block(-2,-21,-6,NETHER_BRICK)
Block(-2,-21,-5,NETHER_BRICK)
Block(-2,-21,-4,NETHER_BRICK)
Block(-2,-21,-3,NETHER_BRICK)
Block(-2,-21,-2,NETHER_BRICK)
Block(-2,-21,-1,NETHER_BRICK)
Block(-2,-21,0,NETHER_BRICK)
Block(-2,-21,1,NETHER_BRICK)
Block(-2,-21,2,NETHER_BRICK)
Block(-2,-21,3,NETHER_BRICK)
Block(-2,-21,4,NETHER_BRICK)
Block(-2,-21,5,NETHER_BRICK)
Block(-2,-21,6,NETHER_BRICK)
Block(-2,-20,-6,NETHER_BRICK)
Block(-2,-20,-5,NETHER_BRICK)
Block(-2,-20,-4,NETHER_BRICK)
Block(-2,-20,-3,NETHER_BRICK)
Block(-2,-20,-2,NETHER_BRICK)
Block(-2,-20,-1,NETHER_BRICK)
Block(-2,-20,0,NETHER_BRICK)
Block(-2,-20,1,NETHER_BRICK)
Block(-2,-20,2,NETHER_BRICK)
Block(-2,-20,3,NETHER_BRICK)
Block(-2,-20,4,NETHER_BRICK)
Block(-2,-20,5,NETHER_BRICK)
Block(-2,-20,6,NETHER_BRICK)
Block(-2,-19,-6,NETHER_BRICK)
Block(-2,-19,-5,NETHER_BRICK)
Block(-2,-19,-4,NETHER_BRICK)
Block(-2,-19,-3,NETHER_BRICK)
Block(-2,-19,-2,NETHER_BRICK)
Block(-2,-19,-1,NETHER_BRICK)
Block(-2,-19,0,NETHER_BRICK)
Block(-2,-19,1,NETHER_BRICK)
Block(-2,-19,2,NETHER_BRICK)
Block(-2,-19,3,NETHER_BRICK)
Block(-2,-19,4,NETHER_BRICK)
Block(-2,-19,5,NETHER_BRICK)
Block(-2,-19,6,NETHER_BRICK)
Block(-2,-18,-6,NETHER_BRICK)
Block(-2,-18,-5,NETHER_BRICK)
Block(-2,-18,-4,NETHER_BRICK)
Block(-2,-18,-3,NETHER_BRICK)
Block(-2,-18,-2,NETHER_BRICK)
Block(-2,-18,-1,NETHER_BRICK)
Block(-2,-18,0,NETHER_BRICK)
Block(-2,-18,1,NETHER_BRICK)
Block(-2,-18,2,NETHER_BRICK)
Block(-2,-18,3,NETHER_BRICK)
Block(-2,-18,4,NETHER_BRICK)
Block(-2,-18,5,NETHER_BRICK)
Block(-2,-18,6,NETHER_BRICK)
Block(-2,-17,-6,NETHER_BRICK)
Block(-2,-17,-5,NETHER_BRICK)
Block(-2,-17,-4,NETHER_BRICK)
Block(-2,-17,-3,NETHER_BRICK)
Block(-2,-17,-2,NETHER_BRICK)
Block(-2,-17,-1,NETHER_BRICK)
Block(-2,-17,0,NETHER_BRICK)
Block(-2,-17,1,NETHER_BRICK)
Block(-2,-17,2,NETHER_BRICK)
Block(-2,-17,3,NETHER_BRICK)
Block(-2,-17,4,NETHER_BRICK)
Block(-2,-17,5,NETHER_BRICK)
Block(-2,-17,6,NETHER_BRICK)
Block(-2,-16,-6,NETHER_BRICK)
Block(-2,-16,-5,NETHER_BRICK)
Block(-2,-16,-4,NETHER_BRICK)
Block(-2,-16,-3,NETHER_BRICK)
Block(-2,-16,-2,NETHER_BRICK)
Block(-2,-16,-1,NETHER_BRICK)
Block(-2,-16,0,NETHER_BRICK)
Block(-2,-16,1,NETHER_BRICK)
Block(-2,-16,2,NETHER_BRICK)
Block(-2,-16,3,NETHER_BRICK)
Block(-2,-16,4,NETHER_BRICK)
Block(-2,-16,5,NETHER_BRICK)
Block(-2,-16,6,NETHER_BRICK)
Block(-2,-15,-6,NETHER_BRICK)
Block(-2,-15,-5,NETHER_BRICK)
Block(-2,-15,-4,NETHER_BRICK)
Block(-2,-15,-3,NETHER_BRICK)
Block(-2,-15,-2,NETHER_BRICK)
Block(-2,-15,-1,NETHER_BRICK)
Block(-2,-15,0,NETHER_BRICK)
Block(-2,-15,1,NETHER_BRICK)
Block(-2,-15,2,NETHER_BRICK)
Block(-2,-15,3,NETHER_BRICK)
Block(-2,-15,4,NETHER_BRICK)
Block(-2,-15,5,NETHER_BRICK)
Block(-2,-15,6,NETHER_BRICK)
Block(-2,-14,-6,NETHER_BRICK)
Block(-2,-14,-5,NETHER_BRICK)
Block(-2,-14,-4,NETHER_BRICK)
Block(-2,-14,-3,NETHER_BRICK)
Block(-2,-14,-2,NETHER_BRICK)
Block(-2,-14,-1,NETHER_BRICK)
Block(-2,-14,0,NETHER_BRICK)
Block(-2,-14,1,NETHER_BRICK)
Block(-2,-14,2,NETHER_BRICK)
Block(-2,-14,3,NETHER_BRICK)
Block(-2,-14,4,NETHER_BRICK)
Block(-2,-14,5,NETHER_BRICK)
Block(-2,-14,6,NETHER_BRICK)
Block(-2,-13,-6,NETHER_BRICK)
Block(-2,-13,-5,NETHER_BRICK)
Block(-2,-13,-4,NETHER_BRICK)
Block(-2,-13,-3,NETHER_BRICK)
Block(-2,-13,-2,NETHER_BRICK)
Block(-2,-13,-1,NETHER_BRICK)
Block(-2,-13,0,NETHER_BRICK)
Block(-2,-13,1,NETHER_BRICK)
Block(-2,-13,2,NETHER_BRICK)
Block(-2,-13,3,NETHER_BRICK)
Block(-2,-13,4,NETHER_BRICK)
Block(-2,-13,5,NETHER_BRICK)
Block(-2,-13,6,NETHER_BRICK)
Block(-2,-12,-6,NETHER_BRICK)
Block(-2,-12,-5,NETHER_BRICK)
Block(-2,-12,-4,NETHER_BRICK)
Block(-2,-12,-3,NETHER_BRICK)
Block(-2,-12,-2,NETHER_BRICK)
Block(-2,-12,-1,NETHER_BRICK)
Block(-2,-12,0,NETHER_BRICK)
Block(-2,-12,1,NETHER_BRICK)
Block(-2,-12,2,NETHER_BRICK)
Block(-2,-12,3,NETHER_BRICK)
Block(-2,-12,4,NETHER_BRICK)
Block(-2,-12,5,NETHER_BRICK)
Block(-2,-12,6,NETHER_BRICK)
Block(-2,-11,-6,NETHER_BRICK)
Block(-2,-11,-5,NETHER_BRICK)
Block(-2,-11,-4,NETHER_BRICK)
Block(-2,-11,-3,NETHER_BRICK)
Block(-2,-11,-2,NETHER_BRICK)
Block(-2,-11,-1,NETHER_BRICK)
Block(-2,-11,0,NETHER_BRICK)
Block(-2,-11,1,NETHER_BRICK)
Block(-2,-11,2,NETHER_BRICK)
Block(-2,-11,3,NETHER_BRICK)
Block(-2,-11,4,NETHER_BRICK)
Block(-2,-11,5,NETHER_BRICK)
Block(-2,-11,6,NETHER_BRICK)
Block(-2,-10,-6,NETHER_BRICK)
Block(-2,-10,-5,NETHER_BRICK)
Block(-2,-10,-4,NETHER_BRICK)
Block(-2,-10,-3,NETHER_BRICK)
Block(-2,-10,-2,NETHER_BRICK)
Block(-2,-10,-1,NETHER_BRICK)
Block(-2,-10,0,NETHER_BRICK)
Block(-2,-10,1,NETHER_BRICK)
Block(-2,-10,2,NETHER_BRICK)
Block(-2,-10,3,NETHER_BRICK)
Block(-2,-10,4,NETHER_BRICK)
Block(-2,-10,5,NETHER_BRICK)
Block(-2,-10,6,NETHER_BRICK)
Block(-2,-9,-6,NETHER_BRICK)
Block(-2,-9,-5,NETHER_BRICK)
Block(-2,-9,-4,NETHER_BRICK)
Block(-2,-9,-3,NETHER_BRICK)
Block(-2,-9,-2,NETHER_BRICK)
Block(-2,-9,-1,NETHER_BRICK)
Block(-2,-9,0,NETHER_BRICK)
Block(-2,-9,1,NETHER_BRICK)
Block(-2,-9,2,NETHER_BRICK)
Block(-2,-9,3,NETHER_BRICK)
Block(-2,-9,4,NETHER_BRICK)
Block(-2,-9,5,NETHER_BRICK)
Block(-2,-9,6,NETHER_BRICK)
Block(-2,-8,-6,NETHER_BRICK)
Block(-2,-8,-5,NETHER_BRICK)
Block(-2,-8,-4,NETHER_BRICK)
Block(-2,-8,-3,NETHER_BRICK)
Block(-2,-8,-2,NETHER_BRICK)
Block(-2,-8,-1,NETHER_BRICK)
Block(-2,-8,0,NETHER_BRICK)
Block(-2,-8,1,NETHER_BRICK)
Block(-2,-8,2,NETHER_BRICK)
Block(-2,-8,3,NETHER_BRICK)
Block(-2,-8,4,NETHER_BRICK)
Block(-2,-8,5,NETHER_BRICK)
Block(-2,-8,6,NETHER_BRICK)
Block(-2,-7,-6,NETHER_BRICK)
Block(-2,-7,-5,NETHER_BRICK)
Block(-2,-7,-4,NETHER_BRICK)
Block(-2,-7,-3,NETHER_BRICK)
Block(-2,-7,-2,NETHER_BRICK)
Block(-2,-7,-1,NETHER_BRICK)
Block(-2,-7,0,NETHER_BRICK)
Block(-2,-7,1,NETHER_BRICK)
Block(-2,-7,2,NETHER_BRICK)
Block(-2,-7,3,NETHER_BRICK)
Block(-2,-7,4,NETHER_BRICK)
Block(-2,-7,5,NETHER_BRICK)
Block(-2,-7,6,NETHER_BRICK)
Block(-2,-6,-6,NETHER_BRICK)
Block(-2,-6,-5,NETHER_BRICK)
Block(-2,-6,-4,NETHER_BRICK)
Block(-2,-6,-3,NETHER_BRICK)
Block(-2,-6,-2,NETHER_BRICK)
Block(-2,-6,-1,NETHER_BRICK)
Block(-2,-6,0,NETHER_BRICK)
Block(-2,-6,1,NETHER_BRICK)
Block(-2,-6,2,NETHER_BRICK)
Block(-2,-6,3,NETHER_BRICK)
Block(-2,-6,4,NETHER_BRICK)
Block(-2,-6,5,NETHER_BRICK)
Block(-2,-6,6,NETHER_BRICK)
Block(-2,-5,-6,NETHER_BRICK)
Block(-2,-5,-5,NETHER_BRICK)
Block(-2,-5,-4,NETHER_BRICK)
Block(-2,-5,-3,NETHER_BRICK)
Block(-2,-5,-2,NETHER_BRICK)
Block(-2,-5,-1,NETHER_BRICK)
Block(-2,-5,0,NETHER_BRICK)
Block(-2,-5,1,NETHER_BRICK)
Block(-2,-5,2,NETHER_BRICK)
Block(-2,-5,3,NETHER_BRICK)
Block(-2,-5,4,NETHER_BRICK)
Block(-2,-5,5,NETHER_BRICK)
Block(-2,-5,6,NETHER_BRICK)
Block(-2,-4,-6,NETHER_BRICK)
Block(-2,-4,-5,NETHER_BRICK)
Block(-2,-4,-4,NETHER_BRICK)
Block(-2,-4,-3,NETHER_BRICK)
Block(-2,-4,-2,NETHER_BRICK)
Block(-2,-4,-1,NETHER_BRICK)
Block(-2,-4,0,NETHER_BRICK)
Block(-2,-4,1,NETHER_BRICK)
Block(-2,-4,2,NETHER_BRICK)
Block(-2,-4,3,NETHER_BRICK)
Block(-2,-4,4,NETHER_BRICK)
Block(-2,-4,5,NETHER_BRICK)
Block(-2,-4,6,NETHER_BRICK)
Block(-2,-3,-6,NETHER_BRICK)
Block(-2,-3,-5,NETHER_BRICK)
Block(-2,-3,-4,NETHER_BRICK)
Block(-2,-3,-3,NETHER_BRICK)
Block(-2,-3,-2,NETHER_BRICK)
Block(-2,-3,-1,NETHER_BRICK)
Block(-2,-3,0,NETHER_BRICK)
Block(-2,-3,1,NETHER_BRICK)
Block(-2,-3,2,NETHER_BRICK)
Block(-2,-3,3,NETHER_BRICK)
Block(-2,-3,4,NETHER_BRICK)
Block(-2,-3,5,NETHER_BRICK)
Block(-2,-3,6,NETHER_BRICK)
Block(-2,-2,-6,NETHER_BRICK)
Block(-2,-2,-5,NETHER_BRICK)
Block(-2,-2,-4,NETHER_BRICK)
Block(-2,-2,-3,NETHER_BRICK)
Block(-2,-2,-2,NETHER_BRICK)
Block(-2,-2,-1,NETHER_BRICK)
Block(-2,-2,0,NETHER_BRICK)
Block(-2,-2,1,NETHER_BRICK)
Block(-2,-2,2,NETHER_BRICK)
Block(-2,-2,3,NETHER_BRICK)
Block(-2,-2,4,NETHER_BRICK)
Block(-2,-2,5,NETHER_BRICK)
Block(-2,-2,6,NETHER_BRICK)
Block(-2,-1,-6,NETHER_BRICK)
Block(-2,-1,-5,NETHER_BRICK)
Block(-2,-1,-4,NETHER_BRICK)
Block(-2,-1,-3,NETHER_BRICK)
Block(-2,-1,-2,NETHER_BRICK)
Block(-2,-1,-1,NETHER_BRICK)
Block(-2,-1,0,NETHER_BRICK)
Block(-2,-1,1,NETHER_BRICK)
Block(-2,-1,2,NETHER_BRICK)
Block(-2,-1,3,NETHER_BRICK)
Block(-2,-1,4,NETHER_BRICK)
Block(-2,-1,5,NETHER_BRICK)
Block(-2,-1,6,NETHER_FENCE)
Block(-2,0,-6,NETHER_BRICK)
Block(-2,0,-5,NETHER_BRICK)
Block(-2,0,-4,NETHER_BRICK)
Block(-2,0,-3,NETHER_BRICK)
Block(-2,0,-2,NETHER_BRICK)
Block(-2,0,-1,NETHER_BRICK)
Block(-2,0,0,NETHER_BRICK)
Block(-2,0,1,NETHER_BRICK)
Block(-2,0,2,NETHER_BRICK)
Block(-2,0,3,NETHER_BRICK)
Block(-2,0,4,NETHER_BRICK)
Block(-2,0,5,NETHER_BRICK)
Block(-2,0,6,NETHER_FENCE)
Block(-2,1,-6,NETHER_BRICK)
Block(-2,1,-5,NETHER_BRICK)
Block(-2,1,-4,NETHER_BRICK)
Block(-2,1,-3,NETHER_BRICK)
Block(-2,1,-2,NETHER_BRICK)
Block(-2,1,-1,NETHER_BRICK)
Block(-2,1,0,NETHER_BRICK)
Block(-2,1,1,NETHER_BRICK)
Block(-2,1,2,NETHER_BRICK)
Block(-2,1,3,NETHER_BRICK)
Block(-2,1,4,NETHER_BRICK)
Block(-2,1,5,NETHER_BRICK)
Block(-2,1,6,NETHER_BRICK)
Block(-2,2,-6,AIR)
Block(-2,2,-5,AIR)
Block(-2,2,-4,AIR)
Block(-2,2,-3,AIR)
Block(-2,2,-2,AIR)
Block(-2,2,-1,AIR)
Block(-2,2,0,AIR)
Block(-2,2,1,AIR)
Block(-2,2,2,AIR)
Block(-2,2,3,AIR)
Block(-2,2,4,AIR)
Block(-2,2,5,NETHER_BRICK)
Block(-2,2,6,NETHER_BRICK)
Block(-2,3,-6,AIR)
Block(-2,3,-5,AIR)
Block(-2,3,-4,AIR)
Block(-2,3,-3,AIR)
Block(-2,3,-2,AIR)
Block(-2,3,-1,AIR)
Block(-2,3,0,AIR)
Block(-2,3,1,AIR)
Block(-2,3,2,AIR)
Block(-2,3,3,AIR)
Block(-2,3,4,AIR)
Block(-2,3,5,NETHER_BRICK)
Block(-2,3,6,NETHER_BRICK)
Block(-2,4,-6,AIR)
Block(-2,4,-5,AIR)
Block(-2,4,-4,AIR)
Block(-2,4,-3,AIR)
Block(-2,4,-2,AIR)
Block(-2,4,-1,AIR)
Block(-2,4,0,AIR)
Block(-2,4,1,AIR)
Block(-2,4,2,AIR)
Block(-2,4,3,AIR)
Block(-2,4,4,AIR)
Block(-2,4,5,NETHER_BRICK)
Block(-2,4,6,NETHER_BRICK)
Block(-2,5,-6,AIR)
Block(-2,5,-5,NETHER_BRICK_STAIRS:5)
Block(-2,5,-4,AIR)
Block(-2,5,-3,AIR)
Block(-2,5,-2,AIR)
Block(-2,5,-1,AIR)
Block(-2,5,0,AIR)
Block(-2,5,1,AIR)
Block(-2,5,2,AIR)
Block(-2,5,3,AIR)
Block(-2,5,4,AIR)
Block(-2,5,5,NETHER_BRICK)
Block(-2,5,6,NETHER_BRICK)
Block(-2,6,-6,AIR)
Block(-2,6,-5,NETHER_BRICK)
Block(-2,6,-4,NETHER_BRICK)
Block(-2,6,-3,AIR)
Block(-2,6,-2,AIR)
Block(-2,6,-1,AIR)
Block(-2,6,0,AIR)
Block(-2,6,1,AIR)
Block(-2,6,2,AIR)
Block(-2,6,3,AIR)
Block(-2,6,4,NETHER_BRICK)
Block(-2,6,5,NETHER_BRICK)
Block(-2,6,6,NETHER_BRICK)
Block(-2,7,-4,NETHER_BRICK)
Block(-2,7,-3,AIR)
Block(-2,7,-2,AIR)
Block(-2,7,-1,AIR)
Block(-2,7,0,AIR)
Block(-2,7,1,AIR)
Block(-2,7,2,AIR)
Block(-2,7,3,AIR)
Block(-2,7,4,NETHER_BRICK)
Block(-2,7,5,NETHER_BRICK)
Block(-2,7,6,NETHER_BRICK)
Block(-2,8,-4,NETHER_BRICK)
Block(-2,8,-3,AIR)
Block(-2,8,-2,AIR)
Block(-2,8,-1,AIR)
Block(-2,8,0,AIR)
Block(-2,8,1,AIR)
Block(-2,8,2,AIR)
Block(-2,8,3,AIR)
Block(-2,8,4,NETHER_BRICK)
Block(-2,8,5,NETHER_BRICK)
Block(-2,8,6,NETHER_BRICK)
Block(-2,9,-4,NETHER_BRICK)
Block(-2,9,-3,AIR)
Block(-2,9,-2,AIR)
Block(-2,9,-1,AIR)
Block(-2,9,0,AIR)
Block(-2,9,1,AIR)
Block(-2,9,2,AIR)
Block(-2,9,3,AIR)
Block(-2,9,4,NETHER_BRICK)
Block(-2,9,5,NETHER_BRICK)
Block(-2,9,6,NETHER_BRICK)
Block(-2,10,-4,NETHER_BRICK)
Block(-2,10,-3,AIR)
Block(-2,10,-2,AIR)
Block(-2,10,-1,AIR)
Block(-2,10,0,AIR)
Block(-2,10,1,AIR)
Block(-2,10,2,AIR)
Block(-2,10,3,AIR)
Block(-2,10,4,AIR)
Block(-2,10,5,AIR)
Block(-2,10,6,NETHER_BRICK)
Block(-2,11,-4,NETHER_BRICK)
Block(-2,11,-3,AIR)
Block(-2,11,-2,AIR)
Block(-2,11,-1,AIR)
Block(-2,11,0,AIR)
Block(-2,11,1,AIR)
Block(-2,11,2,AIR)
Block(-2,11,3,AIR)
Block(-2,11,4,AIR)
Block(-2,11,5,AIR)
Block(-2,11,6,NETHER_BRICK)
Block(-2,12,-4,NETHER_BRICK)
Block(-2,12,-3,AIR)
Block(-2,12,-2,AIR)
Block(-2,12,-1,AIR)
Block(-2,12,0,AIR)
Block(-2,12,1,AIR)
Block(-2,12,2,AIR)
Block(-2,12,3,AIR)
Block(-2,12,4,AIR)
Block(-2,12,5,AIR)
Block(-2,12,6,NETHER_BRICK)
Block(-2,13,-4,NETHER_BRICK)
Block(-2,13,-3,AIR)
Block(-2,13,-2,AIR)
Block(-2,13,-1,AIR)
Block(-2,13,0,AIR)
Block(-2,13,1,AIR)
Block(-2,13,2,AIR)
Block(-2,13,3,AIR)
Block(-2,13,4,AIR)
Block(-2,13,5,AIR)
Block(-2,13,6,NETHER_BRICK)
Block(-2,14,-4,NETHER_BRICK)
Block(-2,14,-3,AIR)
Block(-2,14,-2,AIR)
Block(-2,14,-1,AIR)
Block(-2,14,0,AIR)
Block(-2,14,1,AIR)
Block(-2,14,2,AIR)
Block(-2,14,3,AIR)
Block(-2,14,4,NETHER_BRICK)
Block(-2,14,5,NETHER_BRICK)
Block(-2,14,6,NETHER_BRICK)
Block(-2,15,-4,NETHER_BRICK)
Block(-2,15,-3,AIR)
Block(-2,15,-2,AIR)
Block(-2,15,-1,AIR)
Block(-2,15,0,AIR)
Block(-2,15,1,AIR)
Block(-2,15,2,AIR)
Block(-2,15,3,AIR)
Block(-2,15,4,NETHER_BRICK)
Block(-2,15,5,NETHER_BRICK)
Block(-2,15,6,NETHER_BRICK)
Block(-2,16,-4,NETHER_BRICK)
Block(-2,16,-3,AIR)
Block(-2,16,-2,AIR)
Block(-2,16,-1,AIR)
Block(-2,16,0,AIR)
Block(-2,16,1,AIR)
Block(-2,16,2,AIR)
Block(-2,16,3,AIR)
Block(-2,16,4,NETHER_BRICK)
Block(-2,16,5,NETHER_BRICK)
Block(-2,16,6,NETHER_BRICK)
Block(-2,17,-4,NETHER_BRICK)
Block(-2,17,-3,AIR)
Block(-2,17,-2,AIR)
Block(-2,17,-1,AIR)
Block(-2,17,0,AIR)
Block(-2,17,1,AIR)
Block(-2,17,2,AIR)
Block(-2,17,3,AIR)
Block(-2,17,4,NETHER_BRICK)
Block(-2,17,5,NETHER_BRICK)
Block(-2,17,6,NETHER_BRICK)
Block(-2,18,-4,NETHER_BRICK)
Block(-2,18,-3,AIR)
Block(-2,18,-2,AIR)
Block(-2,18,-1,AIR)
Block(-2,18,0,AIR)
Block(-2,18,1,AIR)
Block(-2,18,2,AIR)
Block(-2,18,3,AIR)
Block(-2,18,4,AIR)
Block(-2,18,5,AIR)
Block(-2,18,6,NETHER_BRICK)
Block(-2,19,-4,NETHER_BRICK)
Block(-2,19,-3,AIR)
Block(-2,19,-2,AIR)
Block(-2,19,-1,AIR)
Block(-2,19,0,AIR)
Block(-2,19,1,AIR)
Block(-2,19,2,AIR)
Block(-2,19,3,AIR)
Block(-2,19,4,AIR)
Block(-2,19,5,AIR)
Block(-2,19,6,NETHER_BRICK)
Block(-2,20,-4,NETHER_BRICK)
Block(-2,20,-3,AIR)
Block(-2,20,-2,AIR)
Block(-2,20,-1,AIR)
Block(-2,20,0,AIR)
Block(-2,20,1,AIR)
Block(-2,20,2,AIR)
Block(-2,20,3,AIR)
Block(-2,20,4,AIR)
Block(-2,20,5,AIR)
Block(-2,20,6,NETHER_BRICK)
Block(-2,21,-4,NETHER_BRICK)
Block(-2,21,-3,AIR)
Block(-2,21,-2,AIR)
Block(-2,21,-1,AIR)
Block(-2,21,0,AIR)
Block(-2,21,1,AIR)
Block(-2,21,2,AIR)
Block(-2,21,3,AIR)
Block(-2,21,4,AIR)
Block(-2,21,5,NETHER_BRICK)
Block(-2,21,6,NETHER_BRICK)
Block(-2,22,-4,NETHER_BRICK)
Block(-2,22,-3,NETHER_BRICK)
Block(-2,22,-2,NETHER_BRICK)
Block(-2,22,-1,NETHER_BRICK)
Block(-2,22,0,NETHER_BRICK)
Block(-2,22,1,NETHER_BRICK)
Block(-2,22,2,NETHER_BRICK)
Block(-2,22,3,NETHER_BRICK)
Block(-2,22,4,AIR)
Block(-2,22,5,NETHER_BRICK)
Block(-2,22,6,NETHER_BRICK)
Block(-2,23,-4,NETHER_BRICK)
Block(-2,23,-3,NETHER_BRICK)
Block(-2,23,-2,AIR)
Block(-2,23,-1,AIR)
Block(-2,23,0,AIR)
Block(-2,23,1,AIR)
Block(-2,23,2,AIR)
Block(-2,23,3,AIR)
Block(-2,23,4,AIR)
Block(-2,23,5,AIR)
Block(-2,23,6,NETHER_BRICK)
Block(-2,24,-4,NETHER_BRICK)
Block(-2,24,-3,NETHER_BRICK)
Block(-2,24,-2,AIR)
Block(-2,24,-1,AIR)
Block(-2,24,0,AIR)
Block(-2,24,1,AIR)
Block(-2,24,2,AIR)
Block(-2,24,3,AIR)
Block(-2,24,4,AIR)
Block(-2,24,5,AIR)
Block(-2,24,6,NETHER_BRICK)
Block(-2,25,-4,NETHER_BRICK)
Block(-2,25,-3,NETHER_BRICK)
Block(-2,25,-2,AIR)
Block(-2,25,-1,AIR)
Block(-2,25,0,AIR)
Block(-2,25,1,AIR)
Block(-2,25,2,AIR)
Block(-2,25,3,AIR)
Block(-2,25,4,AIR)
Block(-2,25,5,AIR)
Block(-2,25,6,NETHER_BRICK)
Block(-2,26,-4,NETHER_BRICK)
Block(-2,26,-3,NETHER_BRICK)
Block(-2,26,-2,AIR)
Block(-2,26,-1,AIR)
Block(-2,26,0,AIR)
Block(-2,26,1,AIR)
Block(-2,26,2,AIR)
Block(-2,26,3,AIR)
Block(-2,26,4,AIR)
Block(-2,26,5,AIR)
Block(-2,26,6,NETHER_BRICK)
Block(-2,27,-4,NETHER_BRICK)
Block(-2,27,-3,NETHER_BRICK)
Block(-2,27,-2,NETHER_BRICK)
Block(-2,27,-1,NETHER_BRICK)
Block(-2,27,0,NETHER_BRICK)
Block(-2,27,1,NETHER_BRICK)
Block(-2,27,2,NETHER_BRICK)
Block(-2,27,3,NETHER_BRICK)
Block(-2,27,4,NETHER_BRICK)
Block(-2,27,5,NETHER_BRICK)
Block(-2,27,6,NETHER_BRICK)
Block(-1,-39,-6,NETHER_BRICK)
Block(-1,-39,-5,NETHER_BRICK)
Block(-1,-39,-4,NETHER_BRICK)
Block(-1,-39,-3,NETHER_BRICK)
Block(-1,-39,-2,NETHER_BRICK)
Block(-1,-39,-1,NETHER_BRICK)
Block(-1,-39,0,NETHER_BRICK)
Block(-1,-39,1,NETHER_BRICK)
Block(-1,-39,2,NETHER_BRICK)
Block(-1,-39,3,NETHER_BRICK)
Block(-1,-39,4,NETHER_BRICK)
Block(-1,-39,5,NETHER_BRICK)
Block(-1,-39,6,NETHER_BRICK)
Block(-1,-38,-6,NETHER_BRICK)
Block(-1,-38,-5,NETHER_BRICK)
Block(-1,-38,-4,NETHER_BRICK)
Block(-1,-38,-3,NETHER_BRICK)
Block(-1,-38,-2,NETHER_BRICK)
Block(-1,-38,-1,NETHER_BRICK)
Block(-1,-38,0,NETHER_BRICK)
Block(-1,-38,1,NETHER_BRICK)
Block(-1,-38,2,NETHER_BRICK)
Block(-1,-38,3,NETHER_BRICK)
Block(-1,-38,4,NETHER_BRICK)
Block(-1,-38,5,NETHER_BRICK)
Block(-1,-38,6,NETHER_BRICK)
Block(-1,-37,-6,NETHER_BRICK)
Block(-1,-37,-5,NETHER_BRICK)
Block(-1,-37,-4,NETHER_BRICK)
Block(-1,-37,-3,NETHER_BRICK)
Block(-1,-37,-2,NETHER_BRICK)
Block(-1,-37,-1,NETHER_BRICK)
Block(-1,-37,0,NETHER_BRICK)
Block(-1,-37,1,NETHER_BRICK)
Block(-1,-37,2,NETHER_BRICK)
Block(-1,-37,3,NETHER_BRICK)
Block(-1,-37,4,NETHER_BRICK)
Block(-1,-37,5,NETHER_BRICK)
Block(-1,-37,6,NETHER_BRICK)
Block(-1,-36,-6,NETHER_BRICK)
Block(-1,-36,-5,NETHER_BRICK)
Block(-1,-36,-4,NETHER_BRICK)
Block(-1,-36,-3,NETHER_BRICK)
Block(-1,-36,-2,NETHER_BRICK)
Block(-1,-36,-1,NETHER_BRICK)
Block(-1,-36,0,NETHER_BRICK)
Block(-1,-36,1,NETHER_BRICK)
Block(-1,-36,2,NETHER_BRICK)
Block(-1,-36,3,NETHER_BRICK)
Block(-1,-36,4,NETHER_BRICK)
Block(-1,-36,5,NETHER_BRICK)
Block(-1,-36,6,NETHER_BRICK)
Block(-1,-35,-6,NETHER_BRICK)
Block(-1,-35,-5,NETHER_BRICK)
Block(-1,-35,-4,NETHER_BRICK)
Block(-1,-35,-3,NETHER_BRICK)
Block(-1,-35,-2,NETHER_BRICK)
Block(-1,-35,-1,NETHER_BRICK)
Block(-1,-35,0,NETHER_BRICK)
Block(-1,-35,1,NETHER_BRICK)
Block(-1,-35,2,NETHER_BRICK)
Block(-1,-35,3,NETHER_BRICK)
Block(-1,-35,4,NETHER_BRICK)
Block(-1,-35,5,NETHER_BRICK)
Block(-1,-35,6,NETHER_BRICK)
Block(-1,-34,-6,NETHER_BRICK)
Block(-1,-34,-5,NETHER_BRICK)
Block(-1,-34,-4,NETHER_BRICK)
Block(-1,-34,-3,NETHER_BRICK)
Block(-1,-34,-2,NETHER_BRICK)
Block(-1,-34,-1,NETHER_BRICK)
Block(-1,-34,0,NETHER_BRICK)
Block(-1,-34,1,NETHER_BRICK)
Block(-1,-34,2,NETHER_BRICK)
Block(-1,-34,3,NETHER_BRICK)
Block(-1,-34,4,NETHER_BRICK)
Block(-1,-34,5,NETHER_BRICK)
Block(-1,-34,6,NETHER_BRICK)
Block(-1,-33,-6,NETHER_BRICK)
Block(-1,-33,-5,NETHER_BRICK)
Block(-1,-33,-4,NETHER_BRICK)
Block(-1,-33,-3,NETHER_BRICK)
Block(-1,-33,-2,NETHER_BRICK)
Block(-1,-33,-1,NETHER_BRICK)
Block(-1,-33,0,NETHER_BRICK)
Block(-1,-33,1,NETHER_BRICK)
Block(-1,-33,2,NETHER_BRICK)
Block(-1,-33,3,NETHER_BRICK)
Block(-1,-33,4,NETHER_BRICK)
Block(-1,-33,5,NETHER_BRICK)
Block(-1,-33,6,NETHER_BRICK)
Block(-1,-32,-6,NETHER_BRICK)
Block(-1,-32,-5,NETHER_BRICK)
Block(-1,-32,-4,NETHER_BRICK)
Block(-1,-32,-3,NETHER_BRICK)
Block(-1,-32,-2,NETHER_BRICK)
Block(-1,-32,-1,NETHER_BRICK)
Block(-1,-32,0,NETHER_BRICK)
Block(-1,-32,1,NETHER_BRICK)
Block(-1,-32,2,NETHER_BRICK)
Block(-1,-32,3,NETHER_BRICK)
Block(-1,-32,4,NETHER_BRICK)
Block(-1,-32,5,NETHER_BRICK)
Block(-1,-32,6,NETHER_BRICK)
Block(-1,-31,-6,NETHER_BRICK)
Block(-1,-31,-5,NETHER_BRICK)
Block(-1,-31,-4,NETHER_BRICK)
Block(-1,-31,-3,NETHER_BRICK)
Block(-1,-31,-2,NETHER_BRICK)
Block(-1,-31,-1,NETHER_BRICK)
Block(-1,-31,0,NETHER_BRICK)
Block(-1,-31,1,NETHER_BRICK)
Block(-1,-31,2,NETHER_BRICK)
Block(-1,-31,3,NETHER_BRICK)
Block(-1,-31,4,NETHER_BRICK)
Block(-1,-31,5,NETHER_BRICK)
Block(-1,-31,6,NETHER_BRICK)
Block(-1,-30,-6,NETHER_BRICK)
Block(-1,-30,-5,NETHER_BRICK)
Block(-1,-30,-4,NETHER_BRICK)
Block(-1,-30,-3,NETHER_BRICK)
Block(-1,-30,-2,NETHER_BRICK)
Block(-1,-30,-1,NETHER_BRICK)
Block(-1,-30,0,NETHER_BRICK)
Block(-1,-30,1,NETHER_BRICK)
Block(-1,-30,2,NETHER_BRICK)
Block(-1,-30,3,NETHER_BRICK)
Block(-1,-30,4,NETHER_BRICK)
Block(-1,-30,5,NETHER_BRICK)
Block(-1,-30,6,NETHER_BRICK)
Block(-1,-29,-6,NETHER_BRICK)
Block(-1,-29,-5,NETHER_BRICK)
Block(-1,-29,-4,NETHER_BRICK)
Block(-1,-29,-3,NETHER_BRICK)
Block(-1,-29,-2,NETHER_BRICK)
Block(-1,-29,-1,NETHER_BRICK)
Block(-1,-29,0,NETHER_BRICK)
Block(-1,-29,1,NETHER_BRICK)
Block(-1,-29,2,NETHER_BRICK)
Block(-1,-29,3,NETHER_BRICK)
Block(-1,-29,4,NETHER_BRICK)
Block(-1,-29,5,NETHER_BRICK)
Block(-1,-29,6,NETHER_BRICK)
Block(-1,-28,-6,NETHER_BRICK)
Block(-1,-28,-5,NETHER_BRICK)
Block(-1,-28,-4,NETHER_BRICK)
Block(-1,-28,-3,NETHER_BRICK)
Block(-1,-28,-2,NETHER_BRICK)
Block(-1,-28,-1,NETHER_BRICK)
Block(-1,-28,0,NETHER_BRICK)
Block(-1,-28,1,NETHER_BRICK)
Block(-1,-28,2,NETHER_BRICK)
Block(-1,-28,3,NETHER_BRICK)
Block(-1,-28,4,NETHER_BRICK)
Block(-1,-28,5,NETHER_BRICK)
Block(-1,-28,6,NETHER_BRICK)
Block(-1,-27,-6,NETHER_BRICK)
Block(-1,-27,-5,NETHER_BRICK)
Block(-1,-27,-4,NETHER_BRICK)
Block(-1,-27,-3,NETHER_BRICK)
Block(-1,-27,-2,NETHER_BRICK)
Block(-1,-27,-1,NETHER_BRICK)
Block(-1,-27,0,NETHER_BRICK)
Block(-1,-27,1,NETHER_BRICK)
Block(-1,-27,2,NETHER_BRICK)
Block(-1,-27,3,NETHER_BRICK)
Block(-1,-27,4,NETHER_BRICK)
Block(-1,-27,5,NETHER_BRICK)
Block(-1,-27,6,NETHER_BRICK)
Block(-1,-26,-6,NETHER_BRICK)
Block(-1,-26,-5,NETHER_BRICK)
Block(-1,-26,-4,NETHER_BRICK)
Block(-1,-26,-3,NETHER_BRICK)
Block(-1,-26,-2,NETHER_BRICK)
Block(-1,-26,-1,NETHER_BRICK)
Block(-1,-26,0,NETHER_BRICK)
Block(-1,-26,1,NETHER_BRICK)
Block(-1,-26,2,NETHER_BRICK)
Block(-1,-26,3,NETHER_BRICK)
Block(-1,-26,4,NETHER_BRICK)
Block(-1,-26,5,NETHER_BRICK)
Block(-1,-26,6,NETHER_BRICK)
Block(-1,-25,-6,NETHER_BRICK)
Block(-1,-25,-5,NETHER_BRICK)
Block(-1,-25,-4,NETHER_BRICK)
Block(-1,-25,-3,NETHER_BRICK)
Block(-1,-25,-2,NETHER_BRICK)
Block(-1,-25,-1,NETHER_BRICK)
Block(-1,-25,0,NETHER_BRICK)
Block(-1,-25,1,NETHER_BRICK)
Block(-1,-25,2,NETHER_BRICK)
Block(-1,-25,3,NETHER_BRICK)
Block(-1,-25,4,NETHER_BRICK)
Block(-1,-25,5,NETHER_BRICK)
Block(-1,-25,6,NETHER_BRICK)
Block(-1,-24,-6,NETHER_BRICK)
Block(-1,-24,-5,NETHER_BRICK)
Block(-1,-24,-4,NETHER_BRICK)
Block(-1,-24,-3,NETHER_BRICK)
Block(-1,-24,-2,NETHER_BRICK)
Block(-1,-24,-1,NETHER_BRICK)
Block(-1,-24,0,NETHER_BRICK)
Block(-1,-24,1,NETHER_BRICK)
Block(-1,-24,2,NETHER_BRICK)
Block(-1,-24,3,NETHER_BRICK)
Block(-1,-24,4,NETHER_BRICK)
Block(-1,-24,5,NETHER_BRICK)
Block(-1,-24,6,NETHER_BRICK)
Block(-1,-23,-6,NETHER_BRICK)
Block(-1,-23,-5,NETHER_BRICK)
Block(-1,-23,-4,NETHER_BRICK)
Block(-1,-23,-3,NETHER_BRICK)
Block(-1,-23,-2,NETHER_BRICK)
Block(-1,-23,-1,NETHER_BRICK)
Block(-1,-23,0,NETHER_BRICK)
Block(-1,-23,1,NETHER_BRICK)
Block(-1,-23,2,NETHER_BRICK)
Block(-1,-23,3,NETHER_BRICK)
Block(-1,-23,4,NETHER_BRICK)
Block(-1,-23,5,NETHER_BRICK)
Block(-1,-23,6,NETHER_BRICK)
Block(-1,-22,-6,NETHER_BRICK)
Block(-1,-22,-5,NETHER_BRICK)
Block(-1,-22,-4,NETHER_BRICK)
Block(-1,-22,-3,NETHER_BRICK)
Block(-1,-22,-2,NETHER_BRICK)
Block(-1,-22,-1,NETHER_BRICK)
Block(-1,-22,0,NETHER_BRICK)
Block(-1,-22,1,NETHER_BRICK)
Block(-1,-22,2,NETHER_BRICK)
Block(-1,-22,3,NETHER_BRICK)
Block(-1,-22,4,NETHER_BRICK)
Block(-1,-22,5,NETHER_BRICK)
Block(-1,-22,6,NETHER_BRICK)
Block(-1,-21,-6,NETHER_BRICK)
Block(-1,-21,-5,NETHER_BRICK)
Block(-1,-21,-4,NETHER_BRICK)
Block(-1,-21,-3,NETHER_BRICK)
Block(-1,-21,-2,NETHER_BRICK)
Block(-1,-21,-1,NETHER_BRICK)
Block(-1,-21,0,NETHER_BRICK)
Block(-1,-21,1,NETHER_BRICK)
Block(-1,-21,2,NETHER_BRICK)
Block(-1,-21,3,NETHER_BRICK)
Block(-1,-21,4,NETHER_BRICK)
Block(-1,-21,5,NETHER_BRICK)
Block(-1,-21,6,NETHER_BRICK)
Block(-1,-20,-6,NETHER_BRICK)
Block(-1,-20,-5,NETHER_BRICK)
Block(-1,-20,-4,NETHER_BRICK)
Block(-1,-20,-3,NETHER_BRICK)
Block(-1,-20,-2,NETHER_BRICK)
Block(-1,-20,-1,NETHER_BRICK)
Block(-1,-20,0,NETHER_BRICK)
Block(-1,-20,1,NETHER_BRICK)
Block(-1,-20,2,NETHER_BRICK)
Block(-1,-20,3,NETHER_BRICK)
Block(-1,-20,4,NETHER_BRICK)
Block(-1,-20,5,NETHER_BRICK)
Block(-1,-20,6,NETHER_BRICK)
Block(-1,-19,-6,NETHER_BRICK)
Block(-1,-19,-5,NETHER_BRICK)
Block(-1,-19,-4,NETHER_BRICK)
Block(-1,-19,-3,NETHER_BRICK)
Block(-1,-19,-2,NETHER_BRICK)
Block(-1,-19,-1,NETHER_BRICK)
Block(-1,-19,0,NETHER_BRICK)
Block(-1,-19,1,NETHER_BRICK)
Block(-1,-19,2,NETHER_BRICK)
Block(-1,-19,3,NETHER_BRICK)
Block(-1,-19,4,NETHER_BRICK)
Block(-1,-19,5,NETHER_BRICK)
Block(-1,-19,6,NETHER_BRICK)
Block(-1,-18,-6,NETHER_BRICK)
Block(-1,-18,-5,NETHER_BRICK)
Block(-1,-18,-4,NETHER_BRICK)
Block(-1,-18,-3,NETHER_BRICK)
Block(-1,-18,-2,NETHER_BRICK)
Block(-1,-18,-1,NETHER_BRICK)
Block(-1,-18,0,NETHER_BRICK)
Block(-1,-18,1,NETHER_BRICK)
Block(-1,-18,2,NETHER_BRICK)
Block(-1,-18,3,NETHER_BRICK)
Block(-1,-18,4,NETHER_BRICK)
Block(-1,-18,5,NETHER_BRICK)
Block(-1,-18,6,NETHER_BRICK)
Block(-1,-17,-6,NETHER_BRICK)
Block(-1,-17,-5,NETHER_BRICK)
Block(-1,-17,-4,NETHER_BRICK)
Block(-1,-17,-3,NETHER_BRICK)
Block(-1,-17,-2,NETHER_BRICK)
Block(-1,-17,-1,NETHER_BRICK)
Block(-1,-17,0,NETHER_BRICK)
Block(-1,-17,1,NETHER_BRICK)
Block(-1,-17,2,NETHER_BRICK)
Block(-1,-17,3,NETHER_BRICK)
Block(-1,-17,4,NETHER_BRICK)
Block(-1,-17,5,NETHER_BRICK)
Block(-1,-17,6,NETHER_BRICK)
Block(-1,-16,-6,NETHER_BRICK)
Block(-1,-16,-5,NETHER_BRICK)
Block(-1,-16,-4,NETHER_BRICK)
Block(-1,-16,-3,NETHER_BRICK)
Block(-1,-16,-2,NETHER_BRICK)
Block(-1,-16,-1,NETHER_BRICK)
Block(-1,-16,0,NETHER_BRICK)
Block(-1,-16,1,NETHER_BRICK)
Block(-1,-16,2,NETHER_BRICK)
Block(-1,-16,3,NETHER_BRICK)
Block(-1,-16,4,NETHER_BRICK)
Block(-1,-16,5,NETHER_BRICK)
Block(-1,-16,6,NETHER_BRICK)
Block(-1,-15,-6,NETHER_BRICK)
Block(-1,-15,-5,NETHER_BRICK)
Block(-1,-15,-4,NETHER_BRICK)
Block(-1,-15,-3,NETHER_BRICK)
Block(-1,-15,-2,NETHER_BRICK)
Block(-1,-15,-1,NETHER_BRICK)
Block(-1,-15,0,NETHER_BRICK)
Block(-1,-15,1,NETHER_BRICK)
Block(-1,-15,2,NETHER_BRICK)
Block(-1,-15,3,NETHER_BRICK)
Block(-1,-15,4,NETHER_BRICK)
Block(-1,-15,5,NETHER_BRICK)
Block(-1,-15,6,NETHER_BRICK)
Block(-1,-14,-6,NETHER_BRICK)
Block(-1,-14,-5,NETHER_BRICK)
Block(-1,-14,-4,NETHER_BRICK)
Block(-1,-14,-3,NETHER_BRICK)
Block(-1,-14,-2,NETHER_BRICK)
Block(-1,-14,-1,NETHER_BRICK)
Block(-1,-14,0,NETHER_BRICK)
Block(-1,-14,1,NETHER_BRICK)
Block(-1,-14,2,NETHER_BRICK)
Block(-1,-14,3,NETHER_BRICK)
Block(-1,-14,4,NETHER_BRICK)
Block(-1,-14,5,NETHER_BRICK)
Block(-1,-14,6,NETHER_BRICK)
Block(-1,-13,-6,NETHER_BRICK)
Block(-1,-13,-5,NETHER_BRICK)
Block(-1,-13,-4,NETHER_BRICK)
Block(-1,-13,-3,NETHER_BRICK)
Block(-1,-13,-2,NETHER_BRICK)
Block(-1,-13,-1,NETHER_BRICK)
Block(-1,-13,0,NETHER_BRICK)
Block(-1,-13,1,NETHER_BRICK)
Block(-1,-13,2,NETHER_BRICK)
Block(-1,-13,3,NETHER_BRICK)
Block(-1,-13,4,NETHER_BRICK)
Block(-1,-13,5,NETHER_BRICK)
Block(-1,-13,6,NETHER_BRICK)
Block(-1,-12,-6,NETHER_BRICK)
Block(-1,-12,-5,NETHER_BRICK)
Block(-1,-12,-4,NETHER_BRICK)
Block(-1,-12,-3,NETHER_BRICK)
Block(-1,-12,-2,NETHER_BRICK)
Block(-1,-12,-1,NETHER_BRICK)
Block(-1,-12,0,NETHER_BRICK)
Block(-1,-12,1,NETHER_BRICK)
Block(-1,-12,2,NETHER_BRICK)
Block(-1,-12,3,NETHER_BRICK)
Block(-1,-12,4,NETHER_BRICK)
Block(-1,-12,5,NETHER_BRICK)
Block(-1,-12,6,NETHER_BRICK)
Block(-1,-11,-6,NETHER_BRICK)
Block(-1,-11,-5,NETHER_BRICK)
Block(-1,-11,-4,NETHER_BRICK)
Block(-1,-11,-3,NETHER_BRICK)
Block(-1,-11,-2,NETHER_BRICK)
Block(-1,-11,-1,NETHER_BRICK)
Block(-1,-11,0,NETHER_BRICK)
Block(-1,-11,1,NETHER_BRICK)
Block(-1,-11,2,NETHER_BRICK)
Block(-1,-11,3,NETHER_BRICK)
Block(-1,-11,4,NETHER_BRICK)
Block(-1,-11,5,NETHER_BRICK)
Block(-1,-11,6,NETHER_BRICK)
Block(-1,-10,-6,NETHER_BRICK)
Block(-1,-10,-5,NETHER_BRICK)
Block(-1,-10,-4,NETHER_BRICK)
Block(-1,-10,-3,NETHER_BRICK)
Block(-1,-10,-2,NETHER_BRICK)
Block(-1,-10,-1,NETHER_BRICK)
Block(-1,-10,0,NETHER_BRICK)
Block(-1,-10,1,NETHER_BRICK)
Block(-1,-10,2,NETHER_BRICK)
Block(-1,-10,3,NETHER_BRICK)
Block(-1,-10,4,NETHER_BRICK)
Block(-1,-10,5,NETHER_BRICK)
Block(-1,-10,6,NETHER_BRICK)
Block(-1,-9,-6,NETHER_BRICK)
Block(-1,-9,-5,NETHER_BRICK)
Block(-1,-9,-4,NETHER_BRICK)
Block(-1,-9,-3,NETHER_BRICK)
Block(-1,-9,-2,NETHER_BRICK)
Block(-1,-9,-1,NETHER_BRICK)
Block(-1,-9,0,NETHER_BRICK)
Block(-1,-9,1,NETHER_BRICK)
Block(-1,-9,2,NETHER_BRICK)
Block(-1,-9,3,NETHER_BRICK)
Block(-1,-9,4,NETHER_BRICK)
Block(-1,-9,5,NETHER_BRICK)
Block(-1,-9,6,NETHER_BRICK)
Block(-1,-8,-6,NETHER_BRICK)
Block(-1,-8,-5,NETHER_BRICK)
Block(-1,-8,-4,NETHER_BRICK)
Block(-1,-8,-3,NETHER_BRICK)
Block(-1,-8,-2,NETHER_BRICK)
Block(-1,-8,-1,NETHER_BRICK)
Block(-1,-8,0,NETHER_BRICK)
Block(-1,-8,1,NETHER_BRICK)
Block(-1,-8,2,NETHER_BRICK)
Block(-1,-8,3,NETHER_BRICK)
Block(-1,-8,4,NETHER_BRICK)
Block(-1,-8,5,NETHER_BRICK)
Block(-1,-8,6,NETHER_BRICK)
Block(-1,-7,-6,NETHER_BRICK)
Block(-1,-7,-5,NETHER_BRICK)
Block(-1,-7,-4,NETHER_BRICK)
Block(-1,-7,-3,NETHER_BRICK)
Block(-1,-7,-2,NETHER_BRICK)
Block(-1,-7,-1,NETHER_BRICK)
Block(-1,-7,0,NETHER_BRICK)
Block(-1,-7,1,NETHER_BRICK)
Block(-1,-7,2,NETHER_BRICK)
Block(-1,-7,3,NETHER_BRICK)
Block(-1,-7,4,NETHER_BRICK)
Block(-1,-7,5,NETHER_BRICK)
Block(-1,-7,6,NETHER_BRICK)
Block(-1,-6,-6,NETHER_BRICK)
Block(-1,-6,-5,NETHER_BRICK)
Block(-1,-6,-4,NETHER_BRICK)
Block(-1,-6,-3,NETHER_BRICK)
Block(-1,-6,-2,NETHER_BRICK)
Block(-1,-6,-1,NETHER_BRICK)
Block(-1,-6,0,NETHER_BRICK)
Block(-1,-6,1,NETHER_BRICK)
Block(-1,-6,2,NETHER_BRICK)
Block(-1,-6,3,NETHER_BRICK)
Block(-1,-6,4,NETHER_BRICK)
Block(-1,-6,5,NETHER_BRICK)
Block(-1,-6,6,NETHER_BRICK)
Block(-1,-5,-6,NETHER_BRICK)
Block(-1,-5,-5,NETHER_BRICK)
Block(-1,-5,-4,NETHER_BRICK)
Block(-1,-5,-3,NETHER_BRICK)
Block(-1,-5,-2,NETHER_BRICK)
Block(-1,-5,-1,NETHER_BRICK)
Block(-1,-5,0,NETHER_BRICK)
Block(-1,-5,1,NETHER_BRICK)
Block(-1,-5,2,NETHER_BRICK)
Block(-1,-5,3,NETHER_BRICK)
Block(-1,-5,4,NETHER_BRICK)
Block(-1,-5,5,NETHER_BRICK)
Block(-1,-5,6,NETHER_BRICK)
Block(-1,-4,-6,NETHER_BRICK)
Block(-1,-4,-5,NETHER_BRICK)
Block(-1,-4,-4,NETHER_BRICK)
Block(-1,-4,-3,NETHER_BRICK)
Block(-1,-4,-2,NETHER_BRICK)
Block(-1,-4,-1,NETHER_BRICK)
Block(-1,-4,0,NETHER_BRICK)
Block(-1,-4,1,NETHER_BRICK)
Block(-1,-4,2,NETHER_BRICK)
Block(-1,-4,3,NETHER_BRICK)
Block(-1,-4,4,NETHER_BRICK)
Block(-1,-4,5,NETHER_BRICK)
Block(-1,-4,6,NETHER_BRICK)
Block(-1,-3,-6,NETHER_BRICK)
Block(-1,-3,-5,NETHER_BRICK)
Block(-1,-3,-4,NETHER_BRICK)
Block(-1,-3,-3,NETHER_BRICK)
Block(-1,-3,-2,NETHER_BRICK)
Block(-1,-3,-1,NETHER_BRICK)
Block(-1,-3,0,NETHER_BRICK)
Block(-1,-3,1,NETHER_BRICK)
Block(-1,-3,2,NETHER_BRICK)
Block(-1,-3,3,NETHER_BRICK)
Block(-1,-3,4,NETHER_BRICK)
Block(-1,-3,5,NETHER_BRICK)
Block(-1,-3,6,NETHER_BRICK)
Block(-1,-2,-6,NETHER_BRICK)
Block(-1,-2,-5,NETHER_BRICK)
Block(-1,-2,-4,NETHER_BRICK)
Block(-1,-2,-3,NETHER_BRICK)
Block(-1,-2,-2,NETHER_BRICK)
Block(-1,-2,-1,NETHER_BRICK)
Block(-1,-2,0,NETHER_BRICK)
Block(-1,-2,1,NETHER_BRICK)
Block(-1,-2,2,NETHER_BRICK)
Block(-1,-2,3,NETHER_BRICK)
Block(-1,-2,4,NETHER_BRICK)
Block(-1,-2,5,NETHER_BRICK)
Block(-1,-2,6,NETHER_BRICK)
Block(-1,-1,-6,NETHER_BRICK)
Block(-1,-1,-5,NETHER_BRICK)
Block(-1,-1,-4,NETHER_BRICK)
Block(-1,-1,-3,NETHER_BRICK)
Block(-1,-1,-2,NETHER_BRICK)
Block(-1,-1,-1,NETHER_BRICK)
Block(-1,-1,0,NETHER_BRICK)
Block(-1,-1,1,NETHER_BRICK)
Block(-1,-1,2,NETHER_BRICK)
Block(-1,-1,3,NETHER_BRICK)
Block(-1,-1,4,NETHER_BRICK)
Block(-1,-1,5,NETHER_BRICK)
Block(-1,-1,6,NETHER_BRICK)
Block(-1,0,-6,NETHER_BRICK)
Block(-1,0,-5,NETHER_BRICK)
Block(-1,0,-4,NETHER_BRICK)
Block(-1,0,-3,NETHER_BRICK)
Block(-1,0,-2,NETHER_BRICK)
Block(-1,0,-1,NETHER_BRICK)
Block(-1,0,0,NETHER_BRICK)
Block(-1,0,1,NETHER_BRICK)
Block(-1,0,2,NETHER_BRICK)
Block(-1,0,3,NETHER_BRICK)
Block(-1,0,4,NETHER_BRICK)
Block(-1,0,5,NETHER_BRICK)
Block(-1,0,6,NETHER_BRICK)
Block(-1,1,-6,NETHER_BRICK)
Block(-1,1,-5,NETHER_BRICK)
Block(-1,1,-4,NETHER_BRICK)
Block(-1,1,-3,NETHER_BRICK)
Block(-1,1,-2,NETHER_BRICK)
Block(-1,1,-1,NETHER_BRICK)
Block(-1,1,0,NETHER_BRICK)
Block(-1,1,1,NETHER_BRICK)
Block(-1,1,2,NETHER_BRICK)
Block(-1,1,3,NETHER_BRICK)
Block(-1,1,4,NETHER_BRICK)
Block(-1,1,5,NETHER_BRICK)
Block(-1,1,6,NETHER_BRICK)
Block(-1,2,-6,AIR)
Block(-1,2,-5,AIR)
Block(-1,2,-4,AIR)
Block(-1,2,-3,AIR)
Block(-1,2,-2,AIR)
Block(-1,2,-1,AIR)
Block(-1,2,0,AIR)
Block(-1,2,1,AIR)
Block(-1,2,2,AIR)
Block(-1,2,3,AIR)
Block(-1,2,4,NETHER_BRICK)
Block(-1,2,5,NETHER_BRICK)
Block(-1,2,6,NETHER_BRICK)
Block(-1,3,-6,AIR)
Block(-1,3,-5,AIR)
Block(-1,3,-4,AIR)
Block(-1,3,-3,AIR)
Block(-1,3,-2,AIR)
Block(-1,3,-1,AIR)
Block(-1,3,0,AIR)
Block(-1,3,1,AIR)
Block(-1,3,2,AIR)
Block(-1,3,3,AIR)
Block(-1,3,4,AIR)
Block(-1,3,5,NETHER_BRICK)
Block(-1,3,6,NETHER_BRICK)
Block(-1,4,-6,AIR)
Block(-1,4,-5,AIR)
Block(-1,4,-4,AIR)
Block(-1,4,-3,AIR)
Block(-1,4,-2,AIR)
Block(-1,4,-1,AIR)
Block(-1,4,0,AIR)
Block(-1,4,1,AIR)
Block(-1,4,2,AIR)
Block(-1,4,3,AIR)
Block(-1,4,4,AIR)
Block(-1,4,5,NETHER_BRICK)
Block(-1,4,6,NETHER_BRICK)
Block(-1,5,-6,AIR)
Block(-1,5,-5,AIR)
Block(-1,5,-4,AIR)
Block(-1,5,-3,AIR)
Block(-1,5,-2,AIR)
Block(-1,5,-1,AIR)
Block(-1,5,0,AIR)
Block(-1,5,1,AIR)
Block(-1,5,2,AIR)
Block(-1,5,3,AIR)
Block(-1,5,4,AIR)
Block(-1,5,5,NETHER_BRICK)
Block(-1,5,6,NETHER_BRICK)
Block(-1,6,-6,AIR)
Block(-1,6,-5,NETHER_BRICK)
Block(-1,6,-4,NETHER_BRICK)
Block(-1,6,-3,AIR)
Block(-1,6,-2,AIR)
Block(-1,6,-1,AIR)
Block(-1,6,0,AIR)
Block(-1,6,1,AIR)
Block(-1,6,2,AIR)
Block(-1,6,3,AIR)
Block(-1,6,4,AIR)
Block(-1,6,5,NETHER_BRICK)
Block(-1,6,6,NETHER_BRICK)
Block(-1,7,-4,NETHER_BRICK)
Block(-1,7,-3,AIR)
Block(-1,7,-2,AIR)
Block(-1,7,-1,AIR)
Block(-1,7,0,AIR)
Block(-1,7,1,AIR)
Block(-1,7,2,AIR)
Block(-1,7,3,AIR)
Block(-1,7,4,NETHER_BRICK)
Block(-1,7,5,NETHER_BRICK)
Block(-1,7,6,NETHER_BRICK)
Block(-1,8,-4,NETHER_BRICK)
Block(-1,8,-3,AIR)
Block(-1,8,-2,AIR)
Block(-1,8,-1,AIR)
Block(-1,8,0,AIR)
Block(-1,8,1,AIR)
Block(-1,8,2,AIR)
Block(-1,8,3,AIR)
Block(-1,8,4,NETHER_BRICK)
Block(-1,8,5,NETHER_BRICK)
Block(-1,8,6,NETHER_BRICK)
Block(-1,9,-4,NETHER_FENCE)
Block(-1,9,-3,AIR)
Block(-1,9,-2,AIR)
Block(-1,9,-1,AIR)
Block(-1,9,0,AIR)
Block(-1,9,1,AIR)
Block(-1,9,2,AIR)
Block(-1,9,3,AIR)
Block(-1,9,4,NETHER_BRICK)
Block(-1,9,5,AIR)
Block(-1,9,6,NETHER_BRICK)
Block(-1,10,-4,NETHER_FENCE)
Block(-1,10,-3,AIR)
Block(-1,10,-2,AIR)
Block(-1,10,-1,AIR)
Block(-1,10,0,AIR)
Block(-1,10,1,AIR)
Block(-1,10,2,AIR)
Block(-1,10,3,AIR)
Block(-1,10,4,NETHER_BRICK)
Block(-1,10,5,AIR)
Block(-1,10,6,NETHER_BRICK)
Block(-1,11,-4,NETHER_BRICK)
Block(-1,11,-3,AIR)
Block(-1,11,-2,AIR)
Block(-1,11,-1,AIR)
Block(-1,11,0,AIR)
Block(-1,11,1,AIR)
Block(-1,11,2,AIR)
Block(-1,11,3,AIR)
Block(-1,11,4,AIR)
Block(-1,11,5,AIR)
Block(-1,11,6,NETHER_BRICK)
Block(-1,12,-4,NETHER_BRICK)
Block(-1,12,-3,AIR)
Block(-1,12,-2,AIR)
Block(-1,12,-1,AIR)
Block(-1,12,0,AIR)
Block(-1,12,1,AIR)
Block(-1,12,2,AIR)
Block(-1,12,3,AIR)
Block(-1,12,4,AIR)
Block(-1,12,5,AIR)
Block(-1,12,6,NETHER_BRICK)
Block(-1,13,-4,NETHER_FENCE)
Block(-1,13,-3,AIR)
Block(-1,13,-2,AIR)
Block(-1,13,-1,AIR)
Block(-1,13,0,AIR)
Block(-1,13,1,AIR)
Block(-1,13,2,AIR)
Block(-1,13,3,AIR)
Block(-1,13,4,AIR)
Block(-1,13,5,NETHER_BRICK)
Block(-1,13,6,NETHER_BRICK)
Block(-1,14,-4,NETHER_FENCE)
Block(-1,14,-3,AIR)
Block(-1,14,-2,AIR)
Block(-1,14,-1,AIR)
Block(-1,14,0,AIR)
Block(-1,14,1,AIR)
Block(-1,14,2,AIR)
Block(-1,14,3,AIR)
Block(-1,14,4,AIR)
Block(-1,14,5,NETHER_BRICK)
Block(-1,14,6,NETHER_BRICK)
Block(-1,15,-4,NETHER_BRICK)
Block(-1,15,-3,AIR)
Block(-1,15,-2,AIR)
Block(-1,15,-1,AIR)
Block(-1,15,0,AIR)
Block(-1,15,1,AIR)
Block(-1,15,2,AIR)
Block(-1,15,3,AIR)
Block(-1,15,4,NETHER_BRICK)
Block(-1,15,5,NETHER_BRICK)
Block(-1,15,6,NETHER_BRICK)
Block(-1,16,-4,NETHER_BRICK)
Block(-1,16,-3,AIR)
Block(-1,16,-2,AIR)
Block(-1,16,-1,AIR)
Block(-1,16,0,AIR)
Block(-1,16,1,AIR)
Block(-1,16,2,AIR)
Block(-1,16,3,AIR)
Block(-1,16,4,NETHER_BRICK)
Block(-1,16,5,NETHER_BRICK)
Block(-1,16,6,NETHER_BRICK)
Block(-1,17,-4,NETHER_FENCE)
Block(-1,17,-3,AIR)
Block(-1,17,-2,AIR)
Block(-1,17,-1,AIR)
Block(-1,17,0,AIR)
Block(-1,17,1,AIR)
Block(-1,17,2,AIR)
Block(-1,17,3,AIR)
Block(-1,17,4,NETHER_BRICK)
Block(-1,17,5,AIR)
Block(-1,17,6,NETHER_BRICK)
Block(-1,18,-4,NETHER_FENCE)
Block(-1,18,-3,AIR)
Block(-1,18,-2,AIR)
Block(-1,18,-1,AIR)
Block(-1,18,0,AIR)
Block(-1,18,1,AIR)
Block(-1,18,2,AIR)
Block(-1,18,3,AIR)
Block(-1,18,4,NETHER_BRICK)
Block(-1,18,5,AIR)
Block(-1,18,6,NETHER_BRICK)
Block(-1,19,-4,NETHER_BRICK)
Block(-1,19,-3,AIR)
Block(-1,19,-2,AIR)
Block(-1,19,-1,AIR)
Block(-1,19,0,AIR)
Block(-1,19,1,AIR)
Block(-1,19,2,AIR)
Block(-1,19,3,AIR)
Block(-1,19,4,AIR)
Block(-1,19,5,AIR)
Block(-1,19,6,NETHER_BRICK)
Block(-1,20,-4,NETHER_BRICK)
Block(-1,20,-3,AIR)
Block(-1,20,-2,AIR)
Block(-1,20,-1,AIR)
Block(-1,20,0,AIR)
Block(-1,20,1,AIR)
Block(-1,20,2,AIR)
Block(-1,20,3,AIR)
Block(-1,20,4,AIR)
Block(-1,20,5,AIR)
Block(-1,20,6,NETHER_BRICK)
Block(-1,21,-4,NETHER_FENCE)
Block(-1,21,-3,AIR)
Block(-1,21,-2,AIR)
Block(-1,21,-1,AIR)
Block(-1,21,0,AIR)
Block(-1,21,1,AIR)
Block(-1,21,2,AIR)
Block(-1,21,3,AIR)
Block(-1,21,4,AIR)
Block(-1,21,5,NETHER_BRICK)
Block(-1,21,6,NETHER_BRICK)
Block(-1,22,-4,NETHER_FENCE)
Block(-1,22,-3,NETHER_BRICK)
Block(-1,22,-2,NETHER_BRICK)
Block(-1,22,-1,NETHER_BRICK)
Block(-1,22,0,NETHER_FENCE)
Block(-1,22,1,NETHER_BRICK)
Block(-1,22,2,NETHER_BRICK)
Block(-1,22,3,NETHER_BRICK)
Block(-1,22,4,AIR)
Block(-1,22,5,NETHER_BRICK)
Block(-1,22,6,NETHER_BRICK)
Block(-1,23,-4,NETHER_BRICK)
Block(-1,23,-3,AIR)
Block(-1,23,-2,AIR)
Block(-1,23,-1,AIR)
Block(-1,23,0,AIR)
Block(-1,23,1,AIR)
Block(-1,23,2,AIR)
Block(-1,23,3,AIR)
Block(-1,23,4,AIR)
Block(-1,23,5,AIR)
Block(-1,23,6,NETHER_BRICK)
Block(-1,24,-4,NETHER_BRICK)
Block(-1,24,-3,AIR)
Block(-1,24,-2,AIR)
Block(-1,24,-1,AIR)
Block(-1,24,0,AIR)
Block(-1,24,1,AIR)
Block(-1,24,2,AIR)
Block(-1,24,3,AIR)
Block(-1,24,4,AIR)
Block(-1,24,5,AIR)
Block(-1,24,6,NETHER_FENCE)
Block(-1,25,-4,NETHER_FENCE)
Block(-1,25,-3,AIR)
Block(-1,25,-2,AIR)
Block(-1,25,-1,AIR)
Block(-1,25,0,AIR)
Block(-1,25,1,AIR)
Block(-1,25,2,AIR)
Block(-1,25,3,AIR)
Block(-1,25,4,AIR)
Block(-1,25,5,AIR)
Block(-1,25,6,NETHER_FENCE)
Block(-1,26,-4,NETHER_FENCE)
Block(-1,26,-3,AIR)
Block(-1,26,-2,AIR)
Block(-1,26,-1,AIR)
Block(-1,26,0,AIR)
