
#######################################################################
# +-----------------------------------------------------------------+ #
# |                            BO3 object                           | #
# +-----------------------------------------------------------------+ #
#######################################################################

# This is the config file of a custom object.
# If you add this object correctly to your BiomeConfigs, it will spawn in the world.

# This is the creator of this BO3 object
Author: TrueMalice

# A short description of this BO3 object
Description: No description given

# The BO3 version, don't change this! It can be used by external applications to do a version check.
Version: 3

# The settings mode, WriteAll, WriteWithoutComments or WriteDisable. See WorldConfig.
SettingsMode: WriteAll


#######################################################################
# +-----------------------------------------------------------------+ #
# |                          Main settings                          | #
# +-----------------------------------------------------------------+ #
#######################################################################

# This needs to be set to true to spawn the object in the Tree and Sapling resources.
Tree: false

# The frequency of the BO3 from 1 to 200. Tries this many times to spawn this BO3 when using the CustomObject(...) resource.
# Ignored by Tree(..), Sapling(..) and CustomStructure(..)
Frequency: 1

# The rarity of the BO3 from 0 to 100. Each spawn attempt has rarity% chance to succeed when using the CustomObject(...) resource.
# Ignored by Tree(..), Sapling(..) and CustomStructure(..)
Rarity: 100.0

# If you set this to true, the BO3 will be placed with a random rotation.
RotateRandomly: false

# The spawn height of the BO3 - randomY, randomY or highestSolidBlock.
SpawnHeight: randomY

# The height limits for the BO3.
MinHeight: 0

MaxHeight: 256

# Objects can have other objects attacthed to it: branches. Branches can also
# have branches attached to it, which can also have branches, etc. This is the
# maximum branch depth for this objects.
MaxBranchDepth: 10

# When spawned with the UseWorld keyword, this BO3 should NOT spawn in the following biomes.
# If you writer.write the BO3 name directly in the BiomeConfigs, this will be ignored.
ExcludedBiomes: All


#######################################################################
# +-----------------------------------------------------------------+ #
# |                      Source block settings                      | #
# +-----------------------------------------------------------------+ #
#######################################################################

# The block(s) the BO3 should spawn in.
SourceBlocks: AIR, LAVA, NETHERRACK

# The maximum percentage of the BO3 that can be outside the SourceBlock.
# The BO3 won't be placed on a location with more blocks outside the SourceBlock than this percentage.
MaxPercentageOutsideSourceBlock: 65

# What to do when a block is about to be placed outside the SourceBlock? (dontPlace, placeAnyway)
OutsideSourceBlock: dontPlace


#######################################################################
# +-----------------------------------------------------------------+ #
# |                              Blocks                             | #
# +-----------------------------------------------------------------+ #
#######################################################################

# All the blocks used in the BO3 are listed here. Possible blocks:
# Block(x,y,z,id[.data][,nbtfile.nbt)
# RandomBlock(x,y,z,id[:data][,nbtfile.nbt],chance[,id[:data][,nbtfile.nbt],chance[,...]])
# So RandomBlock(0,0,0,CHEST,chest.nbt,50,CHEST,anotherchest.nbt,100) will spawn a chest at
# the BO3 origin, and give it a 50% chance to have the contents of chest.nbt, or, if that
# fails, a 100% percent chance to have the contents of anotherchest.nbt.
Block(-3,-39,-2,NETHER_BRICK)
Block(-3,-39,-1,NETHER_BRICK)
Block(-3,-39,0,NETHER_BRICK)
Block(-3,-39,1,NETHER_BRICK)
Block(-3,-39,2,NETHER_BRICK)
Block(-3,-38,-2,NETHER_BRICK)
Block(-3,-38,-1,NETHER_BRICK)
Block(-3,-38,0,NETHER_BRICK)
Block(-3,-38,1,NETHER_BRICK)
Block(-3,-38,2,NETHER_BRICK)
Block(-3,-37,-2,NETHER_BRICK)
Block(-3,-37,-1,NETHER_BRICK)
Block(-3,-37,0,NETHER_BRICK)
Block(-3,-37,1,NETHER_BRICK)
Block(-3,-37,2,NETHER_BRICK)
Block(-3,-36,-2,NETHER_BRICK)
Block(-3,-36,-1,NETHER_BRICK)
Block(-3,-36,0,NETHER_BRICK)
Block(-3,-36,1,NETHER_BRICK)
Block(-3,-36,2,NETHER_BRICK)
Block(-3,-35,-2,NETHER_BRICK)
Block(-3,-35,-1,NETHER_BRICK)
Block(-3,-35,0,NETHER_BRICK)
Block(-3,-35,1,NETHER_BRICK)
Block(-3,-35,2,NETHER_BRICK)
Block(-3,-34,-2,NETHER_BRICK)
Block(-3,-34,-1,NETHER_BRICK)
Block(-3,-34,0,NETHER_BRICK)
Block(-3,-34,1,NETHER_BRICK)
Block(-3,-34,2,NETHER_BRICK)
Block(-3,-33,-2,NETHER_BRICK)
Block(-3,-33,-1,NETHER_BRICK)
Block(-3,-33,0,NETHER_BRICK)
Block(-3,-33,1,NETHER_BRICK)
Block(-3,-33,2,NETHER_BRICK)
Block(-3,-32,-2,NETHER_BRICK)
Block(-3,-32,-1,NETHER_BRICK)
Block(-3,-32,0,NETHER_BRICK)
Block(-3,-32,1,NETHER_BRICK)
Block(-3,-32,2,NETHER_BRICK)
Block(-3,-31,-2,NETHER_BRICK)
Block(-3,-31,-1,NETHER_BRICK)
Block(-3,-31,0,NETHER_BRICK)
Block(-3,-31,1,NETHER_BRICK)
Block(-3,-31,2,NETHER_BRICK)
Block(-3,-30,-2,NETHER_BRICK)
Block(-3,-30,-1,NETHER_BRICK)
Block(-3,-30,0,NETHER_BRICK)
Block(-3,-30,1,NETHER_BRICK)
Block(-3,-30,2,NETHER_BRICK)
Block(-3,-29,-2,NETHER_BRICK)
Block(-3,-29,-1,NETHER_BRICK)
Block(-3,-29,0,NETHER_BRICK)
Block(-3,-29,1,NETHER_BRICK)
Block(-3,-29,2,NETHER_BRICK)
Block(-3,-28,-2,NETHER_BRICK)
Block(-3,-28,-1,NETHER_BRICK)
Block(-3,-28,0,NETHER_BRICK)
Block(-3,-28,1,NETHER_BRICK)
Block(-3,-28,2,NETHER_BRICK)
Block(-3,-27,-2,NETHER_BRICK)
Block(-3,-27,-1,NETHER_BRICK)
Block(-3,-27,0,NETHER_BRICK)
Block(-3,-27,1,NETHER_BRICK)
Block(-3,-27,2,NETHER_BRICK)
Block(-3,-26,-2,NETHER_BRICK)
Block(-3,-26,-1,NETHER_BRICK)
Block(-3,-26,0,NETHER_BRICK)
Block(-3,-26,1,NETHER_BRICK)
Block(-3,-26,2,NETHER_BRICK)
Block(-3,-25,-2,NETHER_BRICK)
Block(-3,-25,-1,NETHER_BRICK)
Block(-3,-25,0,NETHER_BRICK)
Block(-3,-25,1,NETHER_BRICK)
Block(-3,-25,2,NETHER_BRICK)
Block(-3,-24,-2,NETHER_BRICK)
Block(-3,-24,-1,NETHER_BRICK)
Block(-3,-24,0,NETHER_BRICK)
Block(-3,-24,1,NETHER_BRICK)
Block(-3,-24,2,NETHER_BRICK)
Block(-3,-23,-2,NETHER_BRICK)
Block(-3,-23,-1,NETHER_BRICK)
Block(-3,-23,0,NETHER_BRICK)
Block(-3,-23,1,NETHER_BRICK)
Block(-3,-23,2,NETHER_BRICK)
Block(-3,-22,-2,NETHER_BRICK)
Block(-3,-22,-1,NETHER_BRICK)
Block(-3,-22,0,NETHER_BRICK)
Block(-3,-22,1,NETHER_BRICK)
Block(-3,-22,2,NETHER_BRICK)
Block(-3,-21,-2,NETHER_BRICK)
Block(-3,-21,-1,NETHER_BRICK)
Block(-3,-21,0,NETHER_BRICK)
Block(-3,-21,1,NETHER_BRICK)
Block(-3,-21,2,NETHER_BRICK)
Block(-3,-20,-2,NETHER_BRICK)
Block(-3,-20,-1,NETHER_BRICK)
Block(-3,-20,0,NETHER_BRICK)
Block(-3,-20,1,NETHER_BRICK)
Block(-3,-20,2,NETHER_BRICK)
Block(-3,-19,-2,NETHER_BRICK)
Block(-3,-19,-1,NETHER_BRICK)
Block(-3,-19,0,NETHER_BRICK)
Block(-3,-19,1,NETHER_BRICK)
Block(-3,-19,2,NETHER_BRICK)
Block(-3,-18,-2,NETHER_BRICK)
Block(-3,-18,-1,NETHER_BRICK)
Block(-3,-18,0,NETHER_BRICK)
Block(-3,-18,1,NETHER_BRICK)
Block(-3,-18,2,NETHER_BRICK)
Block(-3,-17,-2,NETHER_BRICK)
Block(-3,-17,-1,NETHER_BRICK)
Block(-3,-17,0,NETHER_BRICK)
Block(-3,-17,1,NETHER_BRICK)
Block(-3,-17,2,NETHER_BRICK)
Block(-3,-16,-2,NETHER_BRICK)
Block(-3,-16,-1,NETHER_BRICK)
Block(-3,-16,0,NETHER_BRICK)
Block(-3,-16,1,NETHER_BRICK)
Block(-3,-16,2,NETHER_BRICK)
Block(-3,-15,-2,NETHER_BRICK)
Block(-3,-15,-1,NETHER_BRICK)
Block(-3,-15,0,NETHER_BRICK)
Block(-3,-15,1,NETHER_BRICK)
Block(-3,-15,2,NETHER_BRICK)
Block(-3,-14,-2,NETHER_BRICK)
Block(-3,-14,-1,NETHER_BRICK)
Block(-3,-14,0,NETHER_BRICK)
Block(-3,-14,1,NETHER_BRICK)
Block(-3,-14,2,NETHER_BRICK)
Block(-3,-13,-2,NETHER_BRICK)
Block(-3,-13,-1,NETHER_BRICK)
Block(-3,-13,0,NETHER_BRICK)
Block(-3,-13,1,NETHER_BRICK)
Block(-3,-13,2,NETHER_BRICK)
Block(-3,-12,-2,NETHER_BRICK)
Block(-3,-12,-1,NETHER_BRICK)
Block(-3,-12,0,NETHER_BRICK)
Block(-3,-12,1,NETHER_BRICK)
Block(-3,-12,2,NETHER_BRICK)
Block(-3,-11,-2,NETHER_BRICK)
Block(-3,-11,-1,NETHER_BRICK)
Block(-3,-11,0,NETHER_BRICK)
Block(-3,-11,1,NETHER_BRICK)
Block(-3,-11,2,NETHER_BRICK)
Block(-3,-10,-2,NETHER_BRICK)
Block(-3,-10,-1,NETHER_BRICK)
Block(-3,-10,0,NETHER_BRICK)
Block(-3,-10,1,NETHER_BRICK)
Block(-3,-10,2,NETHER_BRICK)
Block(-3,-9,-2,NETHER_BRICK)
Block(-3,-9,-1,NETHER_BRICK)
Block(-3,-9,0,NETHER_BRICK)
Block(-3,-9,1,NETHER_BRICK)
Block(-3,-9,2,NETHER_BRICK)
Block(-3,-8,-2,NETHER_BRICK)
Block(-3,-8,-1,NETHER_BRICK)
Block(-3,-8,0,NETHER_BRICK)
Block(-3,-8,1,NETHER_BRICK)
Block(-3,-8,2,NETHER_BRICK)
Block(-3,-7,-2,NETHER_BRICK)
Block(-3,-7,-1,NETHER_BRICK)
Block(-3,-7,0,NETHER_BRICK)
Block(-3,-7,1,NETHER_BRICK)
Block(-3,-7,2,NETHER_BRICK)
Block(-3,-6,-2,NETHER_BRICK)
Block(-3,-6,-1,NETHER_BRICK)
Block(-3,-6,0,NETHER_BRICK)
Block(-3,-6,1,NETHER_BRICK)
Block(-3,-6,2,NETHER_BRICK)
Block(-3,-5,-2,NETHER_BRICK)
Block(-3,-5,-1,NETHER_BRICK)
Block(-3,-5,0,NETHER_BRICK)
Block(-3,-5,1,NETHER_BRICK)
Block(-3,-5,2,NETHER_BRICK)
Block(-3,-4,-3,NETHER_BRICK)
Block(-3,-4,-2,NETHER_BRICK)
Block(-3,-4,-1,NETHER_BRICK)
Block(-3,-4,0,NETHER_BRICK)
Block(-3,-4,1,NETHER_BRICK)
Block(-3,-4,2,NETHER_BRICK)
Block(-3,-4,3,NETHER_BRICK)
Block(-3,-3,-3,NETHER_BRICK)
Block(-3,-3,-2,NETHER_BRICK)
Block(-3,-3,-1,NETHER_BRICK)
Block(-3,-3,0,NETHER_BRICK)
Block(-3,-3,1,NETHER_BRICK)
Block(-3,-3,2,NETHER_BRICK)
Block(-3,-3,3,NETHER_BRICK)
Block(-3,-2,-4,NETHER_BRICK)
Block(-3,-2,-3,NETHER_BRICK)
Block(-3,-2,-2,NETHER_BRICK)
Block(-3,-2,-1,NETHER_BRICK)
Block(-3,-2,0,NETHER_BRICK)
Block(-3,-2,1,NETHER_BRICK)
Block(-3,-2,2,NETHER_BRICK)
Block(-3,-2,3,NETHER_BRICK)
Block(-3,-2,4,NETHER_BRICK)
Block(-3,-1,-5,NETHER_BRICK)
Block(-3,-1,-4,NETHER_BRICK)
Block(-3,-1,-3,NETHER_BRICK)
Block(-3,-1,-2,NETHER_BRICK)
Block(-3,-1,-1,NETHER_FENCE)
Block(-3,-1,0,NETHER_BRICK)
Block(-3,-1,1,NETHER_FENCE)
Block(-3,-1,2,NETHER_BRICK)
Block(-3,-1,3,NETHER_BRICK)
Block(-3,-1,4,NETHER_BRICK)
Block(-3,-1,5,NETHER_BRICK)
Block(-3,0,-7,NETHER_BRICK)
Block(-3,0,-6,NETHER_BRICK)
Block(-3,0,-5,NETHER_BRICK)
Block(-3,0,-4,NETHER_BRICK)
Block(-3,0,-3,NETHER_BRICK)
Block(-3,0,-2,NETHER_BRICK)
Block(-3,0,-1,NETHER_FENCE)
Block(-3,0,0,NETHER_BRICK)
Block(-3,0,1,NETHER_FENCE)
Block(-3,0,2,NETHER_BRICK)
Block(-3,0,3,NETHER_BRICK)
Block(-3,0,4,NETHER_BRICK)
Block(-3,0,5,NETHER_BRICK)
Block(-3,0,6,NETHER_BRICK)
Block(-3,0,7,NETHER_BRICK)
Block(-3,1,-7,NETHER_BRICK)
Block(-3,1,-6,NETHER_BRICK)
Block(-3,1,-5,NETHER_BRICK)
Block(-3,1,-4,NETHER_BRICK)
Block(-3,1,-3,NETHER_BRICK)
Block(-3,1,-2,NETHER_BRICK)
Block(-3,1,-1,NETHER_BRICK)
Block(-3,1,0,NETHER_BRICK)
Block(-3,1,1,NETHER_BRICK)
Block(-3,1,2,NETHER_BRICK)
Block(-3,1,3,NETHER_BRICK)
Block(-3,1,4,NETHER_BRICK)
Block(-3,1,5,NETHER_BRICK)
Block(-3,1,6,NETHER_BRICK)
Block(-3,1,7,NETHER_BRICK)
Block(-3,2,-7,NETHER_BRICK)
Block(-3,2,-6,NETHER_FENCE)
Block(-3,2,-5,NETHER_FENCE)
Block(-3,2,-4,NETHER_BRICK)
Block(-3,2,-3,NETHER_BRICK)
Block(-3,2,-2,NETHER_FENCE)
Block(-3,2,-1,NETHER_FENCE)
Block(-3,2,0,NETHER_BRICK)
Block(-3,2,1,NETHER_FENCE)
Block(-3,2,2,NETHER_FENCE)
Block(-3,2,3,NETHER_BRICK)
Block(-3,2,4,NETHER_BRICK)
Block(-3,2,5,NETHER_FENCE)
Block(-3,2,6,NETHER_FENCE)
Block(-3,2,7,NETHER_BRICK)
Block(-3,3,-7,AIR)
Block(-3,3,-6,AIR)
Block(-3,3,-5,AIR)
Block(-3,3,-4,AIR)
Block(-3,3,-3,AIR)
Block(-3,3,-2,AIR)
Block(-3,3,-1,AIR)
Block(-3,3,0,AIR)
Block(-3,3,1,AIR)
Block(-3,3,2,AIR)
Block(-3,3,3,AIR)
Block(-3,3,4,AIR)
Block(-3,3,5,AIR)
Block(-3,3,6,AIR)
Block(-3,3,7,AIR)
Block(-3,4,-7,AIR)
Block(-3,4,-6,AIR)
Block(-3,4,-5,AIR)
Block(-3,4,-4,AIR)
Block(-3,4,-3,AIR)
Block(-3,4,-2,AIR)
Block(-3,4,-1,AIR)
Block(-3,4,0,AIR)
Block(-3,4,1,AIR)
Block(-3,4,2,AIR)
Block(-3,4,3,AIR)
Block(-3,4,4,AIR)
Block(-3,4,5,AIR)
Block(-3,4,6,AIR)
Block(-3,4,7,AIR)
Block(-3,5,-7,AIR)
Block(-3,5,-6,AIR)
Block(-3,5,-5,AIR)
Block(-3,5,-4,AIR)
Block(-3,5,-3,AIR)
Block(-3,5,-2,AIR)
Block(-3,5,-1,AIR)
Block(-3,5,0,AIR)
Block(-3,5,1,AIR)
Block(-3,5,2,AIR)
Block(-3,5,3,AIR)
Block(-3,5,4,AIR)
Block(-3,5,5,AIR)
Block(-3,5,6,AIR)
Block(-3,5,7,AIR)
Block(-2,-39,-2,NETHER_BRICK)
Block(-2,-39,-1,NETHER_BRICK)
Block(-2,-39,0,NETHER_BRICK)
Block(-2,-39,1,NETHER_BRICK)
Block(-2,-39,2,NETHER_BRICK)
Block(-2,-38,-2,NETHER_BRICK)
Block(-2,-38,-1,NETHER_BRICK)
Block(-2,-38,0,NETHER_BRICK)
Block(-2,-38,1,NETHER_BRICK)
Block(-2,-38,2,NETHER_BRICK)
Block(-2,-37,-2,NETHER_BRICK)
Block(-2,-37,-1,NETHER_BRICK)
Block(-2,-37,0,NETHER_BRICK)
Block(-2,-37,1,NETHER_BRICK)
Block(-2,-37,2,NETHER_BRICK)
Block(-2,-36,-2,NETHER_BRICK)
Block(-2,-36,-1,NETHER_BRICK)
Block(-2,-36,0,NETHER_BRICK)
Block(-2,-36,1,NETHER_BRICK)
Block(-2,-36,2,NETHER_BRICK)
Block(-2,-35,-2,NETHER_BRICK)
Block(-2,-35,-1,NETHER_BRICK)
Block(-2,-35,0,NETHER_BRICK)
Block(-2,-35,1,NETHER_BRICK)
Block(-2,-35,2,NETHER_BRICK)
Block(-2,-34,-2,NETHER_BRICK)
Block(-2,-34,-1,NETHER_BRICK)
Block(-2,-34,0,NETHER_BRICK)
Block(-2,-34,1,NETHER_BRICK)
Block(-2,-34,2,NETHER_BRICK)
Block(-2,-33,-2,NETHER_BRICK)
Block(-2,-33,-1,NETHER_BRICK)
Block(-2,-33,0,NETHER_BRICK)
Block(-2,-33,1,NETHER_BRICK)
Block(-2,-33,2,NETHER_BRICK)
Block(-2,-32,-2,NETHER_BRICK)
Block(-2,-32,-1,NETHER_BRICK)
Block(-2,-32,0,NETHER_BRICK)
Block(-2,-32,1,NETHER_BRICK)
Block(-2,-32,2,NETHER_BRICK)
Block(-2,-31,-2,NETHER_BRICK)
Block(-2,-31,-1,NETHER_BRICK)
Block(-2,-31,0,NETHER_BRICK)
Block(-2,-31,1,NETHER_BRICK)
Block(-2,-31,2,NETHER_BRICK)
Block(-2,-30,-2,NETHER_BRICK)
Block(-2,-30,-1,NETHER_BRICK)
Block(-2,-30,0,NETHER_BRICK)
Block(-2,-30,1,NETHER_BRICK)
Block(-2,-30,2,NETHER_BRICK)
Block(-2,-29,-2,NETHER_BRICK)
Block(-2,-29,-1,NETHER_BRICK)
Block(-2,-29,0,NETHER_BRICK)
Block(-2,-29,1,NETHER_BRICK)
Block(-2,-29,2,NETHER_BRICK)
Block(-2,-28,-2,NETHER_BRICK)
Block(-2,-28,-1,NETHER_BRICK)
Block(-2,-28,0,NETHER_BRICK)
Block(-2,-28,1,NETHER_BRICK)
Block(-2,-28,2,NETHER_BRICK)
Block(-2,-27,-2,NETHER_BRICK)
Block(-2,-27,-1,NETHER_BRICK)
Block(-2,-27,0,NETHER_BRICK)
Block(-2,-27,1,NETHER_BRICK)
Block(-2,-27,2,NETHER_BRICK)
Block(-2,-26,-2,NETHER_BRICK)
Block(-2,-26,-1,NETHER_BRICK)
Block(-2,-26,0,NETHER_BRICK)
Block(-2,-26,1,NETHER_BRICK)
Block(-2,-26,2,NETHER_BRICK)
Block(-2,-25,-2,NETHER_BRICK)
Block(-2,-25,-1,NETHER_BRICK)
Block(-2,-25,0,NETHER_BRICK)
Block(-2,-25,1,NETHER_BRICK)
Block(-2,-25,2,NETHER_BRICK)
Block(-2,-24,-2,NETHER_BRICK)
Block(-2,-24,-1,NETHER_BRICK)
Block(-2,-24,0,NETHER_BRICK)
Block(-2,-24,1,NETHER_BRICK)
Block(-2,-24,2,NETHER_BRICK)
Block(-2,-23,-2,NETHER_BRICK)
Block(-2,-23,-1,NETHER_BRICK)
Block(-2,-23,0,NETHER_BRICK)
Block(-2,-23,1,NETHER_BRICK)
Block(-2,-23,2,NETHER_BRICK)
Block(-2,-22,-2,NETHER_BRICK)
Block(-2,-22,-1,NETHER_BRICK)
Block(-2,-22,0,NETHER_BRICK)
Block(-2,-22,1,NETHER_BRICK)
Block(-2,-22,2,NETHER_BRICK)
Block(-2,-21,-2,NETHER_BRICK)
Block(-2,-21,-1,NETHER_BRICK)
Block(-2,-21,0,NETHER_BRICK)
Block(-2,-21,1,NETHER_BRICK)
Block(-2,-21,2,NETHER_BRICK)
Block(-2,-20,-2,NETHER_BRICK)
Block(-2,-20,-1,NETHER_BRICK)
Block(-2,-20,0,NETHER_BRICK)
Block(-2,-20,1,NETHER_BRICK)
Block(-2,-20,2,NETHER_BRICK)
Block(-2,-19,-2,NETHER_BRICK)
Block(-2,-19,-1,NETHER_BRICK)
Block(-2,-19,0,NETHER_BRICK)
Block(-2,-19,1,NETHER_BRICK)
Block(-2,-19,2,NETHER_BRICK)
Block(-2,-18,-2,NETHER_BRICK)
Block(-2,-18,-1,NETHER_BRICK)
Block(-2,-18,0,NETHER_BRICK)
Block(-2,-18,1,NETHER_BRICK)
Block(-2,-18,2,NETHER_BRICK)
Block(-2,-17,-2,NETHER_BRICK)
Block(-2,-17,-1,NETHER_BRICK)
Block(-2,-17,0,NETHER_BRICK)
Block(-2,-17,1,NETHER_BRICK)
Block(-2,-17,2,NETHER_BRICK)
Block(-2,-16,-2,NETHER_BRICK)
Block(-2,-16,-1,NETHER_BRICK)
Block(-2,-16,0,NETHER_BRICK)
Block(-2,-16,1,NETHER_BRICK)
Block(-2,-16,2,NETHER_BRICK)
Block(-2,-15,-2,NETHER_BRICK)
Block(-2,-15,-1,NETHER_BRICK)
Block(-2,-15,0,NETHER_BRICK)
Block(-2,-15,1,NETHER_BRICK)
Block(-2,-15,2,NETHER_BRICK)
Block(-2,-14,-2,NETHER_BRICK)
Block(-2,-14,-1,NETHER_BRICK)
Block(-2,-14,0,NETHER_BRICK)
Block(-2,-14,1,NETHER_BRICK)
Block(-2,-14,2,NETHER_BRICK)
Block(-2,-13,-2,NETHER_BRICK)
Block(-2,-13,-1,NETHER_BRICK)
Block(-2,-13,0,NETHER_BRICK)
Block(-2,-13,1,NETHER_BRICK)
Block(-2,-13,2,NETHER_BRICK)
Block(-2,-12,-2,NETHER_BRICK)
Block(-2,-12,-1,NETHER_BRICK)
Block(-2,-12,0,NETHER_BRICK)
Block(-2,-12,1,NETHER_BRICK)
Block(-2,-12,2,NETHER_BRICK)
Block(-2,-11,-2,NETHER_BRICK)
Block(-2,-11,-1,NETHER_BRICK)
Block(-2,-11,0,NETHER_BRICK)
Block(-2,-11,1,NETHER_BRICK)
Block(-2,-11,2,NETHER_BRICK)
Block(-2,-10,-2,NETHER_BRICK)
Block(-2,-10,-1,NETHER_BRICK)
Block(-2,-10,0,NETHER_BRICK)
Block(-2,-10,1,NETHER_BRICK)
Block(-2,-10,2,NETHER_BRICK)
Block(-2,-9,-2,NETHER_BRICK)
Block(-2,-9,-1,NETHER_BRICK)
Block(-2,-9,0,NETHER_BRICK)
Block(-2,-9,1,NETHER_BRICK)
Block(-2,-9,2,NETHER_BRICK)
Block(-2,-8,-2,NETHER_BRICK)
Block(-2,-8,-1,NETHER_BRICK)
Block(-2,-8,0,NETHER_BRICK)
Block(-2,-8,1,NETHER_BRICK)
Block(-2,-8,2,NETHER_BRICK)
Block(-2,-7,-2,NETHER_BRICK)
Block(-2,-7,-1,NETHER_BRICK)
Block(-2,-7,0,NETHER_BRICK)
Block(-2,-7,1,NETHER_BRICK)
Block(-2,-7,2,NETHER_BRICK)
Block(-2,-6,-2,NETHER_BRICK)
Block(-2,-6,-1,NETHER_BRICK)
Block(-2,-6,0,NETHER_BRICK)
Block(-2,-6,1,NETHER_BRICK)
Block(-2,-6,2,NETHER_BRICK)
Block(-2,-5,-2,NETHER_BRICK)
Block(-2,-5,-1,NETHER_BRICK)
Block(-2,-5,0,NETHER_BRICK)
Block(-2,-5,1,NETHER_BRICK)
Block(-2,-5,2,NETHER_BRICK)
Block(-2,-4,-2,NETHER_BRICK)
Block(-2,-4,-1,NETHER_BRICK)
Block(-2,-4,0,NETHER_BRICK)
Block(-2,-4,1,NETHER_BRICK)
Block(-2,-4,2,NETHER_BRICK)
Block(-2,-3,-2,NETHER_BRICK)
Block(-2,-3,-1,NETHER_BRICK)
Block(-2,-3,0,NETHER_BRICK)
Block(-2,-3,1,NETHER_BRICK)
Block(-2,-3,2,NETHER_BRICK)
Block(-2,-2,-2,NETHER_BRICK)
Block(-2,-2,-1,NETHER_BRICK)
Block(-2,-2,0,NETHER_BRICK)
Block(-2,-2,1,NETHER_BRICK)
Block(-2,-2,2,NETHER_BRICK)
Block(-2,-1,-3,NETHER_BRICK)
Block(-2,-1,-2,NETHER_BRICK)
Block(-2,-1,-1,NETHER_BRICK)
Block(-2,-1,0,NETHER_BRICK)
Block(-2,-1,1,NETHER_BRICK)
Block(-2,-1,2,NETHER_BRICK)
Block(-2,-1,3,NETHER_BRICK)
Block(-2,0,-7,NETHER_BRICK)
Block(-2,0,-6,NETHER_BRICK)
Block(-2,0,-5,NETHER_BRICK)
Block(-2,0,-4,NETHER_BRICK)
Block(-2,0,-3,NETHER_BRICK)
Block(-2,0,-2,NETHER_BRICK)
Block(-2,0,-1,NETHER_BRICK)
Block(-2,0,0,NETHER_BRICK)
Block(-2,0,1,NETHER_BRICK)
Block(-2,0,2,NETHER_BRICK)
Block(-2,0,3,NETHER_BRICK)
Block(-2,0,4,NETHER_BRICK)
Block(-2,0,5,NETHER_BRICK)
Block(-2,0,6,NETHER_BRICK)
Block(-2,0,7,NETHER_BRICK)
Block(-2,1,-7,NETHER_BRICK)
Block(-2,1,-6,NETHER_BRICK)
Block(-2,1,-5,NETHER_BRICK)
Block(-2,1,-4,NETHER_BRICK)
Block(-2,1,-3,NETHER_BRICK)
Block(-2,1,-2,NETHER_BRICK)
Block(-2,1,-1,NETHER_BRICK)
Block(-2,1,0,NETHER_BRICK)
Block(-2,1,1,NETHER_BRICK)
Block(-2,1,2,NETHER_BRICK)
Block(-2,1,3,NETHER_BRICK)
Block(-2,1,4,NETHER_BRICK)
Block(-2,1,5,NETHER_BRICK)
Block(-2,1,6,NETHER_BRICK)
Block(-2,1,7,NETHER_BRICK)
Block(-2,2,-7,AIR)
Block(-2,2,-6,AIR)
Block(-2,2,-5,AIR)
Block(-2,2,-4,AIR)
Block(-2,2,-3,AIR)
Block(-2,2,-2,AIR)
Block(-2,2,-1,AIR)
Block(-2,2,0,AIR)
Block(-2,2,1,AIR)
Block(-2,2,2,AIR)
Block(-2,2,3,AIR)
Block(-2,2,4,AIR)
Block(-2,2,5,AIR)
Block(-2,2,6,AIR)
Block(-2,2,7,AIR)
Block(-2,3,-7,AIR)
Block(-2,3,-6,AIR)
Block(-2,3,-5,AIR)
Block(-2,3,-4,AIR)
Block(-2,3,-3,AIR)
Block(-2,3,-2,AIR)
Block(-2,3,-1,AIR)
Block(-2,3,0,AIR)
Block(-2,3,1,AIR)
Block(-2,3,2,AIR)
Block(-2,3,3,AIR)
Block(-2,3,4,AIR)
Block(-2,3,5,AIR)
Block(-2,3,6,AIR)
Block(-2,3,7,AIR)
Block(-2,4,-7,AIR)
Block(-2,4,-6,AIR)
Block(-2,4,-5,AIR)
Block(-2,4,-4,AIR)
Block(-2,4,-3,AIR)
Block(-2,4,-2,AIR)
Block(-2,4,-1,AIR)
Block(-2,4,0,AIR)
Block(-2,4,1,AIR)
Block(-2,4,2,AIR)
Block(-2,4,3,AIR)
Block(-2,4,4,AIR)
Block(-2,4,5,AIR)
Block(-2,4,6,AIR)
Block(-2,4,7,AIR)
Block(-2,5,-7,AIR)
Block(-2,5,-6,AIR)
Block(-2,5,-5,AIR)
Block(-2,5,-4,AIR)
Block(-2,5,-3,AIR)
Block(-2,5,-2,AIR)
Block(-2,5,-1,AIR)
Block(-2,5,0,AIR)
Block(-2,5,1,AIR)
Block(-2,5,2,AIR)
Block(-2,5,3,AIR)
Block(-2,5,4,AIR)
Block(-2,5,5,AIR)
Block(-2,5,6,AIR)
Block(-2,5,7,AIR)
Block(-1,-39,-2,NETHER_BRICK)
Block(-1,-39,-1,NETHER_BRICK)
Block(-1,-39,0,NETHER_BRICK)
Block(-1,-39,1,NETHER_BRICK)
Block(-1,-39,2,NETHER_BRICK)
Block(-1,-38,-2,NETHER_BRICK)
Block(-1,-38,-1,NETHER_BRICK)
Block(-1,-38,0,NETHER_BRICK)
Block(-1,-38,1,NETHER_BRICK)
Block(-1,-38,2,NETHER_BRICK)
Block(-1,-37,-2,NETHER_BRICK)
Block(-1,-37,-1,NETHER_BRICK)
Block(-1,-37,0,NETHER_BRICK)
Block(-1,-37,1,NETHER_BRICK)
Block(-1,-37,2,NETHER_BRICK)
Block(-1,-36,-2,NETHER_BRICK)
Block(-1,-36,-1,NETHER_BRICK)
Block(-1,-36,0,NETHER_BRICK)
Block(-1,-36,1,NETHER_BRICK)
Block(-1,-36,2,NETHER_BRICK)
Block(-1,-35,-2,NETHER_BRICK)
Block(-1,-35,-1,NETHER_BRICK)
Block(-1,-35,0,NETHER_BRICK)
Block(-1,-35,1,NETHER_BRICK)
Block(-1,-35,2,NETHER_BRICK)
Block(-1,-34,-2,NETHER_BRICK)
Block(-1,-34,-1,NETHER_BRICK)
Block(-1,-34,0,NETHER_BRICK)
Block(-1,-34,1,NETHER_BRICK)
Block(-1,-34,2,NETHER_BRICK)
Block(-1,-33,-2,NETHER_BRICK)
Block(-1,-33,-1,NETHER_BRICK)
Block(-1,-33,0,NETHER_BRICK)
Block(-1,-33,1,NETHER_BRICK)
Block(-1,-33,2,NETHER_BRICK)
Block(-1,-32,-2,NETHER_BRICK)
Block(-1,-32,-1,NETHER_BRICK)
Block(-1,-32,0,NETHER_BRICK)
Block(-1,-32,1,NETHER_BRICK)
Block(-1,-32,2,NETHER_BRICK)
Block(-1,-31,-2,NETHER_BRICK)
Block(-1,-31,-1,NETHER_BRICK)
Block(-1,-31,0,NETHER_BRICK)
Block(-1,-31,1,NETHER_BRICK)
Block(-1,-31,2,NETHER_BRICK)
Block(-1,-30,-2,NETHER_BRICK)
Block(-1,-30,-1,NETHER_BRICK)
Block(-1,-30,0,NETHER_BRICK)
Block(-1,-30,1,NETHER_BRICK)
Block(-1,-30,2,NETHER_BRICK)
Block(-1,-29,-2,NETHER_BRICK)
Block(-1,-29,-1,NETHER_BRICK)
Block(-1,-29,0,NETHER_BRICK)
Block(-1,-29,1,NETHER_BRICK)
Block(-1,-29,2,NETHER_BRICK)
Block(-1,-28,-2,NETHER_BRICK)
Block(-1,-28,-1,NETHER_BRICK)
Block(-1,-28,0,NETHER_BRICK)
Block(-1,-28,1,NETHER_BRICK)
Block(-1,-28,2,NETHER_BRICK)
Block(-1,-27,-2,NETHER_BRICK)
Block(-1,-27,-1,NETHER_BRICK)
Block(-1,-27,0,NETHER_BRICK)
Block(-1,-27,1,NETHER_BRICK)
Block(-1,-27,2,NETHER_BRICK)
Block(-1,-26,-2,NETHER_BRICK)
Block(-1,-26,-1,NETHER_BRICK)
Block(-1,-26,0,NETHER_BRICK)
Block(-1,-26,1,NETHER_BRICK)
Block(-1,-26,2,NETHER_BRICK)
Block(-1,-25,-2,NETHER_BRICK)
Block(-1,-25,-1,NETHER_BRICK)
Block(-1,-25,0,NETHER_BRICK)
Block(-1,-25,1,NETHER_BRICK)
Block(-1,-25,2,NETHER_BRICK)
Block(-1,-24,-2,NETHER_BRICK)
Block(-1,-24,-1,NETHER_BRICK)
Block(-1,-24,0,NETHER_BRICK)
Block(-1,-24,1,NETHER_BRICK)
Block(-1,-24,2,NETHER_BRICK)
Block(-1,-23,-2,NETHER_BRICK)
Block(-1,-23,-1,NETHER_BRICK)
Block(-1,-23,0,NETHER_BRICK)
Block(-1,-23,1,NETHER_BRICK)
Block(-1,-23,2,NETHER_BRICK)
Block(-1,-22,-2,NETHER_BRICK)
Block(-1,-22,-1,NETHER_BRICK)
Block(-1,-22,0,NETHER_BRICK)
Block(-1,-22,1,NETHER_BRICK)
Block(-1,-22,2,NETHER_BRICK)
Block(-1,-21,-2,NETHER_BRICK)
Block(-1,-21,-1,NETHER_BRICK)
Block(-1,-21,0,NETHER_BRICK)
Block(-1,-21,1,NETHER_BRICK)
Block(-1,-21,2,NETHER_BRICK)
Block(-1,-20,-2,NETHER_BRICK)
Block(-1,-20,-1,NETHER_BRICK)
Block(-1,-20,0,NETHER_BRICK)
Block(-1,-20,1,NETHER_BRICK)
Block(-1,-20,2,NETHER_BRICK)
Block(-1,-19,-2,NETHER_BRICK)
Block(-1,-19,-1,NETHER_BRICK)
Block(-1,-19,0,NETHER_BRICK)
Block(-1,-19,1,NETHER_BRICK)
Block(-1,-19,2,NETHER_BRICK)
Block(-1,-18,-2,NETHER_BRICK)
Block(-1,-18,-1,NETHER_BRICK)
Block(-1,-18,0,NETHER_BRICK)
Block(-1,-18,1,NETHER_BRICK)
Block(-1,-18,2,NETHER_BRICK)
Block(-1,-17,-2,NETHER_BRICK)
Block(-1,-17,-1,NETHER_BRICK)
Block(-1,-17,0,NETHER_BRICK)
Block(-1,-17,1,NETHER_BRICK)
Block(-1,-17,2,NETHER_BRICK)
Block(-1,-16,-2,NETHER_BRICK)
Block(-1,-16,-1,NETHER_BRICK)
Block(-1,-16,0,NETHER_BRICK)
Block(-1,-16,1,NETHER_BRICK)
Block(-1,-16,2,NETHER_BRICK)
Block(-1,-15,-2,NETHER_BRICK)
Block(-1,-15,-1,NETHER_BRICK)
Block(-1,-15,0,NETHER_BRICK)
Block(-1,-15,1,NETHER_BRICK)
Block(-1,-15,2,NETHER_BRICK)
Block(-1,-14,-2,NETHER_BRICK)
Block(-1,-14,-1,NETHER_BRICK)
Block(-1,-14,0,NETHER_BRICK)
Block(-1,-14,1,NETHER_BRICK)
Block(-1,-14,2,NETHER_BRICK)
Block(-1,-13,-2,NETHER_BRICK)
Block(-1,-13,-1,NETHER_BRICK)
Block(-1,-13,0,NETHER_BRICK)
Block(-1,-13,1,NETHER_BRICK)
Block(-1,-13,2,NETHER_BRICK)
Block(-1,-12,-2,NETHER_BRICK)
Block(-1,-12,-1,NETHER_BRICK)
Block(-1,-12,0,NETHER_BRICK)
Block(-1,-12,1,NETHER_BRICK)
Block(-1,-12,2,NETHER_BRICK)
Block(-1,-11,-2,NETHER_BRICK)
Block(-1,-11,-1,NETHER_BRICK)
Block(-1,-11,0,NETHER_BRICK)
Block(-1,-11,1,NETHER_BRICK)
Block(-1,-11,2,NETHER_BRICK)
Block(-1,-10,-2,NETHER_BRICK)
Block(-1,-10,-1,NETHER_BRICK)
Block(-1,-10,0,NETHER_BRICK)
Block(-1,-10,1,NETHER_BRICK)
Block(-1,-10,2,NETHER_BRICK)
Block(-1,-9,-2,NETHER_BRICK)
Block(-1,-9,-1,NETHER_BRICK)
Block(-1,-9,0,NETHER_BRICK)
Block(-1,-9,1,NETHER_BRICK)
Block(-1,-9,2,NETHER_BRICK)
Block(-1,-8,-2,NETHER_BRICK)
Block(-1,-8,-1,NETHER_BRICK)
Block(-1,-8,0,NETHER_BRICK)
Block(-1,-8,1,NETHER_BRICK)
Block(-1,-8,2,NETHER_BRICK)
Block(-1,-7,-2,NETHER_BRICK)
Block(-1,-7,-1,NETHER_BRICK)
Block(-1,-7,0,NETHER_BRICK)
Block(-1,-7,1,NETHER_BRICK)
Block(-1,-7,2,NETHER_BRICK)
Block(-1,-6,-2,NETHER_BRICK)
Block(-1,-6,-1,NETHER_BRICK)
Block(-1,-6,0,NETHER_BRICK)
Block(-1,-6,1,NETHER_BRICK)
Block(-1,-6,2,NETHER_BRICK)
Block(-1,-5,-2,NETHER_BRICK)
Block(-1,-5,-1,NETHER_BRICK)
Block(-1,-5,0,NETHER_BRICK)
Block(-1,-5,1,NETHER_BRICK)
Block(-1,-5,2,NETHER_BRICK)
Block(-1,-4,-2,NETHER_BRICK)
Block(-1,-4,-1,NETHER_BRICK)
Block(-1,-4,0,NETHER_BRICK)
Block(-1,-4,1,NETHER_BRICK)
Block(-1,-4,2,NETHER_BRICK)
Block(-1,-3,-2,NETHER_BRICK)
Block(-1,-3,-1,NETHER_BRICK)
Block(-1,-3,0,NETHER_BRICK)
Block(-1,-3,1,NETHER_BRICK)
Block(-1,-3,2,NETHER_BRICK)
Block(-1,-2,-2,NETHER_BRICK)
Block(-1,-2,-1,NETHER_BRICK)
Block(-1,-2,0,NETHER_BRICK)
Block(-1,-2,1,NETHER_BRICK)
Block(-1,-2,2,NETHER_BRICK)
Block(-1,-1,-3,NETHER_BRICK)
Block(-1,-1,-2,NETHER_BRICK)
Block(-1,-1,-1,NETHER_BRICK)
Block(-1,-1,0,NETHER_BRICK)
Block(-1,-1,1,NETHER_BRICK)
Block(-1,-1,2,NETHER_BRICK)
Block(-1,-1,3,NETHER_BRICK)
Block(-1,0,-7,NETHER_BRICK)
Block(-1,0,-6,NETHER_BRICK)
Block(-1,0,-5,NETHER_BRICK)
Block(-1,0,-4,NETHER_BRICK)
Block(-1,0,-3,NETHER_BRICK)
Block(-1,0,-2,NETHER_BRICK)
Block(-1,0,-1,NETHER_BRICK)
Block(-1,0,0,NETHER_BRICK)
Block(-1,0,1,NETHER_BRICK)
Block(-1,0,2,NETHER_BRICK)
Block(-1,0,3,NETHER_BRICK)
Block(-1,0,4,NETHER_BRICK)
Block(-1,0,5,NETHER_BRICK)
Block(-1,0,6,NETHER_BRICK)
Block(-1,0,7,NETHER_BRICK)
Block(-1,1,-7,NETHER_BRICK)
Block(-1,1,-6,NETHER_BRICK)
Block(-1,1,-5,NETHER_BRICK)
Block(-1,1,-4,NETHER_BRICK)
Block(-1,1,-3,NETHER_BRICK)
Block(-1,1,-2,NETHER_BRICK)
Block(-1,1,-1,NETHER_BRICK)
Block(-1,1,0,NETHER_BRICK)
Block(-1,1,1,NETHER_BRICK)
Block(-1,1,2,NETHER_BRICK)
Block(-1,1,3,NETHER_BRICK)
Block(-1,1,4,NETHER_BRICK)
Block(-1,1,5,NETHER_BRICK)
Block(-1,1,6,NETHER_BRICK)
Block(-1,1,7,NETHER_BRICK)
Block(-1,2,-7,AIR)
Block(-1,2,-6,AIR)
Block(-1,2,-5,AIR)
Block(-1,2,-4,AIR)
Block(-1,2,-3,AIR)
Block(-1,2,-2,AIR)
Block(-1,2,-1,AIR)
Block(-1,2,0,AIR)
Block(-1,2,1,AIR)
Block(-1,2,2,AIR)
Block(-1,2,3,AIR)
Block(-1,2,4,AIR)
Block(-1,2,5,AIR)
Block(-1,2,6,AIR)
Block(-1,2,7,AIR)
Block(-1,3,-7,AIR)
Block(-1,3,-6,AIR)
Block(-1,3,-5,AIR)
Block(-1,3,-4,AIR)
Block(-1,3,-3,AIR)
Block(-1,3,-2,AIR)
Block(-1,3,-1,AIR)
Block(-1,3,0,AIR)
Block(-1,3,1,AIR)
Block(-1,3,2,AIR)
Block(-1,3,3,AIR)
Block(-1,3,4,AIR)
Block(-1,3,5,AIR)
Block(-1,3,6,AIR)
Block(-1,3,7,AIR)
Block(-1,4,-7,AIR)
Block(-1,4,-6,AIR)
Block(-1,4,-5,AIR)
Block(-1,4,-4,AIR)
Block(-1,4,-3,AIR)
Block(-1,4,-2,AIR)
Block(-1,4,-1,AIR)
Block(-1,4,0,AIR)
Block(-1,4,1,AIR)
Block(-1,4,2,AIR)
Block(-1,4,3,AIR)
Block(-1,4,4,AIR)
Block(-1,4,5,AIR)
Block(-1,4,6,AIR)
Block(-1,4,7,AIR)
Block(-1,5,-7,AIR)
Block(-1,5,-6,AIR)
Block(-1,5,-5,AIR)
Block(-1,5,-4,AIR)
Block(-1,5,-3,AIR)
Block(-1,5,-2,AIR)
Block(-1,5,-1,AIR)
Block(-1,5,0,AIR)
Block(-1,5,1,AIR)
Block(-1,5,2,AIR)
Block(-1,5,3,AIR)
Block(-1,5,4,AIR)
Block(-1,5,5,AIR)
Block(-1,5,6,AIR)
Block(-1,5,7,AIR)
Block(0,-39,-2,NETHER_BRICK)
Block(0,-39,-1,NETHER_BRICK)
Block(0,-39,0,NETHER_BRICK)
Block(0,-39,1,NETHER_BRICK)
Block(0,-39,2,NETHER_BRICK)
Block(0,-38,-2,NETHER_BRICK)
Block(0,-38,-1,NETHER_BRICK)
Block(0,-38,0,NETHER_BRICK)
Block(0,-38,1,NETHER_BRICK)
Block(0,-38,2,NETHER_BRICK)
Block(0,-37,-2,NETHER_BRICK)
Block(0,-37,-1,NETHER_BRICK)
Block(0,-37,0,NETHER_BRICK)
Block(0,-37,1,NETHER_BRICK)
Block(0,-37,2,NETHER_BRICK)
Block(0,-36,-2,NETHER_BRICK)
Block(0,-36,-1,NETHER_BRICK)
Block(0,-36,0,NETHER_BRICK)
Block(0,-36,1,NETHER_BRICK)
Block(0,-36,2,NETHER_BRICK)
Block(0,-35,-2,NETHER_BRICK)
Block(0,-35,-1,NETHER_BRICK)
Block(0,-35,0,NETHER_BRICK)
Block(0,-35,1,NETHER_BRICK)
Block(0,-35,2,NETHER_BRICK)
Block(0,-34,-2,NETHER_BRICK)
Block(0,-34,-1,NETHER_BRICK)
Block(0,-34,0,NETHER_BRICK)
Block(0,-34,1,NETHER_BRICK)
Block(0,-34,2,NETHER_BRICK)
Block(0,-33,-2,NETHER_BRICK)
Block(0,-33,-1,NETHER_BRICK)
Block(0,-33,0,NETHER_BRICK)
Block(0,-33,1,NETHER_BRICK)
Block(0,-33,2,NETHER_BRICK)
Block(0,-32,-2,NETHER_BRICK)
Block(0,-32,-1,NETHER_BRICK)
Block(0,-32,0,NETHER_BRICK)
Block(0,-32,1,NETHER_BRICK)
Block(0,-32,2,NETHER_BRICK)
Block(0,-31,-2,NETHER_BRICK)
Block(0,-31,-1,NETHER_BRICK)
Block(0,-31,0,NETHER_BRICK)
Block(0,-31,1,NETHER_BRICK)
Block(0,-31,2,NETHER_BRICK)
Block(0,-30,-2,NETHER_BRICK)
Block(0,-30,-1,NETHER_BRICK)
Block(0,-30,0,NETHER_BRICK)
Block(0,-30,1,NETHER_BRICK)
Block(0,-30,2,NETHER_BRICK)
Block(0,-29,-2,NETHER_BRICK)
Block(0,-29,-1,NETHER_BRICK)
Block(0,-29,0,NETHER_BRICK)
Block(0,-29,1,NETHER_BRICK)
Block(0,-29,2,NETHER_BRICK)
Block(0,-28,-2,NETHER_BRICK)
Block(0,-28,-1,NETHER_BRICK)
Block(0,-28,0,NETHER_BRICK)
Block(0,-28,1,NETHER_BRICK)
Block(0,-28,2,NETHER_BRICK)
Block(0,-27,-2,NETHER_BRICK)
Block(0,-27,-1,NETHER_BRICK)
Block(0,-27,0,NETHER_BRICK)
Block(0,-27,1,NETHER_BRICK)
Block(0,-27,2,NETHER_BRICK)
Block(0,-26,-2,NETHER_BRICK)
Block(0,-26,-1,NETHER_BRICK)
Block(0,-26,0,NETHER_BRICK)
Block(0,-26,1,NETHER_BRICK)
Block(0,-26,2,NETHER_BRICK)
Block(0,-25,-2,NETHER_BRICK)
Block(0,-25,-1,NETHER_BRICK)
Block(0,-25,0,NETHER_BRICK)
Block(0,-25,1,NETHER_BRICK)
Block(0,-25,2,NETHER_BRICK)
Block(0,-24,-2,NETHER_BRICK)
Block(0,-24,-1,NETHER_BRICK)
Block(0,-24,0,NETHER_BRICK)
Block(0,-24,1,NETHER_BRICK)
Block(0,-24,2,NETHER_BRICK)
Block(0,-23,-2,NETHER_BRICK)
Block(0,-23,-1,NETHER_BRICK)
Block(0,-23,0,NETHER_BRICK)
Block(0,-23,1,NETHER_BRICK)
Block(0,-23,2,NETHER_BRICK)
Block(0,-22,-2,NETHER_BRICK)
Block(0,-22,-1,NETHER_BRICK)
Block(0,-22,0,NETHER_BRICK)
Block(0,-22,1,NETHER_BRICK)
Block(0,-22,2,NETHER_BRICK)
Block(0,-21,-2,NETHER_BRICK)
Block(0,-21,-1,NETHER_BRICK)
Block(0,-21,0,NETHER_BRICK)
Block(0,-21,1,NETHER_BRICK)
Block(0,-21,2,NETHER_BRICK)
Block(0,-20,-2,NETHER_BRICK)
Block(0,-20,-1,NETHER_BRICK)
Block(0,-20,0,NETHER_BRICK)
Block(0,-20,1,NETHER_BRICK)
Block(0,-20,2,NETHER_BRICK)
Block(0,-19,-2,NETHER_BRICK)
Block(0,-19,-1,NETHER_BRICK)
Block(0,-19,0,NETHER_BRICK)
Block(0,-19,1,NETHER_BRICK)
Block(0,-19,2,NETHER_BRICK)
Block(0,-18,-2,NETHER_BRICK)
Block(0,-18,-1,NETHER_BRICK)
Block(0,-18,0,NETHER_BRICK)
Block(0,-18,1,NETHER_BRICK)
Block(0,-18,2,NETHER_BRICK)
Block(0,-17,-2,NETHER_BRICK)
Block(0,-17,-1,NETHER_BRICK)
Block(0,-17,0,NETHER_BRICK)
Block(0,-17,1,NETHER_BRICK)
Block(0,-17,2,NETHER_BRICK)
Block(0,-16,-2,NETHER_BRICK)
Block(0,-16,-1,NETHER_BRICK)
Block(0,-16,0,NETHER_BRICK)
Block(0,-16,1,NETHER_BRICK)
Block(0,-16,2,NETHER_BRICK)
Block(0,-15,-2,NETHER_BRICK)
Block(0,-15,-1,NETHER_BRICK)
Block(0,-15,0,NETHER_BRICK)
Block(0,-15,1,NETHER_BRICK)
Block(0,-15,2,NETHER_BRICK)
Block(0,-14,-2,NETHER_BRICK)
Block(0,-14,-1,NETHER_BRICK)
Block(0,-14,0,NETHER_BRICK)
Block(0,-14,1,NETHER_BRICK)
Block(0,-14,2,NETHER_BRICK)
Block(0,-13,-2,NETHER_BRICK)
Block(0,-13,-1,NETHER_BRICK)
Block(0,-13,0,NETHER_BRICK)
Block(0,-13,1,NETHER_BRICK)
Block(0,-13,2,NETHER_BRICK)
Block(0,-12,-2,NETHER_BRICK)
Block(0,-12,-1,NETHER_BRICK)
Block(0,-12,0,NETHER_BRICK)
Block(0,-12,1,NETHER_BRICK)
Block(0,-12,2,NETHER_BRICK)
Block(0,-11,-2,NETHER_BRICK)
Block(0,-11,-1,NETHER_BRICK)
Block(0,-11,0,NETHER_BRICK)
Block(0,-11,1,NETHER_BRICK)
Block(0,-11,2,NETHER_BRICK)
Block(0,-10,-2,NETHER_BRICK)
Block(0,-10,-1,NETHER_BRICK)
Block(0,-10,0,NETHER_BRICK)
Block(0,-10,1,NETHER_BRICK)
Block(0,-10,2,NETHER_BRICK)
Block(0,-9,-2,NETHER_BRICK)
Block(0,-9,-1,NETHER_BRICK)
Block(0,-9,0,NETHER_BRICK)
Block(0,-9,1,NETHER_BRICK)
Block(0,-9,2,NETHER_BRICK)
Block(0,-8,-2,NETHER_BRICK)
Block(0,-8,-1,NETHER_BRICK)
Block(0,-8,0,NETHER_BRICK)
Block(0,-8,1,NETHER_BRICK)
Block(0,-8,2,NETHER_BRICK)
Block(0,-7,-2,NETHER_BRICK)
Block(0,-7,-1,NETHER_BRICK)
Block(0,-7,0,NETHER_BRICK)
Block(0,-7,1,NETHER_BRICK)
Block(0,-7,2,NETHER_BRICK)
Block(0,-6,-2,NETHER_BRICK)
Block(0,-6,-1,NETHER_BRICK)
Block(0,-6,0,NETHER_BRICK)
Block(0,-6,1,NETHER_BRICK)
Block(0,-6,2,NETHER_BRICK)
Block(0,-5,-2,NETHER_BRICK)
Block(0,-5,-1,NETHER_BRICK)
Block(0,-5,0,NETHER_BRICK)
Block(0,-5,1,NETHER_BRICK)
Block(0,-5,2,NETHER_BRICK)
Block(0,-4,-2,NETHER_BRICK)
Block(0,-4,-1,NETHER_BRICK)
Block(0,-4,0,NETHER_BRICK)
Block(0,-4,1,NETHER_BRICK)
Block(0,-4,2,NETHER_BRICK)
Block(0,-3,-2,NETHER_BRICK)
Block(0,-3,-1,NETHER_BRICK)
Block(0,-3,0,NETHER_BRICK)
Block(0,-3,1,NETHER_BRICK)
Block(0,-3,2,NETHER_BRICK)
Block(0,-2,-2,NETHER_BRICK)
Block(0,-2,-1,NETHER_BRICK)
Block(0,-2,0,NETHER_BRICK)
Block(0,-2,1,NETHER_BRICK)
Block(0,-2,2,NETHER_BRICK)
Block(0,-1,-3,NETHER_BRICK)
Block(0,-1,-2,NETHER_BRICK)
Block(0,-1,-1,NETHER_BRICK)
Block(0,-1,0,NETHER_BRICK)
Block(0,-1,1,NETHER_BRICK)
Block(0,-1,2,NETHER_BRICK)
Block(0,-1,3,NETHER_BRICK)
Block(0,0,-7,NETHER_BRICK)
Block(0,0,-6,NETHER_BRICK)
Block(0,0,-5,NETHER_BRICK)
Block(0,0,-4,NETHER_BRICK)
Block(0,0,-3,NETHER_BRICK)
Block(0,0,-2,NETHER_BRICK)
Block(0,0,-1,NETHER_BRICK)
Block(0,0,0,NETHER_BRICK)
Block(0,0,1,NETHER_BRICK)
Block(0,0,2,NETHER_BRICK)
Block(0,0,3,NETHER_BRICK)
Block(0,0,4,NETHER_BRICK)
Block(0,0,5,NETHER_BRICK)
Block(0,0,6,NETHER_BRICK)
Block(0,0,7,NETHER_BRICK)
Block(0,1,-7,NETHER_BRICK)
Block(0,1,-6,NETHER_BRICK)
Block(0,1,-5,NETHER_BRICK)
Block(0,1,-4,NETHER_BRICK)
Block(0,1,-3,NETHER_BRICK)
Block(0,1,-2,NETHER_BRICK)
Block(0,1,-1,NETHER_BRICK)
Block(0,1,0,NETHER_BRICK)
Block(0,1,1,NETHER_BRICK)
Block(0,1,2,NETHER_BRICK)
Block(0,1,3,NETHER_BRICK)
Block(0,1,4,NETHER_BRICK)
Block(0,1,5,NETHER_BRICK)
Block(0,1,6,NETHER_BRICK)
Block(0,1,7,NETHER_BRICK)
Block(0,2,-7,AIR)
Block(0,2,-6,AIR)
Block(0,2,-5,AIR)
Block(0,2,-4,AIR)
Block(0,2,-3,AIR)
Block(0,2,-2,AIR)
Block(0,2,-1,AIR)
Block(0,2,0,AIR)
Block(0,2,1,AIR)
Block(0,2,2,AIR)
Block(0,2,3,AIR)
Block(0,2,4,AIR)
Block(0,2,5,AIR)
Block(0,2,6,AIR)
Block(0,2,7,AIR)
Block(0,3,-7,AIR)
Block(0,3,-6,AIR)
Block(0,3,-5,AIR)
Block(0,3,-4,AIR)
Block(0,3,-3,AIR)
Block(0,3,-2,AIR)
Block(0,3,-1,AIR)
Block(0,3,0,AIR)
Block(0,3,1,AIR)
Block(0,3,2,AIR)
Block(0,3,3,AIR)
Block(0,3,4,AIR)
Block(0,3,5,AIR)
Block(0,3,6,AIR)
Block(0,3,7,AIR)
Block(0,4,-7,AIR)
Block(0,4,-6,AIR)
Block(0,4,-5,AIR)
Block(0,4,-4,AIR)
Block(0,4,-3,AIR)
Block(0,4,-2,AIR)
Block(0,4,-1,AIR)
Block(0,4,0,AIR)
Block(0,4,1,AIR)
Block(0,4,2,AIR)
Block(0,4,3,AIR)
Block(0,4,4,AIR)
Block(0,4,5,AIR)
Block(0,4,6,AIR)
Block(0,4,7,AIR)
Block(0,5,-7,AIR)
Block(0,5,-6,AIR)
Block(0,5,-5,AIR)
Block(0,5,-4,AIR)
Block(0,5,-3,AIR)
Block(0,5,-2,AIR)
Block(0,5,-1,AIR)
Block(0,5,0,AIR)
Block(0,5,1,AIR)
Block(0,5,2,AIR)
Block(0,5,3,AIR)
Block(0,5,4,AIR)
Block(0,5,5,AIR)
Block(0,5,6,AIR)
Block(0,5,7,AIR)
Block(1,-39,-2,NETHER_BRICK)
Block(1,-39,-1,NETHER_BRICK)
Block(1,-39,0,NETHER_BRICK)
Block(1,-39,1,NETHER_BRICK)
Block(1,-39,2,NETHER_BRICK)
Block(1,-38,-2,NETHER_BRICK)
Block(1,-38,-1,NETHER_BRICK)
Block(1,-38,0,NETHER_BRICK)
Block(1,-38,1,NETHER_BRICK)
Block(1,-38,2,NETHER_BRICK)
Block(1,-37,-2,NETHER_BRICK)
Block(1,-37,-1,NETHER_BRICK)
Block(1,-37,0,NETHER_BRICK)
Block(1,-37,1,NETHER_BRICK)
Block(1,-37,2,NETHER_BRICK)
Block(1,-36,-2,NETHER_BRICK)
Block(1,-36,-1,NETHER_BRICK)
Block(1,-36,0,NETHER_BRICK)
Block(1,-36,1,NETHER_BRICK)
Block(1,-36,2,NETHER_BRICK)
Block(1,-35,-2,NETHER_BRICK)
Block(1,-35,-1,NETHER_BRICK)
Block(1,-35,0,NETHER_BRICK)
Block(1,-35,1,NETHER_BRICK)
Block(1,-35,2,NETHER_BRICK)
Block(1,-34,-2,NETHER_BRICK)
Block(1,-34,-1,NETHER_BRICK)
Block(1,-34,0,NETHER_BRICK)
Block(1,-34,1,NETHER_BRICK)
Block(1,-34,2,NETHER_BRICK)
Block(1,-33,-2,NETHER_BRICK)
Block(1,-33,-1,NETHER_BRICK)
Block(1,-33,0,NETHER_BRICK)
Block(1,-33,1,NETHER_BRICK)
Block(1,-33,2,NETHER_BRICK)
Block(1,-32,-2,NETHER_BRICK)
Block(1,-32,-1,NETHER_BRICK)
Block(1,-32,0,NETHER_BRICK)
Block(1,-32,1,NETHER_BRICK)
Block(1,-32,2,NETHER_BRICK)
Block(1,-31,-2,NETHER_BRICK)
Block(1,-31,-1,NETHER_BRICK)
Block(1,-31,0,NETHER_BRICK)
Block(1,-31,1,NETHER_BRICK)
Block(1,-31,2,NETHER_BRICK)
Block(1,-30,-2,NETHER_BRICK)
Block(1,-30,-1,NETHER_BRICK)
Block(1,-30,0,NETHER_BRICK)
Block(1,-30,1,NETHER_BRICK)
Block(1,-30,2,NETHER_BRICK)
Block(1,-29,-2,NETHER_BRICK)
Block(1,-29,-1,NETHER_BRICK)
Block(1,-29,0,NETHER_BRICK)
Block(1,-29,1,NETHER_BRICK)
Block(1,-29,2,NETHER_BRICK)
Block(1,-28,-2,NETHER_BRICK)
Block(1,-28,-1,NETHER_BRICK)
Block(1,-28,0,NETHER_BRICK)
Block(1,-28,1,NETHER_BRICK)
Block(1,-28,2,NETHER_BRICK)
Block(1,-27,-2,NETHER_BRICK)
Block(1,-27,-1,NETHER_BRICK)
Block(1,-27,0,NETHER_BRICK)
Block(1,-27,1,NETHER_BRICK)
Block(1,-27,2,NETHER_BRICK)
Block(1,-26,-2,NETHER_BRICK)
Block(1,-26,-1,NETHER_BRICK)
Block(1,-26,0,NETHER_BRICK)
Block(1,-26,1,NETHER_BRICK)
Block(1,-26,2,NETHER_BRICK)
Block(1,-25,-2,NETHER_BRICK)
Block(1,-25,-1,NETHER_BRICK)
Block(1,-25,0,NETHER_BRICK)
Block(1,-25,1,NETHER_BRICK)
Block(1,-25,2,NETHER_BRICK)
Block(1,-24,-2,NETHER_BRICK)
Block(1,-24,-1,NETHER_BRICK)
Block(1,-24,0,NETHER_BRICK)
Block(1,-24,1,NETHER_BRICK)
Block(1,-24,2,NETHER_BRICK)
Block(1,-23,-2,NETHER_BRICK)
Block(1,-23,-1,NETHER_BRICK)
Block(1,-23,0,NETHER_BRICK)
Block(1,-23,1,NETHER_BRICK)
Block(1,-23,2,NETHER_BRICK)
Block(1,-22,-2,NETHER_BRICK)
Block(1,-22,-1,NETHER_BRICK)
Block(1,-22,0,NETHER_BRICK)
Block(1,-22,1,NETHER_BRICK)
Block(1,-22,2,NETHER_BRICK)
Block(1,-21,-2,NETHER_BRICK)
Block(1,-21,-1,NETHER_BRICK)
Block(1,-21,0,NETHER_BRICK)
Block(1,-21,1,NETHER_BRICK)
Block(1,-21,2,NETHER_BRICK)
Block(1,-20,-2,NETHER_BRICK)
Block(1,-20,-1,NETHER_BRICK)
Block(1,-20,0,NETHER_BRICK)
Block(1,-20,1,NETHER_BRICK)
Block(1,-20,2,NETHER_BRICK)
Block(1,-19,-2,NETHER_BRICK)
Block(1,-19,-1,NETHER_BRICK)
Block(1,-19,0,NETHER_BRICK)
Block(1,-19,1,NETHER_BRICK)
Block(1,-19,2,NETHER_BRICK)
Block(1,-18,-2,NETHER_BRICK)
Block(1,-18,-1,NETHER_BRICK)
Block(1,-18,0,NETHER_BRICK)
Block(1,-18,1,NETHER_BRICK)
Block(1,-18,2,NETHER_BRICK)
Block(1,-17,-2,NETHER_BRICK)
Block(1,-17,-1,NETHER_BRICK)
Block(1,-17,0,NETHER_BRICK)
Block(1,-17,1,NETHER_BRICK)
Block(1,-17,2,NETHER_BRICK)
Block(1,-16,-2,NETHER_BRICK)
Block(1,-16,-1,NETHER_BRICK)
Block(1,-16,0,NETHER_BRICK)
Block(1,-16,1,NETHER_BRICK)
Block(1,-16,2,NETHER_BRICK)
Block(1,-15,-2,NETHER_BRICK)
Block(1,-15,-1,NETHER_BRICK)
Block(1,-15,0,NETHER_BRICK)
Block(1,-15,1,NETHER_BRICK)
Block(1,-15,2,NETHER_BRICK)
Block(1,-14,-2,NETHER_BRICK)
Block(1,-14,-1,NETHER_BRICK)
Block(1,-14,0,NETHER_BRICK)
Block(1,-14,1,NETHER_BRICK)
Block(1,-14,2,NETHER_BRICK)
Block(1,-13,-2,NETHER_BRICK)
Block(1,-13,-1,NETHER_BRICK)
Block(1,-13,0,NETHER_BRICK)
Block(1,-13,1,NETHER_BRICK)
Block(1,-13,2,NETHER_BRICK)
Block(1,-12,-2,NETHER_BRICK)
Block(1,-12,-1,NETHER_BRICK)
Block(1,-12,0,NETHER_BRICK)
Block(1,-12,1,NETHER_BRICK)
Block(1,-12,2,NETHER_BRICK)
Block(1,-11,-2,NETHER_BRICK)
Block(1,-11,-1,NETHER_BRICK)
Block(1,-11,0,NETHER_BRICK)
Block(1,-11,1,NETHER_BRICK)
Block(1,-11,2,NETHER_BRICK)
Block(1,-10,-2,NETHER_BRICK)
Block(1,-10,-1,NETHER_BRICK)
Block(1,-10,0,NETHER_BRICK)
Block(1,-10,1,NETHER_BRICK)
Block(1,-10,2,NETHER_BRICK)
Block(1,-9,-2,NETHER_BRICK)
Block(1,-9,-1,NETHER_BRICK)
Block(1,-9,0,NETHER_BRICK)
Block(1,-9,1,NETHER_BRICK)
Block(1,-9,2,NETHER_BRICK)
Block(1,-8,-2,NETHER_BRICK)
Block(1,-8,-1,NETHER_BRICK)
Block(1,-8,0,NETHER_BRICK)
Block(1,-8,1,NETHER_BRICK)
Block(1,-8,2,NETHER_BRICK)
Block(1,-7,-2,NETHER_BRICK)
Block(1,-7,-1,NETHER_BRICK)
Block(1,-7,0,NETHER_BRICK)
Block(1,-7,1,NETHER_BRICK)
Block(1,-7,2,NETHER_BRICK)
Block(1,-6,-2,NETHER_BRICK)
Block(1,-6,-1,NETHER_BRICK)
Block(1,-6,0,NETHER_BRICK)
Block(1,-6,1,NETHER_BRICK)
Block(1,-6,2,NETHER_BRICK)
Block(1,-5,-2,NETHER_BRICK)
Block(1,-5,-1,NETHER_BRICK)
Block(1,-5,0,NETHER_BRICK)
Block(1,-5,1,NETHER_BRICK)
Block(1,-5,2,NETHER_BRICK)
Block(1,-4,-2,NETHER_BRICK)
Block(1,-4,-1,NETHER_BRICK)
Block(1,-4,0,NETHER_BRICK)
Block(1,-4,1,NETHER_BRICK)
Block(1,-4,2,NETHER_BRICK)
Block(1,-3,-2,NETHER_BRICK)
Block(1,-3,-1,NETHER_BRICK)
Block(1,-3,0,NETHER_BRICK)
Block(1,-3,1,NETHER_BRICK)
Block(1,-3,2,NETHER_BRICK)
Block(1,-2,-2,NETHER_BRICK)
Block(1,-2,-1,NETHER_BRICK)
Block(1,-2,0,NETHER_BRICK)
Block(1,-2,1,NETHER_BRICK)
Block(1,-2,2,NETHER_BRICK)
Block(1,-1,-3,NETHER_BRICK)
Block(1,-1,-2,NETHER_BRICK)
Block(1,-1,-1,NETHER_BRICK)
Block(1,-1,0,NETHER_BRICK)
Block(1,-1,1,NETHER_BRICK)
Block(1,-1,2,NETHER_BRICK)
Block(1,-1,3,NETHER_BRICK)
Block(1,0,-7,NETHER_BRICK)
Block(1,0,-6,NETHER_BRICK)
Block(1,0,-5,NETHER_BRICK)
Block(1,0,-4,NETHER_BRICK)
Block(1,0,-3,NETHER_BRICK)
Block(1,0,-2,NETHER_BRICK)
Block(1,0,-1,NETHER_BRICK)
Block(1,0,0,NETHER_BRICK)
Block(1,0,1,NETHER_BRICK)
Block(1,0,2,NETHER_BRICK)
Block(1,0,3,NETHER_BRICK)
Block(1,0,4,NETHER_BRICK)
Block(1,0,5,NETHER_BRICK)
Block(1,0,6,NETHER_BRICK)
Block(1,0,7,NETHER_BRICK)
Block(1,1,-7,NETHER_BRICK)
Block(1,1,-6,NETHER_BRICK)
Block(1,1,-5,NETHER_BRICK)
Block(1,1,-4,NETHER_BRICK)
Block(1,1,-3,NETHER_BRICK)
Block(1,1,-2,NETHER_BRICK)
Block(1,1,-1,NETHER_BRICK)
Block(1,1,0,NETHER_BRICK)
Block(1,1,1,NETHER_BRICK)
Block(1,1,2,NETHER_BRICK)
Block(1,1,3,NETHER_BRICK)
Block(1,1,4,NETHER_BRICK)
Block(1,1,5,NETHER_BRICK)
Block(1,1,6,NETHER_BRICK)
Block(1,1,7,NETHER_BRICK)
Block(1,2,-7,AIR)
Block(1,2,-6,AIR)
Block(1,2,-5,AIR)
Block(1,2,-4,AIR)
Block(1,2,-3,AIR)
Block(1,2,-2,AIR)
Block(1,2,-1,AIR)
Block(1,2,0,AIR)
Block(1,2,1,AIR)
Block(1,2,2,AIR)
Block(1,2,3,AIR)
Block(1,2,4,AIR)
Block(1,2,5,AIR)
Block(1,2,6,AIR)
Block(1,2,7,AIR)
Block(1,3,-7,AIR)
Block(1,3,-6,AIR)
Block(1,3,-5,AIR)
Block(1,3,-4,AIR)
Block(1,3,-3,AIR)
Block(1,3,-2,AIR)
Block(1,3,-1,AIR)
Block(1,3,0,AIR)
Block(1,3,1,AIR)
Block(1,3,2,AIR)
Block(1,3,3,AIR)
Block(1,3,4,AIR)
Block(1,3,5,AIR)
Block(1,3,6,AIR)
Block(1,3,7,AIR)
Block(1,4,-7,AIR)
Block(1,4,-6,AIR)
Block(1,4,-5,AIR)
Block(1,4,-4,AIR)
Block(1,4,-3,AIR)
Block(1,4,-2,AIR)
Block(1,4,-1,AIR)
Block(1,4,0,AIR)
Block(1,4,1,AIR)
Block(1,4,2,AIR)
Block(1,4,3,AIR)
Block(1,4,4,AIR)
Block(1,4,5,AIR)
Block(1,4,6,AIR)
Block(1,4,7,AIR)
Block(1,5,-7,AIR)
Block(1,5,-6,AIR)
Block(1,5,-5,AIR)
Block(1,5,-4,AIR)
Block(1,5,-3,AIR)
Block(1,5,-2,AIR)
Block(1,5,-1,AIR)
Block(1,5,0,AIR)
Block(1,5,1,AIR)
Block(1,5,2,AIR)
Block(1,5,3,AIR)
Block(1,5,4,AIR)
Block(1,5,5,AIR)
Block(1,5,6,AIR)
Block(1,5,7,AIR)
Block(2,-39,-2,NETHER_BRICK)
Block(2,-39,-1,NETHER_BRICK)
Block(2,-39,0,NETHER_BRICK)
Block(2,-39,1,NETHER_BRICK)
Block(2,-39,2,NETHER_BRICK)
Block(2,-38,-2,NETHER_BRICK)
Block(2,-38,-1,NETHER_BRICK)
Block(2,-38,0,NETHER_BRICK)
Block(2,-38,1,NETHER_BRICK)
Block(2,-38,2,NETHER_BRICK)
Block(2,-37,-2,NETHER_BRICK)
Block(2,-37,-1,NETHER_BRICK)
Block(2,-37,0,NETHER_BRICK)
Block(2,-37,1,NETHER_BRICK)
Block(2,-37,2,NETHER_BRICK)
Block(2,-36,-2,NETHER_BRICK)
Block(2,-36,-1,NETHER_BRICK)
Block(2,-36,0,NETHER_BRICK)
Block(2,-36,1,NETHER_BRICK)
Block(2,-36,2,NETHER_BRICK)
Block(2,-35,-2,NETHER_BRICK)
Block(2,-35,-1,NETHER_BRICK)
Block(2,-35,0,NETHER_BRICK)
Block(2,-35,1,NETHER_BRICK)
Block(2,-35,2,NETHER_BRICK)
Block(2,-34,-2,NETHER_BRICK)
Block(2,-34,-1,NETHER_BRICK)
Block(2,-34,0,NETHER_BRICK)
Block(2,-34,1,NETHER_BRICK)
Block(2,-34,2,NETHER_BRICK)
Block(2,-33,-2,NETHER_BRICK)
Block(2,-33,-1,NETHER_BRICK)
Block(2,-33,0,NETHER_BRICK)
Block(2,-33,1,NETHER_BRICK)
Block(2,-33,2,NETHER_BRICK)
Block(2,-32,-2,NETHER_BRICK)
Block(2,-32,-1,NETHER_BRICK)
Block(2,-32,0,NETHER_BRICK)
Block(2,-32,1,NETHER_BRICK)
Block(2,-32,2,NETHER_BRICK)
Block(2,-31,-2,NETHER_BRICK)
Block(2,-31,-1,NETHER_BRICK)
Block(2,-31,0,NETHER_BRICK)
Block(2,-31,1,NETHER_BRICK)
Block(2,-31,2,NETHER_BRICK)
Block(2,-30,-2,NETHER_BRICK)
Block(2,-30,-1,NETHER_BRICK)
Block(2,-30,0,NETHER_BRICK)
Block(2,-30,1,NETHER_BRICK)
Block(2,-30,2,NETHER_BRICK)
Block(2,-29,-2,NETHER_BRICK)
Block(2,-29,-1,NETHER_BRICK)
Block(2,-29,0,NETHER_BRICK)
Block(2,-29,1,NETHER_BRICK)
Block(2,-29,2,NETHER_BRICK)
Block(2,-28,-2,NETHER_BRICK)
Block(2,-28,-1,NETHER_BRICK)
Block(2,-28,0,NETHER_BRICK)
Block(2,-28,1,NETHER_BRICK)
Block(2,-28,2,NETHER_BRICK)
Block(2,-27,-2,NETHER_BRICK)
Block(2,-27,-1,NETHER_BRICK)
Block(2,-27,0,NETHER_BRICK)
Block(2,-27,1,NETHER_BRICK)
Block(2,-27,2,NETHER_BRICK)
Block(2,-26,-2,NETHER_BRICK)
Block(2,-26,-1,NETHER_BRICK)
Block(2,-26,0,NETHER_BRICK)
Block(2,-26,1,NETHER_BRICK)
Block(2,-26,2,NETHER_BRICK)
Block(2,-25,-2,NETHER_BRICK)
Block(2,-25,-1,NETHER_BRICK)
Block(2,-25,0,NETHER_BRICK)
Block(2,-25,1,NETHER_BRICK)
Block(2,-25,2,NETHER_BRICK)
Block(2,-24,-2,NETHER_BRICK)
Block(2,-24,-1,NETHER_BRICK)
Block(2,-24,0,NETHER_BRICK)
Block(2,-24,1,NETHER_BRICK)
Block(2,-24,2,NETHER_BRICK)
Block(2,-23,-2,NETHER_BRICK)
Block(2,-23,-1,NETHER_BRICK)
Block(2,-23,0,NETHER_BRICK)
Block(2,-23,1,NETHER_BRICK)
Block(2,-23,2,NETHER_BRICK)
Block(2,-22,-2,NETHER_BRICK)
Block(2,-22,-1,NETHER_BRICK)
Block(2,-22,0,NETHER_BRICK)
Block(2,-22,1,NETHER_BRICK)
Block(2,-22,2,NETHER_BRICK)
Block(2,-21,-2,NETHER_BRICK)
Block(2,-21,-1,NETHER_BRICK)
Block(2,-21,0,NETHER_BRICK)
Block(2,-21,1,NETHER_BRICK)
Block(2,-21,2,NETHER_BRICK)
Block(2,-20,-2,NETHER_BRICK)
Block(2,-20,-1,NETHER_BRICK)
Block(2,-20,0,NETHER_BRICK)
Block(2,-20,1,NETHER_BRICK)
Block(2,-20,2,NETHER_BRICK)
Block(2,-19,-2,NETHER_BRICK)
Block(2,-19,-1,NETHER_BRICK)
Block(2,-19,0,NETHER_BRICK)
Block(2,-19,1,NETHER_BRICK)
Block(2,-19,2,NETHER_BRICK)
Block(2,-18,-2,NETHER_BRICK)
Block(2,-18,-1,NETHER_BRICK)
Block(2,-18,0,NETHER_BRICK)
Block(2,-18,1,NETHER_BRICK)
Block(2,-18,2,NETHER_BRICK)
Block(2,-17,-2,NETHER_BRICK)
Block(2,-17,-1,NETHER_BRICK)
Block(2,-17,0,NETHER_BRICK)
Block(2,-17,1,NETHER_BRICK)
Block(2,-17,2,NETHER_BRICK)
Block(2,-16,-2,NETHER_BRICK)
Block(2,-16,-1,NETHER_BRICK)
Block(2,-16,0,NETHER_BRICK)
Block(2,-16,1,NETHER_BRICK)
Block(2,-16,2,NETHER_BRICK)
Block(2,-15,-2,NETHER_BRICK)
Block(2,-15,-1,NETHER_BRICK)
Block(2,-15,0,NETHER_BRICK)
Block(2,-15,1,NETHER_BRICK)
Block(2,-15,2,NETHER_BRICK)
Block(2,-14,-2,NETHER_BRICK)
Block(2,-14,-1,NETHER_BRICK)
Block(2,-14,0,NETHER_BRICK)
Block(2,-14,1,NETHER_BRICK)
Block(2,-14,2,NETHER_BRICK)
Block(2,-13,-2,NETHER_BRICK)
Block(2,-13,-1,NETHER_BRICK)
Block(2,-13,0,NETHER_BRICK)
Block(2,-13,1,NETHER_BRICK)
Block(2,-13,2,NETHER_BRICK)
Block(2,-12,-2,NETHER_BRICK)
Block(2,-12,-1,NETHER_BRICK)
Block(2,-12,0,NETHER_BRICK)
Block(2,-12,1,NETHER_BRICK)
Block(2,-12,2,NETHER_BRICK)
Block(2,-11,-2,NETHER_BRICK)
Block(2,-11,-1,NETHER_BRICK)
Block(2,-11,0,NETHER_BRICK)
Block(2,-11,1,NETHER_BRICK)
Block(2,-11,2,NETHER_BRICK)
Block(2,-10,-2,NETHER_BRICK)
Block(2,-10,-1,NETHER_BRICK)
Block(2,-10,0,NETHER_BRICK)
Block(2,-10,1,NETHER_BRICK)
Block(2,-10,2,NETHER_BRICK)
Block(2,-9,-2,NETHER_BRICK)
Block(2,-9,-1,NETHER_BRICK)
Block(2,-9,0,NETHER_BRICK)
Block(2,-9,1,NETHER_BRICK)
Block(2,-9,2,NETHER_BRICK)
Block(2,-8,-2,NETHER_BRICK)
Block(2,-8,-1,NETHER_BRICK)
Block(2,-8,0,NETHER_BRICK)
Block(2,-8,1,NETHER_BRICK)
Block(2,-8,2,NETHER_BRICK)
Block(2,-7,-2,NETHER_BRICK)
Block(2,-7,-1,NETHER_BRICK)
Block(2,-7,0,NETHER_BRICK)
Block(2,-7,1,NETHER_BRICK)
Block(2,-7,2,NETHER_BRICK)
Block(2,-6,-2,NETHER_BRICK)
Block(2,-6,-1,NETHER_BRICK)
Block(2,-6,0,NETHER_BRICK)
Block(2,-6,1,NETHER_BRICK)
Block(2,-6,2,NETHER_BRICK)
Block(2,-5,-2,NETHER_BRICK)
Block(2,-5,-1,NETHER_BRICK)
Block(2,-5,0,NETHER_BRICK)
Block(2,-5,1,NETHER_BRICK)
Block(2,-5,2,NETHER_BRICK)
Block(2,-4,-2,NETHER_BRICK)
Block(2,-4,-1,NETHER_BRICK)
Block(2,-4,0,NETHER_BRICK)
Block(2,-4,1,NETHER_BRICK)
Block(2,-4,2,NETHER_BRICK)
Block(2,-3,-2,NETHER_BRICK)
Block(2,-3,-1,NETHER_BRICK)
Block(2,-3,0,NETHER_BRICK)
Block(2,-3,1,NETHER_BRICK)
Block(2,-3,2,NETHER_BRICK)
Block(2,-2,-2,NETHER_BRICK)
Block(2,-2,-1,NETHER_BRICK)
Block(2,-2,0,NETHER_BRICK)
Block(2,-2,1,NETHER_BRICK)
Block(2,-2,2,NETHER_BRICK)
Block(2,-1,-3,NETHER_BRICK)
Block(2,-1,-2,NETHER_BRICK)
Block(2,-1,-1,NETHER_BRICK)
Block(2,-1,0,NETHER_BRICK)
Block(2,-1,1,NETHER_BRICK)
Block(2,-1,2,NETHER_BRICK)
Block(2,-1,3,NETHER_BRICK)
Block(2,0,-7,NETHER_BRICK)
Block(2,0,-6,NETHER_BRICK)
Block(2,0,-5,NETHER_BRICK)
Block(2,0,-4,NETHER_BRICK)
Block(2,0,-3,NETHER_BRICK)
Block(2,0,-2,NETHER_BRICK)
Block(2,0,-1,NETHER_BRICK)
Block(2,0,0,NETHER_BRICK)
Block(2,0,1,NETHER_BRICK)
Block(2,0,2,NETHER_BRICK)
Block(2,0,3,NETHER_BRICK)
Block(2,0,4,NETHER_BRICK)
Block(2,0,5,NETHER_BRICK)
Block(2,0,6,NETHER_BRICK)
Block(2,0,7,NETHER_BRICK)
Block(2,1,-7,NETHER_BRICK)
Block(2,1,-6,NETHER_BRICK)
Block(2,1,-5,NETHER_BRICK)
Block(2,1,-4,NETHER_BRICK)
Block(2,1,-3,NETHER_BRICK)
Block(2,1,-2,NETHER_BRICK)
Block(2,1,-1,NETHER_BRICK)
Block(2,1,0,NETHER_BRICK)
Block(2,1,1,NETHER_BRICK)
Block(2,1,2,NETHER_BRICK)
Block(2,1,3,NETHER_BRICK)
Block(2,1,4,NETHER_BRICK)
Block(2,1,5,NETHER_BRICK)
Block(2,1,6,NETHER_BRICK)
Block(2,1,7,NETHER_BRICK)
Block(2,2,-7,AIR)
Block(2,2,-6,AIR)
Block(2,2,-5,AIR)
Block(2,2,-4,AIR)
Block(2,2,-3,AIR)
Block(2,2,-2,AIR)
Block(2,2,-1,AIR)
Block(2,2,0,AIR)
Block(2,2,1,AIR)
Block(2,2,2,AIR)
Block(2,2,3,AIR)
Block(2,2,4,AIR)
Block(2,2,5,AIR)
Block(2,2,6,AIR)
Block(2,2,7,AIR)
Block(2,3,-7,AIR)
Block(2,3,-6,AIR)
Block(2,3,-5,AIR)
Block(2,3,-4,AIR)
Block(2,3,-3,AIR)
Block(2,3,-2,AIR)
Block(2,3,-1,AIR)
Block(2,3,0,AIR)
Block(2,3,1,AIR)
Block(2,3,2,AIR)
Block(2,3,3,AIR)
Block(2,3,4,AIR)
Block(2,3,5,AIR)
Block(2,3,6,AIR)
Block(2,3,7,AIR)
Block(2,4,-7,AIR)
Block(2,4,-6,AIR)
Block(2,4,-5,AIR)
Block(2,4,-4,AIR)
Block(2,4,-3,AIR)
Block(2,4,-2,AIR)
Block(2,4,-1,AIR)
Block(2,4,0,AIR)
Block(2,4,1,AIR)
Block(2,4,2,AIR)
Block(2,4,3,AIR)
Block(2,4,4,AIR)
Block(2,4,5,AIR)
Block(2,4,6,AIR)
Block(2,4,7,AIR)
Block(2,5,-7,AIR)
Block(2,5,-6,AIR)
Block(2,5,-5,AIR)
Block(2,5,-4,AIR)
Block(2,5,-3,AIR)
Block(2,5,-2,AIR)
Block(2,5,-1,AIR)
Block(2,5,0,AIR)
Block(2,5,1,AIR)
Block(2,5,2,AIR)
Block(2,5,3,AIR)
Block(2,5,4,AIR)
Block(2,5,5,AIR)
Block(2,5,6,AIR)
Block(2,5,7,AIR)
Block(3,-39,-2,NETHER_BRICK)
Block(3,-39,-1,NETHER_BRICK)
Block(3,-39,0,NETHER_BRICK)
Block(3,-39,1,NETHER_BRICK)
Block(3,-39,2,NETHER_BRICK)
Block(3,-38,-2,NETHER_BRICK)
Block(3,-38,-1,NETHER_BRICK)
Block(3,-38,0,NETHER_BRICK)
Block(3,-38,1,NETHER_BRICK)
Block(3,-38,2,NETHER_BRICK)
Block(3,-37,-2,NETHER_BRICK)
Block(3,-37,-1,NETHER_BRICK)
Block(3,-37,0,NETHER_BRICK)
Block(3,-37,1,NETHER_BRICK)
Block(3,-37,2,NETHER_BRICK)
Block(3,-36,-2,NETHER_BRICK)
Block(3,-36,-1,NETHER_BRICK)
Block(3,-36,0,NETHER_BRICK)
Block(3,-36,1,NETHER_BRICK)
Block(3,-36,2,NETHER_BRICK)
Block(3,-35,-2,NETHER_BRICK)
Block(3,-35,-1,NETHER_BRICK)
Block(3,-35,0,NETHER_BRICK)
Block(3,-35,1,NETHER_BRICK)
Block(3,-35,2,NETHER_BRICK)
Block(3,-34,-2,NETHER_BRICK)
Block(3,-34,-1,NETHER_BRICK)
Block(3,-34,0,NETHER_BRICK)
Block(3,-34,1,NETHER_BRICK)
Block(3,-34,2,NETHER_BRICK)
Block(3,-33,-2,NETHER_BRICK)
Block(3,-33,-1,NETHER_BRICK)
Block(3,-33,0,NETHER_BRICK)
Block(3,-33,1,NETHER_BRICK)
Block(3,-33,2,NETHER_BRICK)
Block(3,-32,-2,NETHER_BRICK)
Block(3,-32,-1,NETHER_BRICK)
Block(3,-32,0,NETHER_BRICK)
Block(3,-32,1,NETHER_BRICK)
Block(3,-32,2,NETHER_BRICK)
Block(3,-31,-2,NETHER_BRICK)
Block(3,-31,-1,NETHER_BRICK)
Block(3,-31,0,NETHER_BRICK)
Block(3,-31,1,NETHER_BRICK)
Block(3,-31,2,NETHER_BRICK)
Block(3,-30,-2,NETHER_BRICK)
Block(3,-30,-1,NETHER_BRICK)
Block(3,-30,0,NETHER_BRICK)
Block(3,-30,1,NETHER_BRICK)
Block(3,-30,2,NETHER_BRICK)
Block(3,-29,-2,NETHER_BRICK)
Block(3,-29,-1,NETHER_BRICK)
Block(3,-29,0,NETHER_BRICK)
Block(3,-29,1,NETHER_BRICK)
Block(3,-29,2,NETHER_BRICK)
Block(3,-28,-2,NETHER_BRICK)
Block(3,-28,-1,NETHER_BRICK)
Block(3,-28,0,NETHER_BRICK)
Block(3,-28,1,NETHER_BRICK)
Block(3,-28,2,NETHER_BRICK)
Block(3,-27,-2,NETHER_BRICK)
Block(3,-27,-1,NETHER_BRICK)
Block(3,-27,0,NETHER_BRICK)
Block(3,-27,1,NETHER_BRICK)
Block(3,-27,2,NETHER_BRICK)
Block(3,-26,-2,NETHER_BRICK)
Block(3,-26,-1,NETHER_BRICK)
Block(3,-26,0,NETHER_BRICK)
Block(3,-26,1,NETHER_BRICK)
Block(3,-26,2,NETHER_BRICK)
Block(3,-25,-2,NETHER_BRICK)
Block(3,-25,-1,NETHER_BRICK)
Block(3,-25,0,NETHER_BRICK)
Block(3,-25,1,NETHER_BRICK)
Block(3,-25,2,NETHER_BRICK)
Block(3,-24,-2,NETHER_BRICK)
Block(3,-24,-1,NETHER_BRICK)
Block(3,-24,0,NETHER_BRICK)
Block(3,-24,1,NETHER_BRICK)
Block(3,-24,2,NETHER_BRICK)
Block(3,-23,-2,NETHER_BRICK)
Block(3,-23,-1,NETHER_BRICK)
Block(3,-23,0,NETHER_BRICK)
Block(3,-23,1,NETHER_BRICK)
Block(3,-23,2,NETHER_BRICK)
Block(3,-22,-2,NETHER_BRICK)
Block(3,-22,-1,NETHER_BRICK)
Block(3,-22,0,NETHER_BRICK)
Block(3,-22,1,NETHER_BRICK)
Block(3,-22,2,NETHER_BRICK)
Block(3,-21,-2,NETHER_BRICK)
Block(3,-21,-1,NETHER_BRICK)
Block(3,-21,0,NETHER_BRICK)
Block(3,-21,1,NETHER_BRICK)
Block(3,-21,2,NETHER_BRICK)
Block(3,-20,-2,NETHER_BRICK)
Block(3,-20,-1,NETHER_BRICK)
Block(3,-20,0,NETHER_BRICK)
Block(3,-20,1,NETHER_BRICK)
Block(3,-20,2,NETHER_BRICK)
Block(3,-19,-2,NETHER_BRICK)
Block(3,-19,-1,NETHER_BRICK)
Block(3,-19,0,NETHER_BRICK)
Block(3,-19,1,NETHER_BRICK)
Block(3,-19,2,NETHER_BRICK)
Block(3,-18,-2,NETHER_BRICK)
Block(3,-18,-1,NETHER_BRICK)
Block(3,-18,0,NETHER_BRICK)
Block(3,-18,1,NETHER_BRICK)
Block(3,-18,2,NETHER_BRICK)
Block(3,-17,-2,NETHER_BRICK)
Block(3,-17,-1,NETHER_BRICK)
Block(3,-17,0,NETHER_BRICK)
Block(3,-17,1,NETHER_BRICK)
Block(3,-17,2,NETHER_BRICK)
Block(3,-16,-2,NETHER_BRICK)
Block(3,-16,-1,NETHER_BRICK)
Block(3,-16,0,NETHER_BRICK)
Block(3,-16,1,NETHER_BRICK)
Block(3,-16,2,NETHER_BRICK)
Block(3,-15,-2,NETHER_BRICK)
Block(3,-15,-1,NETHER_BRICK)
Block(3,-15,0,NETHER_BRICK)
Block(3,-15,1,NETHER_BRICK)
Block(3,-15,2,NETHER_BRICK)
Block(3,-14,-2,NETHER_BRICK)
Block(3,-14,-1,NETHER_BRICK)
Block(3,-14,0,NETHER_BRICK)
Block(3,-14,1,NETHER_BRICK)
Block(3,-14,2,NETHER_BRICK)
Block(3,-13,-2,NETHER_BRICK)
Block(3,-13,-1,NETHER_BRICK)
Block(3,-13,0,NETHER_BRICK)
Block(3,-13,1,NETHER_BRICK)
Block(3,-13,2,NETHER_BRICK)
Block(3,-12,-2,NETHER_BRICK)
Block(3,-12,-1,NETHER_BRICK)
Block(3,-12,0,NETHER_BRICK)
Block(3,-12,1,NETHER_BRICK)
Block(3,-12,2,NETHER_BRICK)
Block(3,-11,-2,NETHER_BRICK)
Block(3,-11,-1,NETHER_BRICK)
Block(3,-11,0,NETHER_BRICK)
Block(3,-11,1,NETHER_BRICK)
Block(3,-11,2,NETHER_BRICK)
Block(3,-10,-2,NETHER_BRICK)
Block(3,-10,-1,NETHER_BRICK)
Block(3,-10,0,NETHER_BRICK)
Block(3,-10,1,NETHER_BRICK)
Block(3,-10,2,NETHER_BRICK)
Block(3,-9,-2,NETHER_BRICK)
Block(3,-9,-1,NETHER_BRICK)
Block(3,-9,0,NETHER_BRICK)
Block(3,-9,1,NETHER_BRICK)
Block(3,-9,2,NETHER_BRICK)
Block(3,-8,-2,NETHER_BRICK)
Block(3,-8,-1,NETHER_BRICK)
Block(3,-8,0,NETHER_BRICK)
Block(3,-8,1,NETHER_BRICK)
Block(3,-8,2,NETHER_BRICK)
Block(3,-7,-2,NETHER_BRICK)
Block(3,-7,-1,NETHER_BRICK)
Block(3,-7,0,NETHER_BRICK)
Block(3,-7,1,NETHER_BRICK)
Block(3,-7,2,NETHER_BRICK)
Block(3,-6,-2,NETHER_BRICK)
Block(3,-6,-1,NETHER_BRICK)
Block(3,-6,0,NETHER_BRICK)
Block(3,-6,1,NETHER_BRICK)
Block(3,-6,2,NETHER_BRICK)
Block(3,-5,-2,NETHER_BRICK)
Block(3,-5,-1,NETHER_BRICK)
Block(3,-5,0,NETHER_BRICK)
Block(3,-5,1,NETHER_BRICK)
Block(3,-5,2,NETHER_BRICK)
Block(3,-4,-3,NETHER_BRICK)
Block(3,-4,-2,NETHER_BRICK)
Block(3,-4,-1,NETHER_BRICK)
Block(3,-4,0,NETHER_BRICK)
Block(3,-4,1,NETHER_BRICK)
Block(3,-4,2,NETHER_BRICK)
Block(3,-4,3,NETHER_BRICK)
Block(3,-3,-3,NETHER_BRICK)
Block(3,-3,-2,NETHER_BRICK)
Block(3,-3,-1,NETHER_BRICK)
Block(3,-3,0,NETHER_BRICK)
Block(3,-3,1,NETHER_BRICK)
Block(3,-3,2,NETHER_BRICK)
Block(3,-3,3,NETHER_BRICK)
Block(3,-2,-4,NETHER_BRICK)
Block(3,-2,-3,NETHER_BRICK)
Block(3,-2,-2,NETHER_BRICK)
Block(3,-2,-1,NETHER_BRICK)
Block(3,-2,0,NETHER_BRICK)
Block(3,-2,1,NETHER_BRICK)
Block(3,-2,2,NETHER_BRICK)
Block(3,-2,3,NETHER_BRICK)
Block(3,-2,4,NETHER_BRICK)
Block(3,-1,-5,NETHER_BRICK)
Block(3,-1,-4,NETHER_BRICK)
Block(3,-1,-3,NETHER_BRICK)
Block(3,-1,-2,NETHER_BRICK)
Block(3,-1,-1,NETHER_FENCE)
Block(3,-1,0,NETHER_BRICK)
Block(3,-1,1,NETHER_FENCE)
Block(3,-1,2,NETHER_BRICK)
Block(3,-1,3,NETHER_BRICK)
Block(3,-1,4,NETHER_BRICK)
Block(3,-1,5,NETHER_BRICK)
Block(3,0,-7,NETHER_BRICK)
Block(3,0,-6,NETHER_BRICK)
Block(3,0,-5,NETHER_BRICK)
Block(3,0,-4,NETHER_BRICK)
Block(3,0,-3,NETHER_BRICK)
Block(3,0,-2,NETHER_BRICK)
Block(3,0,-1,NETHER_FENCE)
Block(3,0,0,NETHER_BRICK)
Block(3,0,1,NETHER_FENCE)
Block(3,0,2,NETHER_BRICK)
Block(3,0,3,NETHER_BRICK)
Block(3,0,4,NETHER_BRICK)
Block(3,0,5,NETHER_BRICK)
Block(3,0,6,NETHER_BRICK)
Block(3,0,7,NETHER_BRICK)
Block(3,1,-7,NETHER_BRICK)
Block(3,1,-6,NETHER_BRICK)
Block(3,1,-5,NETHER_BRICK)
Block(3,1,-4,NETHER_BRICK)
Block(3,1,-3,NETHER_BRICK)
Block(3,1,-2,NETHER_BRICK)
Block(3,1,-1,NETHER_BRICK)
Block(3,1,0,NETHER_BRICK)
Block(3,1,1,NETHER_BRICK)
Block(3,1,2,NETHER_BRICK)
Block(3,1,3,NETHER_BRICK)
Block(3,1,4,NETHER_BRICK)
Block(3,1,5,NETHER_BRICK)
Block(3,1,6,NETHER_BRICK)
Block(3,1,7,NETHER_BRICK)
Block(3,2,-7,NETHER_BRICK)
Block(3,2,-6,NETHER_FENCE)
Block(3,2,-5,NETHER_FENCE)
Block(3,2,-4,NETHER_BRICK)
Block(3,2,-3,NETHER_BRICK)
Block(3,2,-2,NETHER_FENCE)
Block(3,2,-1,NETHER_FENCE)
Block(3,2,0,NETHER_BRICK)
Block(3,2,1,NETHER_FENCE)
Block(3,2,2,NETHER_FENCE)
Block(3,2,3,NETHER_BRICK)
Block(3,2,4,NETHER_BRICK)
Block(3,2,5,NETHER_FENCE)
Block(3,2,6,NETHER_FENCE)
Block(3,2,7,NETHER_BRICK)
Block(3,3,-7,AIR)
Block(3,3,-6,AIR)
Block(3,3,-5,AIR)
Block(3,3,-4,AIR)
Block(3,3,-3,AIR)
Block(3,3,-2,AIR)
Block(3,3,-1,AIR)
Block(3,3,0,AIR)
Block(3,3,1,AIR)
Block(3,3,2,AIR)
Block(3,3,3,AIR)
Block(3,3,4,AIR)
Block(3,3,5,AIR)
Block(3,3,6,AIR)
Block(3,3,7,AIR)
Block(3,4,-7,AIR)
Block(3,4,-6,AIR)
Block(3,4,-5,AIR)
Block(3,4,-4,AIR)
Block(3,4,-3,AIR)
Block(3,4,-2,AIR)
Block(3,4,-1,AIR)
Block(3,4,0,AIR)
Block(3,4,1,AIR)
Block(3,4,2,AIR)
Block(3,4,3,AIR)
Block(3,4,4,AIR)
Block(3,4,5,AIR)
Block(3,4,6,AIR)
Block(3,4,7,AIR)
Block(3,5,-7,AIR)
Block(3,5,-6,AIR)
Block(3,5,-5,AIR)
Block(3,5,-4,AIR)
Block(3,5,-3,AIR)
Block(3,5,-2,AIR)
Block(3,5,-1,AIR)
Block(3,5,0,AIR)
Block(3,5,1,AIR)
Block(3,5,2,AIR)
Block(3,5,3,AIR)
Block(3,5,4,AIR)
Block(3,5,5,AIR)
Block(3,5,6,AIR)
Block(3,5,7,AIR)

#######################################################################
# +-----------------------------------------------------------------+ #
# |                            BO3 checks                           | #
# +-----------------------------------------------------------------+ #
#######################################################################

# Require a condition at a certain location in order for the BO3 to be spawned.
# BlockCheck(x,y,z,BlockName[,BlockName[,...]]) - one of the blocks must be at the location
# BlockCheckNot(x,y,z,BlockName[,BlockName[,...]]) - all the blocks must not be at the location
# LightCheck(x,y,z,minLightLevel,maxLightLevel) - light must be between min and max (inclusive)

# You can use "Solid" as a BlockName for matching all solid blocks or "All" to match all blocks that aren't air.

# Examples:
#   BlockCheck(0,-1,0,GRASS,DIRT)  Require grass or dirt just below the object
#   BlockCheck(0,-1,0,Solid)       Require any solid block just below the object
#   BlockCheck(0,-1,0,WOOL)        Require any type of wool just below the object
#   BlockCheck(0,-1,0,WOOL:0)      Require white wool just below the object
#   BlockCheckNot(0,-1,0,WOOL:0)   Require that there is no white wool below the object
#   LightCheck(0,0,0,0,1)          Require almost complete darkness just below the object

#######################################################################
# +-----------------------------------------------------------------+ #
# |                             Branches                            | #
# +-----------------------------------------------------------------+ #
#######################################################################

# Branches are objects that will spawn when this object spawns when it is used in
# the CustomStructure resource. Branches can also have branches, making complex
# structures possible. See the wiki for more details.

# Regular Branches spawn each branch with an independent chance of spawning.
# Branch(x,y,z,branchName,rotation,chance[,anotherBranchName,rotation,chance[,...]][IndividualChance])
# branchName - name of the object to spawn.
# rotation - NORTH, SOUTH, EAST or WEST.
# IndividualChance - The chance each branch has to spawn, assumed to be 100 when left blank

# Weighted Branches spawn branches with a dependent chance of spawning.
# WeightedBranch(x,y,z,branchName,rotation,chance[,anotherBranchName,rotation,chance[,...]][MaxChanceOutOf])
# MaxChanceOutOf - The chance all branches have to spawn out of, assumed to be 100 when left blank

WeightedBranch(0,0,-15,flatfort-walkway-S2N,NORTH,50,flatfort-walkway-end-S2N,NORTH,50,100)